
ERROR 2024-08-23 17:30:20,460 settings Test error message C:\Users\User\PycharmProjects\my_portal\my_portal\settings.py
ERROR 2024-08-23 17:30:21,871 signal Signal handler <bound method DjangoFixup.on_import_modules of <celery.fixups.django.DjangoFixup object at 0x000001ADAD4355D0>> raised: NameError("name 'r' is not defined") C:\Users\User\AppData\Local\Programs\Python\Python310\lib\site-packages\celery\utils\dispatch\signal.py
Traceback (most recent call last):
  File "C:\Users\User\AppData\Local\Programs\Python\Python310\lib\site-packages\celery\utils\dispatch\signal.py", line 276, in send
    response = receiver(signal=self, sender=sender, **named)
  File "C:\Users\User\AppData\Local\Programs\Python\Python310\lib\site-packages\celery\fixups\django.py", line 100, in on_import_modules
    self.worker_fixup.validate_models()
  File "C:\Users\User\AppData\Local\Programs\Python\Python310\lib\site-packages\celery\fixups\django.py", line 140, in validate_models
    run_checks()
  File "C:\Users\User\AppData\Local\Programs\Python\Python310\lib\site-packages\django\core\checks\registry.py", line 88, in run_checks
    new_errors = check(app_configs=app_configs, databases=databases)
  File "C:\Users\User\AppData\Local\Programs\Python\Python310\lib\site-packages\django\core\checks\urls.py", line 42, in check_url_namespaces_unique
    all_namespaces = _load_all_namespaces(resolver)
  File "C:\Users\User\AppData\Local\Programs\Python\Python310\lib\site-packages\django\core\checks\urls.py", line 61, in _load_all_namespaces
    url_patterns = getattr(resolver, "url_patterns", [])
  File "C:\Users\User\AppData\Local\Programs\Python\Python310\lib\site-packages\django\utils\functional.py", line 47, in __get__
    res = instance.__dict__[self.name] = self.func(instance)
  File "C:\Users\User\AppData\Local\Programs\Python\Python310\lib\site-packages\django\urls\resolvers.py", line 738, in url_patterns
    patterns = getattr(self.urlconf_module, "urlpatterns", self.urlconf_module)
  File "C:\Users\User\AppData\Local\Programs\Python\Python310\lib\site-packages\django\utils\functional.py", line 47, in __get__
    res = instance.__dict__[self.name] = self.func(instance)
  File "C:\Users\User\AppData\Local\Programs\Python\Python310\lib\site-packages\django\urls\resolvers.py", line 731, in urlconf_module
    return import_module(self.urlconf_name)
  File "C:\Users\User\AppData\Local\Programs\Python\Python310\lib\importlib\__init__.py", line 126, in import_module
    return _bootstrap._gcd_import(name[level:], package, level)
  File "<frozen importlib._bootstrap>", line 1050, in _gcd_import
  File "<frozen importlib._bootstrap>", line 1027, in _find_and_load
  File "<frozen importlib._bootstrap>", line 1006, in _find_and_load_unlocked
  File "<frozen importlib._bootstrap>", line 688, in _load_unlocked
  File "<frozen importlib._bootstrap_external>", line 883, in exec_module
  File "<frozen importlib._bootstrap>", line 241, in _call_with_frames_removed
  File "C:\Users\User\PycharmProjects\my_portal\my_portal\urls.py", line 25, in <module>
    from news import views
  File "C:\Users\User\PycharmProjects\my_portal\news\views.py", line 24, in <module>
    r
NameError: name 'r' is not defined
ERROR 2024-08-23 17:30:55,253 settings Test error message C:\Users\User\PycharmProjects\my_portal\my_portal\settings.py
ERROR 2024-08-23 17:31:10,218 settings Test error message C:\Users\User\PycharmProjects\my_portal\my_portal\settings.py
ERROR 2024-08-23 17:31:29,933 settings Test error message C:\Users\User\PycharmProjects\my_portal\my_portal\settings.py
ERROR 2024-08-23 17:31:33,027 settings Test error message C:\Users\User\PycharmProjects\my_portal\my_portal\settings.py
