ERROR 2024-08-29 21:18:20,592 settings Test error message
ERROR 2024-08-29 21:18:23,696 settings Test error message
INFO 2024-08-29 21:18:24,363 autoreload Watching for file changes with StatReloader
ERROR 2024-08-29 21:18:59,022 log Internal Server Error: /news/
Traceback (most recent call last):
  File "C:\Users\User\AppData\Local\Programs\Python\Python310\lib\site-packages\django\template\base.py", line 502, in parse
    compile_func = self.tags[command]
KeyError: 'endblock'

During handling of the above exception, another exception occurred:

Traceback (most recent call last):
  File "C:\Users\User\AppData\Local\Programs\Python\Python310\lib\site-packages\django\core\handlers\exception.py", line 55, in inner
    response = get_response(request)
  File "C:\Users\User\AppData\Local\Programs\Python\Python310\lib\site-packages\django\core\handlers\base.py", line 220, in _get_response
    response = response.render()
  File "C:\Users\User\AppData\Local\Programs\Python\Python310\lib\site-packages\django\template\response.py", line 114, in render
    self.content = self.rendered_content
  File "C:\Users\User\AppData\Local\Programs\Python\Python310\lib\site-packages\django\template\response.py", line 90, in rendered_content
    template = self.resolve_template(self.template_name)
  File "C:\Users\User\AppData\Local\Programs\Python\Python310\lib\site-packages\django\template\response.py", line 72, in resolve_template
    return select_template(template, using=self.using)
  File "C:\Users\User\AppData\Local\Programs\Python\Python310\lib\site-packages\django\template\loader.py", line 42, in select_template
    return engine.get_template(template_name)
  File "C:\Users\User\AppData\Local\Programs\Python\Python310\lib\site-packages\django\template\backends\django.py", line 33, in get_template
    return Template(self.engine.get_template(template_name), self)
  File "C:\Users\User\AppData\Local\Programs\Python\Python310\lib\site-packages\django\template\engine.py", line 177, in get_template
    template, origin = self.find_template(template_name)
  File "C:\Users\User\AppData\Local\Programs\Python\Python310\lib\site-packages\django\template\engine.py", line 159, in find_template
    template = loader.get_template(name, skip=skip)
  File "C:\Users\User\AppData\Local\Programs\Python\Python310\lib\site-packages\django\template\loaders\cached.py", line 57, in get_template
    template = super().get_template(template_name, skip)
  File "C:\Users\User\AppData\Local\Programs\Python\Python310\lib\site-packages\django\template\loaders\base.py", line 28, in get_template
    return Template(
  File "C:\Users\User\AppData\Local\Programs\Python\Python310\lib\site-packages\django\template\base.py", line 154, in __init__
    self.nodelist = self.compile_nodelist()
  File "C:\Users\User\AppData\Local\Programs\Python\Python310\lib\site-packages\django\template\base.py", line 196, in compile_nodelist
    return parser.parse()
  File "C:\Users\User\AppData\Local\Programs\Python\Python310\lib\site-packages\django\template\base.py", line 510, in parse
    raise self.error(token, e)
  File "C:\Users\User\AppData\Local\Programs\Python\Python310\lib\site-packages\django\template\base.py", line 508, in parse
    compiled_result = compile_func(self, token)
  File "C:\Users\User\AppData\Local\Programs\Python\Python310\lib\site-packages\django\template\loader_tags.py", line 295, in do_extends
    nodelist = parser.parse()
  File "C:\Users\User\AppData\Local\Programs\Python\Python310\lib\site-packages\django\template\base.py", line 510, in parse
    raise self.error(token, e)
  File "C:\Users\User\AppData\Local\Programs\Python\Python310\lib\site-packages\django\template\base.py", line 508, in parse
    compiled_result = compile_func(self, token)
  File "C:\Users\User\AppData\Local\Programs\Python\Python310\lib\site-packages\django\template\loader_tags.py", line 234, in do_block
    nodelist = parser.parse(("endblock",))
  File "C:\Users\User\AppData\Local\Programs\Python\Python310\lib\site-packages\django\template\base.py", line 510, in parse
    raise self.error(token, e)
  File "C:\Users\User\AppData\Local\Programs\Python\Python310\lib\site-packages\django\template\base.py", line 508, in parse
    compiled_result = compile_func(self, token)
  File "C:\Users\User\AppData\Local\Programs\Python\Python310\lib\site-packages\django\templatetags\cache.py", line 84, in do_cache
    nodelist = parser.parse(("endcache",))
  File "C:\Users\User\AppData\Local\Programs\Python\Python310\lib\site-packages\django\template\base.py", line 504, in parse
    self.invalid_block_tag(token, command, parse_until)
  File "C:\Users\User\AppData\Local\Programs\Python\Python310\lib\site-packages\django\template\base.py", line 555, in invalid_block_tag
    raise self.error(
django.template.exceptions.TemplateSyntaxError: Invalid block tag on line 50: 'endblock', expected 'endcache'. Did you forget to register or load this tag?
ERROR 2024-08-29 21:18:59,402 log Internal Server Error: /news/
Traceback (most recent call last):
  File "C:\Users\User\AppData\Local\Programs\Python\Python310\lib\site-packages\django\template\base.py", line 502, in parse
    compile_func = self.tags[command]
KeyError: 'endblock'

During handling of the above exception, another exception occurred:

Traceback (most recent call last):
  File "C:\Users\User\AppData\Local\Programs\Python\Python310\lib\site-packages\django\core\handlers\exception.py", line 55, in inner
    response = get_response(request)
  File "C:\Users\User\AppData\Local\Programs\Python\Python310\lib\site-packages\django\core\handlers\base.py", line 220, in _get_response
    response = response.render()
  File "C:\Users\User\AppData\Local\Programs\Python\Python310\lib\site-packages\django\template\response.py", line 114, in render
    self.content = self.rendered_content
  File "C:\Users\User\AppData\Local\Programs\Python\Python310\lib\site-packages\django\template\response.py", line 90, in rendered_content
    template = self.resolve_template(self.template_name)
  File "C:\Users\User\AppData\Local\Programs\Python\Python310\lib\site-packages\django\template\response.py", line 72, in resolve_template
    return select_template(template, using=self.using)
  File "C:\Users\User\AppData\Local\Programs\Python\Python310\lib\site-packages\django\template\loader.py", line 42, in select_template
    return engine.get_template(template_name)
  File "C:\Users\User\AppData\Local\Programs\Python\Python310\lib\site-packages\django\template\backends\django.py", line 33, in get_template
    return Template(self.engine.get_template(template_name), self)
  File "C:\Users\User\AppData\Local\Programs\Python\Python310\lib\site-packages\django\template\engine.py", line 177, in get_template
    template, origin = self.find_template(template_name)
  File "C:\Users\User\AppData\Local\Programs\Python\Python310\lib\site-packages\django\template\engine.py", line 159, in find_template
    template = loader.get_template(name, skip=skip)
  File "C:\Users\User\AppData\Local\Programs\Python\Python310\lib\site-packages\django\template\loaders\cached.py", line 57, in get_template
    template = super().get_template(template_name, skip)
  File "C:\Users\User\AppData\Local\Programs\Python\Python310\lib\site-packages\django\template\loaders\base.py", line 28, in get_template
    return Template(
  File "C:\Users\User\AppData\Local\Programs\Python\Python310\lib\site-packages\django\template\base.py", line 154, in __init__
    self.nodelist = self.compile_nodelist()
  File "C:\Users\User\AppData\Local\Programs\Python\Python310\lib\site-packages\django\template\base.py", line 196, in compile_nodelist
    return parser.parse()
  File "C:\Users\User\AppData\Local\Programs\Python\Python310\lib\site-packages\django\template\base.py", line 510, in parse
    raise self.error(token, e)
  File "C:\Users\User\AppData\Local\Programs\Python\Python310\lib\site-packages\django\template\base.py", line 508, in parse
    compiled_result = compile_func(self, token)
  File "C:\Users\User\AppData\Local\Programs\Python\Python310\lib\site-packages\django\template\loader_tags.py", line 295, in do_extends
    nodelist = parser.parse()
  File "C:\Users\User\AppData\Local\Programs\Python\Python310\lib\site-packages\django\template\base.py", line 510, in parse
    raise self.error(token, e)
  File "C:\Users\User\AppData\Local\Programs\Python\Python310\lib\site-packages\django\template\base.py", line 508, in parse
    compiled_result = compile_func(self, token)
  File "C:\Users\User\AppData\Local\Programs\Python\Python310\lib\site-packages\django\template\loader_tags.py", line 234, in do_block
    nodelist = parser.parse(("endblock",))
  File "C:\Users\User\AppData\Local\Programs\Python\Python310\lib\site-packages\django\template\base.py", line 510, in parse
    raise self.error(token, e)
  File "C:\Users\User\AppData\Local\Programs\Python\Python310\lib\site-packages\django\template\base.py", line 508, in parse
    compiled_result = compile_func(self, token)
  File "C:\Users\User\AppData\Local\Programs\Python\Python310\lib\site-packages\django\templatetags\cache.py", line 84, in do_cache
    nodelist = parser.parse(("endcache",))
  File "C:\Users\User\AppData\Local\Programs\Python\Python310\lib\site-packages\django\template\base.py", line 504, in parse
    self.invalid_block_tag(token, command, parse_until)
  File "C:\Users\User\AppData\Local\Programs\Python\Python310\lib\site-packages\django\template\base.py", line 555, in invalid_block_tag
    raise self.error(
django.template.exceptions.TemplateSyntaxError: Invalid block tag on line 50: 'endblock', expected 'endcache'. Did you forget to register or load this tag?

During handling of the above exception, another exception occurred:

Traceback (most recent call last):
  File "C:\Users\User\AppData\Local\Programs\Python\Python310\lib\site-packages\django\core\handlers\exception.py", line 55, in inner
    response = get_response(request)
  File "C:\Users\User\AppData\Local\Programs\Python\Python310\lib\site-packages\allauth\account\middleware.py", line 37, in middleware
    response = get_response(request)
  File "C:\Users\User\AppData\Local\Programs\Python\Python310\lib\site-packages\django\core\handlers\exception.py", line 57, in inner
    response = response_for_exception(request, exc)
  File "C:\Users\User\AppData\Local\Programs\Python\Python310\lib\site-packages\django\core\handlers\exception.py", line 143, in response_for_exception
    log_response(
  File "C:\Users\User\AppData\Local\Programs\Python\Python310\lib\site-packages\django\utils\log.py", line 241, in log_response
    getattr(logger, level)(
  File "C:\Users\User\AppData\Local\Programs\Python\Python310\lib\logging\__init__.py", line 1497, in error
    self._log(ERROR, msg, args, **kwargs)
  File "C:\Users\User\AppData\Local\Programs\Python\Python310\lib\logging\__init__.py", line 1615, in _log
    self.handle(record)
  File "C:\Users\User\AppData\Local\Programs\Python\Python310\lib\logging\__init__.py", line 1625, in handle
    self.callHandlers(record)
  File "C:\Users\User\AppData\Local\Programs\Python\Python310\lib\logging\__init__.py", line 1687, in callHandlers
    hdlr.handle(record)
  File "C:\Users\User\AppData\Local\Programs\Python\Python310\lib\logging\__init__.py", line 967, in handle
    self.emit(record)
  File "C:\Users\User\PycharmProjects\my_portal\my_portal\settings.py", line 275, in emit
    self.server.send_message(msg, self.fromaddr, self.toaddrs)
  File "C:\Users\User\AppData\Local\Programs\Python\Python310\lib\smtplib.py", line 986, in send_message
    return self.sendmail(from_addr, to_addrs, flatmsg, mail_options,
  File "C:\Users\User\AppData\Local\Programs\Python\Python310\lib\smtplib.py", line 908, in sendmail
    raise SMTPDataError(code, resp)
smtplib.SMTPDataError: (554, b'5.7.1 Message rejected under suspicion of SPAM; https://ya.cc/1IrBc 1724955539-MIbwHU7VvmI0-LIG9Mnkh')
ERROR 2024-08-29 21:18:59,767 log Internal Server Error: /news/
Traceback (most recent call last):
  File "C:\Users\User\AppData\Local\Programs\Python\Python310\lib\site-packages\django\template\base.py", line 502, in parse
    compile_func = self.tags[command]
KeyError: 'endblock'

During handling of the above exception, another exception occurred:

Traceback (most recent call last):
  File "C:\Users\User\AppData\Local\Programs\Python\Python310\lib\site-packages\django\core\handlers\exception.py", line 55, in inner
    response = get_response(request)
  File "C:\Users\User\AppData\Local\Programs\Python\Python310\lib\site-packages\django\core\handlers\base.py", line 220, in _get_response
    response = response.render()
  File "C:\Users\User\AppData\Local\Programs\Python\Python310\lib\site-packages\django\template\response.py", line 114, in render
    self.content = self.rendered_content
  File "C:\Users\User\AppData\Local\Programs\Python\Python310\lib\site-packages\django\template\response.py", line 90, in rendered_content
    template = self.resolve_template(self.template_name)
  File "C:\Users\User\AppData\Local\Programs\Python\Python310\lib\site-packages\django\template\response.py", line 72, in resolve_template
    return select_template(template, using=self.using)
  File "C:\Users\User\AppData\Local\Programs\Python\Python310\lib\site-packages\django\template\loader.py", line 42, in select_template
    return engine.get_template(template_name)
  File "C:\Users\User\AppData\Local\Programs\Python\Python310\lib\site-packages\django\template\backends\django.py", line 33, in get_template
    return Template(self.engine.get_template(template_name), self)
  File "C:\Users\User\AppData\Local\Programs\Python\Python310\lib\site-packages\django\template\engine.py", line 177, in get_template
    template, origin = self.find_template(template_name)
  File "C:\Users\User\AppData\Local\Programs\Python\Python310\lib\site-packages\django\template\engine.py", line 159, in find_template
    template = loader.get_template(name, skip=skip)
  File "C:\Users\User\AppData\Local\Programs\Python\Python310\lib\site-packages\django\template\loaders\cached.py", line 57, in get_template
    template = super().get_template(template_name, skip)
  File "C:\Users\User\AppData\Local\Programs\Python\Python310\lib\site-packages\django\template\loaders\base.py", line 28, in get_template
    return Template(
  File "C:\Users\User\AppData\Local\Programs\Python\Python310\lib\site-packages\django\template\base.py", line 154, in __init__
    self.nodelist = self.compile_nodelist()
  File "C:\Users\User\AppData\Local\Programs\Python\Python310\lib\site-packages\django\template\base.py", line 196, in compile_nodelist
    return parser.parse()
  File "C:\Users\User\AppData\Local\Programs\Python\Python310\lib\site-packages\django\template\base.py", line 510, in parse
    raise self.error(token, e)
  File "C:\Users\User\AppData\Local\Programs\Python\Python310\lib\site-packages\django\template\base.py", line 508, in parse
    compiled_result = compile_func(self, token)
  File "C:\Users\User\AppData\Local\Programs\Python\Python310\lib\site-packages\django\template\loader_tags.py", line 295, in do_extends
    nodelist = parser.parse()
  File "C:\Users\User\AppData\Local\Programs\Python\Python310\lib\site-packages\django\template\base.py", line 510, in parse
    raise self.error(token, e)
  File "C:\Users\User\AppData\Local\Programs\Python\Python310\lib\site-packages\django\template\base.py", line 508, in parse
    compiled_result = compile_func(self, token)
  File "C:\Users\User\AppData\Local\Programs\Python\Python310\lib\site-packages\django\template\loader_tags.py", line 234, in do_block
    nodelist = parser.parse(("endblock",))
  File "C:\Users\User\AppData\Local\Programs\Python\Python310\lib\site-packages\django\template\base.py", line 510, in parse
    raise self.error(token, e)
  File "C:\Users\User\AppData\Local\Programs\Python\Python310\lib\site-packages\django\template\base.py", line 508, in parse
    compiled_result = compile_func(self, token)
  File "C:\Users\User\AppData\Local\Programs\Python\Python310\lib\site-packages\django\templatetags\cache.py", line 84, in do_cache
    nodelist = parser.parse(("endcache",))
  File "C:\Users\User\AppData\Local\Programs\Python\Python310\lib\site-packages\django\template\base.py", line 504, in parse
    self.invalid_block_tag(token, command, parse_until)
  File "C:\Users\User\AppData\Local\Programs\Python\Python310\lib\site-packages\django\template\base.py", line 555, in invalid_block_tag
    raise self.error(
django.template.exceptions.TemplateSyntaxError: Invalid block tag on line 50: 'endblock', expected 'endcache'. Did you forget to register or load this tag?

During handling of the above exception, another exception occurred:

Traceback (most recent call last):
  File "C:\Users\User\AppData\Local\Programs\Python\Python310\lib\site-packages\django\core\handlers\exception.py", line 55, in inner
    response = get_response(request)
  File "C:\Users\User\AppData\Local\Programs\Python\Python310\lib\site-packages\allauth\account\middleware.py", line 37, in middleware
    response = get_response(request)
  File "C:\Users\User\AppData\Local\Programs\Python\Python310\lib\site-packages\django\core\handlers\exception.py", line 57, in inner
    response = response_for_exception(request, exc)
  File "C:\Users\User\AppData\Local\Programs\Python\Python310\lib\site-packages\django\core\handlers\exception.py", line 143, in response_for_exception
    log_response(
  File "C:\Users\User\AppData\Local\Programs\Python\Python310\lib\site-packages\django\utils\log.py", line 241, in log_response
    getattr(logger, level)(
  File "C:\Users\User\AppData\Local\Programs\Python\Python310\lib\logging\__init__.py", line 1497, in error
    self._log(ERROR, msg, args, **kwargs)
  File "C:\Users\User\AppData\Local\Programs\Python\Python310\lib\logging\__init__.py", line 1615, in _log
    self.handle(record)
  File "C:\Users\User\AppData\Local\Programs\Python\Python310\lib\logging\__init__.py", line 1625, in handle
    self.callHandlers(record)
  File "C:\Users\User\AppData\Local\Programs\Python\Python310\lib\logging\__init__.py", line 1687, in callHandlers
    hdlr.handle(record)
  File "C:\Users\User\AppData\Local\Programs\Python\Python310\lib\logging\__init__.py", line 967, in handle
    self.emit(record)
  File "C:\Users\User\PycharmProjects\my_portal\my_portal\settings.py", line 275, in emit
    self.server.send_message(msg, self.fromaddr, self.toaddrs)
  File "C:\Users\User\AppData\Local\Programs\Python\Python310\lib\smtplib.py", line 986, in send_message
    return self.sendmail(from_addr, to_addrs, flatmsg, mail_options,
  File "C:\Users\User\AppData\Local\Programs\Python\Python310\lib\smtplib.py", line 908, in sendmail
    raise SMTPDataError(code, resp)
smtplib.SMTPDataError: (554, b'5.7.1 Message rejected under suspicion of SPAM; https://ya.cc/1IrBc 1724955539-MIbwHU7VvmI0-LIG9Mnkh')

During handling of the above exception, another exception occurred:

Traceback (most recent call last):
  File "C:\Users\User\AppData\Local\Programs\Python\Python310\lib\site-packages\django\core\handlers\exception.py", line 55, in inner
    response = get_response(request)
  File "C:\Users\User\AppData\Local\Programs\Python\Python310\lib\site-packages\django\utils\deprecation.py", line 134, in __call__
    response = response or self.get_response(request)
  File "C:\Users\User\AppData\Local\Programs\Python\Python310\lib\site-packages\django\core\handlers\exception.py", line 57, in inner
    response = response_for_exception(request, exc)
  File "C:\Users\User\AppData\Local\Programs\Python\Python310\lib\site-packages\django\core\handlers\exception.py", line 143, in response_for_exception
    log_response(
  File "C:\Users\User\AppData\Local\Programs\Python\Python310\lib\site-packages\django\utils\log.py", line 241, in log_response
    getattr(logger, level)(
  File "C:\Users\User\AppData\Local\Programs\Python\Python310\lib\logging\__init__.py", line 1497, in error
    self._log(ERROR, msg, args, **kwargs)
  File "C:\Users\User\AppData\Local\Programs\Python\Python310\lib\logging\__init__.py", line 1615, in _log
    self.handle(record)
  File "C:\Users\User\AppData\Local\Programs\Python\Python310\lib\logging\__init__.py", line 1625, in handle
    self.callHandlers(record)
  File "C:\Users\User\AppData\Local\Programs\Python\Python310\lib\logging\__init__.py", line 1687, in callHandlers
    hdlr.handle(record)
  File "C:\Users\User\AppData\Local\Programs\Python\Python310\lib\logging\__init__.py", line 967, in handle
    self.emit(record)
  File "C:\Users\User\PycharmProjects\my_portal\my_portal\settings.py", line 275, in emit
    self.server.send_message(msg, self.fromaddr, self.toaddrs)
  File "C:\Users\User\AppData\Local\Programs\Python\Python310\lib\smtplib.py", line 986, in send_message
    return self.sendmail(from_addr, to_addrs, flatmsg, mail_options,
  File "C:\Users\User\AppData\Local\Programs\Python\Python310\lib\smtplib.py", line 908, in sendmail
    raise SMTPDataError(code, resp)
smtplib.SMTPDataError: (554, b'5.7.1 Message rejected under suspicion of SPAM; https://ya.cc/1IrBc 1724955539-MIbwHU7VvmI0-fa9qjARd')
ERROR 2024-08-29 21:19:00,200 log Internal Server Error: /news/
Traceback (most recent call last):
  File "C:\Users\User\AppData\Local\Programs\Python\Python310\lib\site-packages\django\template\base.py", line 502, in parse
    compile_func = self.tags[command]
KeyError: 'endblock'

During handling of the above exception, another exception occurred:

Traceback (most recent call last):
  File "C:\Users\User\AppData\Local\Programs\Python\Python310\lib\site-packages\django\core\handlers\exception.py", line 55, in inner
    response = get_response(request)
  File "C:\Users\User\AppData\Local\Programs\Python\Python310\lib\site-packages\django\core\handlers\base.py", line 220, in _get_response
    response = response.render()
  File "C:\Users\User\AppData\Local\Programs\Python\Python310\lib\site-packages\django\template\response.py", line 114, in render
    self.content = self.rendered_content
  File "C:\Users\User\AppData\Local\Programs\Python\Python310\lib\site-packages\django\template\response.py", line 90, in rendered_content
    template = self.resolve_template(self.template_name)
  File "C:\Users\User\AppData\Local\Programs\Python\Python310\lib\site-packages\django\template\response.py", line 72, in resolve_template
    return select_template(template, using=self.using)
  File "C:\Users\User\AppData\Local\Programs\Python\Python310\lib\site-packages\django\template\loader.py", line 42, in select_template
    return engine.get_template(template_name)
  File "C:\Users\User\AppData\Local\Programs\Python\Python310\lib\site-packages\django\template\backends\django.py", line 33, in get_template
    return Template(self.engine.get_template(template_name), self)
  File "C:\Users\User\AppData\Local\Programs\Python\Python310\lib\site-packages\django\template\engine.py", line 177, in get_template
    template, origin = self.find_template(template_name)
  File "C:\Users\User\AppData\Local\Programs\Python\Python310\lib\site-packages\django\template\engine.py", line 159, in find_template
    template = loader.get_template(name, skip=skip)
  File "C:\Users\User\AppData\Local\Programs\Python\Python310\lib\site-packages\django\template\loaders\cached.py", line 57, in get_template
    template = super().get_template(template_name, skip)
  File "C:\Users\User\AppData\Local\Programs\Python\Python310\lib\site-packages\django\template\loaders\base.py", line 28, in get_template
    return Template(
  File "C:\Users\User\AppData\Local\Programs\Python\Python310\lib\site-packages\django\template\base.py", line 154, in __init__
    self.nodelist = self.compile_nodelist()
  File "C:\Users\User\AppData\Local\Programs\Python\Python310\lib\site-packages\django\template\base.py", line 196, in compile_nodelist
    return parser.parse()
  File "C:\Users\User\AppData\Local\Programs\Python\Python310\lib\site-packages\django\template\base.py", line 510, in parse
    raise self.error(token, e)
  File "C:\Users\User\AppData\Local\Programs\Python\Python310\lib\site-packages\django\template\base.py", line 508, in parse
    compiled_result = compile_func(self, token)
  File "C:\Users\User\AppData\Local\Programs\Python\Python310\lib\site-packages\django\template\loader_tags.py", line 295, in do_extends
    nodelist = parser.parse()
  File "C:\Users\User\AppData\Local\Programs\Python\Python310\lib\site-packages\django\template\base.py", line 510, in parse
    raise self.error(token, e)
  File "C:\Users\User\AppData\Local\Programs\Python\Python310\lib\site-packages\django\template\base.py", line 508, in parse
    compiled_result = compile_func(self, token)
  File "C:\Users\User\AppData\Local\Programs\Python\Python310\lib\site-packages\django\template\loader_tags.py", line 234, in do_block
    nodelist = parser.parse(("endblock",))
  File "C:\Users\User\AppData\Local\Programs\Python\Python310\lib\site-packages\django\template\base.py", line 510, in parse
    raise self.error(token, e)
  File "C:\Users\User\AppData\Local\Programs\Python\Python310\lib\site-packages\django\template\base.py", line 508, in parse
    compiled_result = compile_func(self, token)
  File "C:\Users\User\AppData\Local\Programs\Python\Python310\lib\site-packages\django\templatetags\cache.py", line 84, in do_cache
    nodelist = parser.parse(("endcache",))
  File "C:\Users\User\AppData\Local\Programs\Python\Python310\lib\site-packages\django\template\base.py", line 504, in parse
    self.invalid_block_tag(token, command, parse_until)
  File "C:\Users\User\AppData\Local\Programs\Python\Python310\lib\site-packages\django\template\base.py", line 555, in invalid_block_tag
    raise self.error(
django.template.exceptions.TemplateSyntaxError: Invalid block tag on line 50: 'endblock', expected 'endcache'. Did you forget to register or load this tag?

During handling of the above exception, another exception occurred:

Traceback (most recent call last):
  File "C:\Users\User\AppData\Local\Programs\Python\Python310\lib\site-packages\django\core\handlers\exception.py", line 55, in inner
    response = get_response(request)
  File "C:\Users\User\AppData\Local\Programs\Python\Python310\lib\site-packages\allauth\account\middleware.py", line 37, in middleware
    response = get_response(request)
  File "C:\Users\User\AppData\Local\Programs\Python\Python310\lib\site-packages\django\core\handlers\exception.py", line 57, in inner
    response = response_for_exception(request, exc)
  File "C:\Users\User\AppData\Local\Programs\Python\Python310\lib\site-packages\django\core\handlers\exception.py", line 143, in response_for_exception
    log_response(
  File "C:\Users\User\AppData\Local\Programs\Python\Python310\lib\site-packages\django\utils\log.py", line 241, in log_response
    getattr(logger, level)(
  File "C:\Users\User\AppData\Local\Programs\Python\Python310\lib\logging\__init__.py", line 1497, in error
    self._log(ERROR, msg, args, **kwargs)
  File "C:\Users\User\AppData\Local\Programs\Python\Python310\lib\logging\__init__.py", line 1615, in _log
    self.handle(record)
  File "C:\Users\User\AppData\Local\Programs\Python\Python310\lib\logging\__init__.py", line 1625, in handle
    self.callHandlers(record)
  File "C:\Users\User\AppData\Local\Programs\Python\Python310\lib\logging\__init__.py", line 1687, in callHandlers
    hdlr.handle(record)
  File "C:\Users\User\AppData\Local\Programs\Python\Python310\lib\logging\__init__.py", line 967, in handle
    self.emit(record)
  File "C:\Users\User\PycharmProjects\my_portal\my_portal\settings.py", line 275, in emit
    self.server.send_message(msg, self.fromaddr, self.toaddrs)
  File "C:\Users\User\AppData\Local\Programs\Python\Python310\lib\smtplib.py", line 986, in send_message
    return self.sendmail(from_addr, to_addrs, flatmsg, mail_options,
  File "C:\Users\User\AppData\Local\Programs\Python\Python310\lib\smtplib.py", line 908, in sendmail
    raise SMTPDataError(code, resp)
smtplib.SMTPDataError: (554, b'5.7.1 Message rejected under suspicion of SPAM; https://ya.cc/1IrBc 1724955539-MIbwHU7VvmI0-LIG9Mnkh')

During handling of the above exception, another exception occurred:

Traceback (most recent call last):
  File "C:\Users\User\AppData\Local\Programs\Python\Python310\lib\site-packages\django\core\handlers\exception.py", line 55, in inner
    response = get_response(request)
  File "C:\Users\User\AppData\Local\Programs\Python\Python310\lib\site-packages\django\utils\deprecation.py", line 134, in __call__
    response = response or self.get_response(request)
  File "C:\Users\User\AppData\Local\Programs\Python\Python310\lib\site-packages\django\core\handlers\exception.py", line 57, in inner
    response = response_for_exception(request, exc)
  File "C:\Users\User\AppData\Local\Programs\Python\Python310\lib\site-packages\django\core\handlers\exception.py", line 143, in response_for_exception
    log_response(
  File "C:\Users\User\AppData\Local\Programs\Python\Python310\lib\site-packages\django\utils\log.py", line 241, in log_response
    getattr(logger, level)(
  File "C:\Users\User\AppData\Local\Programs\Python\Python310\lib\logging\__init__.py", line 1497, in error
    self._log(ERROR, msg, args, **kwargs)
  File "C:\Users\User\AppData\Local\Programs\Python\Python310\lib\logging\__init__.py", line 1615, in _log
    self.handle(record)
  File "C:\Users\User\AppData\Local\Programs\Python\Python310\lib\logging\__init__.py", line 1625, in handle
    self.callHandlers(record)
  File "C:\Users\User\AppData\Local\Programs\Python\Python310\lib\logging\__init__.py", line 1687, in callHandlers
    hdlr.handle(record)
  File "C:\Users\User\AppData\Local\Programs\Python\Python310\lib\logging\__init__.py", line 967, in handle
    self.emit(record)
  File "C:\Users\User\PycharmProjects\my_portal\my_portal\settings.py", line 275, in emit
    self.server.send_message(msg, self.fromaddr, self.toaddrs)
  File "C:\Users\User\AppData\Local\Programs\Python\Python310\lib\smtplib.py", line 986, in send_message
    return self.sendmail(from_addr, to_addrs, flatmsg, mail_options,
  File "C:\Users\User\AppData\Local\Programs\Python\Python310\lib\smtplib.py", line 908, in sendmail
    raise SMTPDataError(code, resp)
smtplib.SMTPDataError: (554, b'5.7.1 Message rejected under suspicion of SPAM; https://ya.cc/1IrBc 1724955539-MIbwHU7VvmI0-fa9qjARd')

During handling of the above exception, another exception occurred:

Traceback (most recent call last):
  File "C:\Users\User\AppData\Local\Programs\Python\Python310\lib\site-packages\django\core\handlers\exception.py", line 55, in inner
    response = get_response(request)
  File "C:\Users\User\AppData\Local\Programs\Python\Python310\lib\site-packages\django\utils\deprecation.py", line 134, in __call__
    response = response or self.get_response(request)
  File "C:\Users\User\AppData\Local\Programs\Python\Python310\lib\site-packages\django\core\handlers\exception.py", line 57, in inner
    response = response_for_exception(request, exc)
  File "C:\Users\User\AppData\Local\Programs\Python\Python310\lib\site-packages\django\core\handlers\exception.py", line 143, in response_for_exception
    log_response(
  File "C:\Users\User\AppData\Local\Programs\Python\Python310\lib\site-packages\django\utils\log.py", line 241, in log_response
    getattr(logger, level)(
  File "C:\Users\User\AppData\Local\Programs\Python\Python310\lib\logging\__init__.py", line 1497, in error
    self._log(ERROR, msg, args, **kwargs)
  File "C:\Users\User\AppData\Local\Programs\Python\Python310\lib\logging\__init__.py", line 1615, in _log
    self.handle(record)
  File "C:\Users\User\AppData\Local\Programs\Python\Python310\lib\logging\__init__.py", line 1625, in handle
    self.callHandlers(record)
  File "C:\Users\User\AppData\Local\Programs\Python\Python310\lib\logging\__init__.py", line 1687, in callHandlers
    hdlr.handle(record)
  File "C:\Users\User\AppData\Local\Programs\Python\Python310\lib\logging\__init__.py", line 967, in handle
    self.emit(record)
  File "C:\Users\User\PycharmProjects\my_portal\my_portal\settings.py", line 275, in emit
    self.server.send_message(msg, self.fromaddr, self.toaddrs)
  File "C:\Users\User\AppData\Local\Programs\Python\Python310\lib\smtplib.py", line 986, in send_message
    return self.sendmail(from_addr, to_addrs, flatmsg, mail_options,
  File "C:\Users\User\AppData\Local\Programs\Python\Python310\lib\smtplib.py", line 908, in sendmail
    raise SMTPDataError(code, resp)
smtplib.SMTPDataError: (554, b'5.7.1 Message rejected under suspicion of SPAM; https://ya.cc/1IrBc 1724955539-MIbwHU7VvmI0-It3ZvrYU')
ERROR 2024-08-29 21:19:00,690 log Internal Server Error: /news/
Traceback (most recent call last):
  File "C:\Users\User\AppData\Local\Programs\Python\Python310\lib\site-packages\django\template\base.py", line 502, in parse
    compile_func = self.tags[command]
KeyError: 'endblock'

During handling of the above exception, another exception occurred:

Traceback (most recent call last):
  File "C:\Users\User\AppData\Local\Programs\Python\Python310\lib\site-packages\django\core\handlers\exception.py", line 55, in inner
    response = get_response(request)
  File "C:\Users\User\AppData\Local\Programs\Python\Python310\lib\site-packages\django\core\handlers\base.py", line 220, in _get_response
    response = response.render()
  File "C:\Users\User\AppData\Local\Programs\Python\Python310\lib\site-packages\django\template\response.py", line 114, in render
    self.content = self.rendered_content
  File "C:\Users\User\AppData\Local\Programs\Python\Python310\lib\site-packages\django\template\response.py", line 90, in rendered_content
    template = self.resolve_template(self.template_name)
  File "C:\Users\User\AppData\Local\Programs\Python\Python310\lib\site-packages\django\template\response.py", line 72, in resolve_template
    return select_template(template, using=self.using)
  File "C:\Users\User\AppData\Local\Programs\Python\Python310\lib\site-packages\django\template\loader.py", line 42, in select_template
    return engine.get_template(template_name)
  File "C:\Users\User\AppData\Local\Programs\Python\Python310\lib\site-packages\django\template\backends\django.py", line 33, in get_template
    return Template(self.engine.get_template(template_name), self)
  File "C:\Users\User\AppData\Local\Programs\Python\Python310\lib\site-packages\django\template\engine.py", line 177, in get_template
    template, origin = self.find_template(template_name)
  File "C:\Users\User\AppData\Local\Programs\Python\Python310\lib\site-packages\django\template\engine.py", line 159, in find_template
    template = loader.get_template(name, skip=skip)
  File "C:\Users\User\AppData\Local\Programs\Python\Python310\lib\site-packages\django\template\loaders\cached.py", line 57, in get_template
    template = super().get_template(template_name, skip)
  File "C:\Users\User\AppData\Local\Programs\Python\Python310\lib\site-packages\django\template\loaders\base.py", line 28, in get_template
    return Template(
  File "C:\Users\User\AppData\Local\Programs\Python\Python310\lib\site-packages\django\template\base.py", line 154, in __init__
    self.nodelist = self.compile_nodelist()
  File "C:\Users\User\AppData\Local\Programs\Python\Python310\lib\site-packages\django\template\base.py", line 196, in compile_nodelist
    return parser.parse()
  File "C:\Users\User\AppData\Local\Programs\Python\Python310\lib\site-packages\django\template\base.py", line 510, in parse
    raise self.error(token, e)
  File "C:\Users\User\AppData\Local\Programs\Python\Python310\lib\site-packages\django\template\base.py", line 508, in parse
    compiled_result = compile_func(self, token)
  File "C:\Users\User\AppData\Local\Programs\Python\Python310\lib\site-packages\django\template\loader_tags.py", line 295, in do_extends
    nodelist = parser.parse()
  File "C:\Users\User\AppData\Local\Programs\Python\Python310\lib\site-packages\django\template\base.py", line 510, in parse
    raise self.error(token, e)
  File "C:\Users\User\AppData\Local\Programs\Python\Python310\lib\site-packages\django\template\base.py", line 508, in parse
    compiled_result = compile_func(self, token)
  File "C:\Users\User\AppData\Local\Programs\Python\Python310\lib\site-packages\django\template\loader_tags.py", line 234, in do_block
    nodelist = parser.parse(("endblock",))
  File "C:\Users\User\AppData\Local\Programs\Python\Python310\lib\site-packages\django\template\base.py", line 510, in parse
    raise self.error(token, e)
  File "C:\Users\User\AppData\Local\Programs\Python\Python310\lib\site-packages\django\template\base.py", line 508, in parse
    compiled_result = compile_func(self, token)
  File "C:\Users\User\AppData\Local\Programs\Python\Python310\lib\site-packages\django\templatetags\cache.py", line 84, in do_cache
    nodelist = parser.parse(("endcache",))
  File "C:\Users\User\AppData\Local\Programs\Python\Python310\lib\site-packages\django\template\base.py", line 504, in parse
    self.invalid_block_tag(token, command, parse_until)
  File "C:\Users\User\AppData\Local\Programs\Python\Python310\lib\site-packages\django\template\base.py", line 555, in invalid_block_tag
    raise self.error(
django.template.exceptions.TemplateSyntaxError: Invalid block tag on line 50: 'endblock', expected 'endcache'. Did you forget to register or load this tag?

During handling of the above exception, another exception occurred:

Traceback (most recent call last):
  File "C:\Users\User\AppData\Local\Programs\Python\Python310\lib\site-packages\django\core\handlers\exception.py", line 55, in inner
    response = get_response(request)
  File "C:\Users\User\AppData\Local\Programs\Python\Python310\lib\site-packages\allauth\account\middleware.py", line 37, in middleware
    response = get_response(request)
  File "C:\Users\User\AppData\Local\Programs\Python\Python310\lib\site-packages\django\core\handlers\exception.py", line 57, in inner
    response = response_for_exception(request, exc)
  File "C:\Users\User\AppData\Local\Programs\Python\Python310\lib\site-packages\django\core\handlers\exception.py", line 143, in response_for_exception
    log_response(
  File "C:\Users\User\AppData\Local\Programs\Python\Python310\lib\site-packages\django\utils\log.py", line 241, in log_response
    getattr(logger, level)(
  File "C:\Users\User\AppData\Local\Programs\Python\Python310\lib\logging\__init__.py", line 1497, in error
    self._log(ERROR, msg, args, **kwargs)
  File "C:\Users\User\AppData\Local\Programs\Python\Python310\lib\logging\__init__.py", line 1615, in _log
    self.handle(record)
  File "C:\Users\User\AppData\Local\Programs\Python\Python310\lib\logging\__init__.py", line 1625, in handle
    self.callHandlers(record)
  File "C:\Users\User\AppData\Local\Programs\Python\Python310\lib\logging\__init__.py", line 1687, in callHandlers
    hdlr.handle(record)
  File "C:\Users\User\AppData\Local\Programs\Python\Python310\lib\logging\__init__.py", line 967, in handle
    self.emit(record)
  File "C:\Users\User\PycharmProjects\my_portal\my_portal\settings.py", line 275, in emit
    self.server.send_message(msg, self.fromaddr, self.toaddrs)
  File "C:\Users\User\AppData\Local\Programs\Python\Python310\lib\smtplib.py", line 986, in send_message
    return self.sendmail(from_addr, to_addrs, flatmsg, mail_options,
  File "C:\Users\User\AppData\Local\Programs\Python\Python310\lib\smtplib.py", line 908, in sendmail
    raise SMTPDataError(code, resp)
smtplib.SMTPDataError: (554, b'5.7.1 Message rejected under suspicion of SPAM; https://ya.cc/1IrBc 1724955539-MIbwHU7VvmI0-LIG9Mnkh')

During handling of the above exception, another exception occurred:

Traceback (most recent call last):
  File "C:\Users\User\AppData\Local\Programs\Python\Python310\lib\site-packages\django\core\handlers\exception.py", line 55, in inner
    response = get_response(request)
  File "C:\Users\User\AppData\Local\Programs\Python\Python310\lib\site-packages\django\utils\deprecation.py", line 134, in __call__
    response = response or self.get_response(request)
  File "C:\Users\User\AppData\Local\Programs\Python\Python310\lib\site-packages\django\core\handlers\exception.py", line 57, in inner
    response = response_for_exception(request, exc)
  File "C:\Users\User\AppData\Local\Programs\Python\Python310\lib\site-packages\django\core\handlers\exception.py", line 143, in response_for_exception
    log_response(
  File "C:\Users\User\AppData\Local\Programs\Python\Python310\lib\site-packages\django\utils\log.py", line 241, in log_response
    getattr(logger, level)(
  File "C:\Users\User\AppData\Local\Programs\Python\Python310\lib\logging\__init__.py", line 1497, in error
    self._log(ERROR, msg, args, **kwargs)
  File "C:\Users\User\AppData\Local\Programs\Python\Python310\lib\logging\__init__.py", line 1615, in _log
    self.handle(record)
  File "C:\Users\User\AppData\Local\Programs\Python\Python310\lib\logging\__init__.py", line 1625, in handle
    self.callHandlers(record)
  File "C:\Users\User\AppData\Local\Programs\Python\Python310\lib\logging\__init__.py", line 1687, in callHandlers
    hdlr.handle(record)
  File "C:\Users\User\AppData\Local\Programs\Python\Python310\lib\logging\__init__.py", line 967, in handle
    self.emit(record)
  File "C:\Users\User\PycharmProjects\my_portal\my_portal\settings.py", line 275, in emit
    self.server.send_message(msg, self.fromaddr, self.toaddrs)
  File "C:\Users\User\AppData\Local\Programs\Python\Python310\lib\smtplib.py", line 986, in send_message
    return self.sendmail(from_addr, to_addrs, flatmsg, mail_options,
  File "C:\Users\User\AppData\Local\Programs\Python\Python310\lib\smtplib.py", line 908, in sendmail
    raise SMTPDataError(code, resp)
smtplib.SMTPDataError: (554, b'5.7.1 Message rejected under suspicion of SPAM; https://ya.cc/1IrBc 1724955539-MIbwHU7VvmI0-fa9qjARd')

During handling of the above exception, another exception occurred:

Traceback (most recent call last):
  File "C:\Users\User\AppData\Local\Programs\Python\Python310\lib\site-packages\django\core\handlers\exception.py", line 55, in inner
    response = get_response(request)
  File "C:\Users\User\AppData\Local\Programs\Python\Python310\lib\site-packages\django\utils\deprecation.py", line 134, in __call__
    response = response or self.get_response(request)
  File "C:\Users\User\AppData\Local\Programs\Python\Python310\lib\site-packages\django\core\handlers\exception.py", line 57, in inner
    response = response_for_exception(request, exc)
  File "C:\Users\User\AppData\Local\Programs\Python\Python310\lib\site-packages\django\core\handlers\exception.py", line 143, in response_for_exception
    log_response(
  File "C:\Users\User\AppData\Local\Programs\Python\Python310\lib\site-packages\django\utils\log.py", line 241, in log_response
    getattr(logger, level)(
  File "C:\Users\User\AppData\Local\Programs\Python\Python310\lib\logging\__init__.py", line 1497, in error
    self._log(ERROR, msg, args, **kwargs)
  File "C:\Users\User\AppData\Local\Programs\Python\Python310\lib\logging\__init__.py", line 1615, in _log
    self.handle(record)
  File "C:\Users\User\AppData\Local\Programs\Python\Python310\lib\logging\__init__.py", line 1625, in handle
    self.callHandlers(record)
  File "C:\Users\User\AppData\Local\Programs\Python\Python310\lib\logging\__init__.py", line 1687, in callHandlers
    hdlr.handle(record)
  File "C:\Users\User\AppData\Local\Programs\Python\Python310\lib\logging\__init__.py", line 967, in handle
    self.emit(record)
  File "C:\Users\User\PycharmProjects\my_portal\my_portal\settings.py", line 275, in emit
    self.server.send_message(msg, self.fromaddr, self.toaddrs)
  File "C:\Users\User\AppData\Local\Programs\Python\Python310\lib\smtplib.py", line 986, in send_message
    return self.sendmail(from_addr, to_addrs, flatmsg, mail_options,
  File "C:\Users\User\AppData\Local\Programs\Python\Python310\lib\smtplib.py", line 908, in sendmail
    raise SMTPDataError(code, resp)
smtplib.SMTPDataError: (554, b'5.7.1 Message rejected under suspicion of SPAM; https://ya.cc/1IrBc 1724955539-MIbwHU7VvmI0-It3ZvrYU')

During handling of the above exception, another exception occurred:

Traceback (most recent call last):
  File "C:\Users\User\AppData\Local\Programs\Python\Python310\lib\site-packages\django\core\handlers\exception.py", line 55, in inner
    response = get_response(request)
  File "C:\Users\User\AppData\Local\Programs\Python\Python310\lib\site-packages\django\utils\deprecation.py", line 134, in __call__
    response = response or self.get_response(request)
  File "C:\Users\User\AppData\Local\Programs\Python\Python310\lib\site-packages\django\core\handlers\exception.py", line 57, in inner
    response = response_for_exception(request, exc)
  File "C:\Users\User\AppData\Local\Programs\Python\Python310\lib\site-packages\django\core\handlers\exception.py", line 143, in response_for_exception
    log_response(
  File "C:\Users\User\AppData\Local\Programs\Python\Python310\lib\site-packages\django\utils\log.py", line 241, in log_response
    getattr(logger, level)(
  File "C:\Users\User\AppData\Local\Programs\Python\Python310\lib\logging\__init__.py", line 1497, in error
    self._log(ERROR, msg, args, **kwargs)
  File "C:\Users\User\AppData\Local\Programs\Python\Python310\lib\logging\__init__.py", line 1615, in _log
    self.handle(record)
  File "C:\Users\User\AppData\Local\Programs\Python\Python310\lib\logging\__init__.py", line 1625, in handle
    self.callHandlers(record)
  File "C:\Users\User\AppData\Local\Programs\Python\Python310\lib\logging\__init__.py", line 1687, in callHandlers
    hdlr.handle(record)
  File "C:\Users\User\AppData\Local\Programs\Python\Python310\lib\logging\__init__.py", line 967, in handle
    self.emit(record)
  File "C:\Users\User\PycharmProjects\my_portal\my_portal\settings.py", line 275, in emit
    self.server.send_message(msg, self.fromaddr, self.toaddrs)
  File "C:\Users\User\AppData\Local\Programs\Python\Python310\lib\smtplib.py", line 986, in send_message
    return self.sendmail(from_addr, to_addrs, flatmsg, mail_options,
  File "C:\Users\User\AppData\Local\Programs\Python\Python310\lib\smtplib.py", line 908, in sendmail
    raise SMTPDataError(code, resp)
smtplib.SMTPDataError: (554, b'5.7.1 Message rejected under suspicion of SPAM; https://ya.cc/1IrBc 1724955540-MIbwHU7VvmI0-fJp7hE4r')
ERROR 2024-08-29 21:19:01,083 log Internal Server Error: /news/
Traceback (most recent call last):
  File "C:\Users\User\AppData\Local\Programs\Python\Python310\lib\site-packages\django\template\base.py", line 502, in parse
    compile_func = self.tags[command]
KeyError: 'endblock'

During handling of the above exception, another exception occurred:

Traceback (most recent call last):
  File "C:\Users\User\AppData\Local\Programs\Python\Python310\lib\site-packages\django\core\handlers\exception.py", line 55, in inner
    response = get_response(request)
  File "C:\Users\User\AppData\Local\Programs\Python\Python310\lib\site-packages\django\core\handlers\base.py", line 220, in _get_response
    response = response.render()
  File "C:\Users\User\AppData\Local\Programs\Python\Python310\lib\site-packages\django\template\response.py", line 114, in render
    self.content = self.rendered_content
  File "C:\Users\User\AppData\Local\Programs\Python\Python310\lib\site-packages\django\template\response.py", line 90, in rendered_content
    template = self.resolve_template(self.template_name)
  File "C:\Users\User\AppData\Local\Programs\Python\Python310\lib\site-packages\django\template\response.py", line 72, in resolve_template
    return select_template(template, using=self.using)
  File "C:\Users\User\AppData\Local\Programs\Python\Python310\lib\site-packages\django\template\loader.py", line 42, in select_template
    return engine.get_template(template_name)
  File "C:\Users\User\AppData\Local\Programs\Python\Python310\lib\site-packages\django\template\backends\django.py", line 33, in get_template
    return Template(self.engine.get_template(template_name), self)
  File "C:\Users\User\AppData\Local\Programs\Python\Python310\lib\site-packages\django\template\engine.py", line 177, in get_template
    template, origin = self.find_template(template_name)
  File "C:\Users\User\AppData\Local\Programs\Python\Python310\lib\site-packages\django\template\engine.py", line 159, in find_template
    template = loader.get_template(name, skip=skip)
  File "C:\Users\User\AppData\Local\Programs\Python\Python310\lib\site-packages\django\template\loaders\cached.py", line 57, in get_template
    template = super().get_template(template_name, skip)
  File "C:\Users\User\AppData\Local\Programs\Python\Python310\lib\site-packages\django\template\loaders\base.py", line 28, in get_template
    return Template(
  File "C:\Users\User\AppData\Local\Programs\Python\Python310\lib\site-packages\django\template\base.py", line 154, in __init__
    self.nodelist = self.compile_nodelist()
  File "C:\Users\User\AppData\Local\Programs\Python\Python310\lib\site-packages\django\template\base.py", line 196, in compile_nodelist
    return parser.parse()
  File "C:\Users\User\AppData\Local\Programs\Python\Python310\lib\site-packages\django\template\base.py", line 510, in parse
    raise self.error(token, e)
  File "C:\Users\User\AppData\Local\Programs\Python\Python310\lib\site-packages\django\template\base.py", line 508, in parse
    compiled_result = compile_func(self, token)
  File "C:\Users\User\AppData\Local\Programs\Python\Python310\lib\site-packages\django\template\loader_tags.py", line 295, in do_extends
    nodelist = parser.parse()
  File "C:\Users\User\AppData\Local\Programs\Python\Python310\lib\site-packages\django\template\base.py", line 510, in parse
    raise self.error(token, e)
  File "C:\Users\User\AppData\Local\Programs\Python\Python310\lib\site-packages\django\template\base.py", line 508, in parse
    compiled_result = compile_func(self, token)
  File "C:\Users\User\AppData\Local\Programs\Python\Python310\lib\site-packages\django\template\loader_tags.py", line 234, in do_block
    nodelist = parser.parse(("endblock",))
  File "C:\Users\User\AppData\Local\Programs\Python\Python310\lib\site-packages\django\template\base.py", line 510, in parse
    raise self.error(token, e)
  File "C:\Users\User\AppData\Local\Programs\Python\Python310\lib\site-packages\django\template\base.py", line 508, in parse
    compiled_result = compile_func(self, token)
  File "C:\Users\User\AppData\Local\Programs\Python\Python310\lib\site-packages\django\templatetags\cache.py", line 84, in do_cache
    nodelist = parser.parse(("endcache",))
  File "C:\Users\User\AppData\Local\Programs\Python\Python310\lib\site-packages\django\template\base.py", line 504, in parse
    self.invalid_block_tag(token, command, parse_until)
  File "C:\Users\User\AppData\Local\Programs\Python\Python310\lib\site-packages\django\template\base.py", line 555, in invalid_block_tag
    raise self.error(
django.template.exceptions.TemplateSyntaxError: Invalid block tag on line 50: 'endblock', expected 'endcache'. Did you forget to register or load this tag?

During handling of the above exception, another exception occurred:

Traceback (most recent call last):
  File "C:\Users\User\AppData\Local\Programs\Python\Python310\lib\site-packages\django\core\handlers\exception.py", line 55, in inner
    response = get_response(request)
  File "C:\Users\User\AppData\Local\Programs\Python\Python310\lib\site-packages\allauth\account\middleware.py", line 37, in middleware
    response = get_response(request)
  File "C:\Users\User\AppData\Local\Programs\Python\Python310\lib\site-packages\django\core\handlers\exception.py", line 57, in inner
    response = response_for_exception(request, exc)
  File "C:\Users\User\AppData\Local\Programs\Python\Python310\lib\site-packages\django\core\handlers\exception.py", line 143, in response_for_exception
    log_response(
  File "C:\Users\User\AppData\Local\Programs\Python\Python310\lib\site-packages\django\utils\log.py", line 241, in log_response
    getattr(logger, level)(
  File "C:\Users\User\AppData\Local\Programs\Python\Python310\lib\logging\__init__.py", line 1497, in error
    self._log(ERROR, msg, args, **kwargs)
  File "C:\Users\User\AppData\Local\Programs\Python\Python310\lib\logging\__init__.py", line 1615, in _log
    self.handle(record)
  File "C:\Users\User\AppData\Local\Programs\Python\Python310\lib\logging\__init__.py", line 1625, in handle
    self.callHandlers(record)
  File "C:\Users\User\AppData\Local\Programs\Python\Python310\lib\logging\__init__.py", line 1687, in callHandlers
    hdlr.handle(record)
  File "C:\Users\User\AppData\Local\Programs\Python\Python310\lib\logging\__init__.py", line 967, in handle
    self.emit(record)
  File "C:\Users\User\PycharmProjects\my_portal\my_portal\settings.py", line 275, in emit
    self.server.send_message(msg, self.fromaddr, self.toaddrs)
  File "C:\Users\User\AppData\Local\Programs\Python\Python310\lib\smtplib.py", line 986, in send_message
    return self.sendmail(from_addr, to_addrs, flatmsg, mail_options,
  File "C:\Users\User\AppData\Local\Programs\Python\Python310\lib\smtplib.py", line 908, in sendmail
    raise SMTPDataError(code, resp)
smtplib.SMTPDataError: (554, b'5.7.1 Message rejected under suspicion of SPAM; https://ya.cc/1IrBc 1724955539-MIbwHU7VvmI0-LIG9Mnkh')

During handling of the above exception, another exception occurred:

Traceback (most recent call last):
  File "C:\Users\User\AppData\Local\Programs\Python\Python310\lib\site-packages\django\core\handlers\exception.py", line 55, in inner
    response = get_response(request)
  File "C:\Users\User\AppData\Local\Programs\Python\Python310\lib\site-packages\django\utils\deprecation.py", line 134, in __call__
    response = response or self.get_response(request)
  File "C:\Users\User\AppData\Local\Programs\Python\Python310\lib\site-packages\django\core\handlers\exception.py", line 57, in inner
    response = response_for_exception(request, exc)
  File "C:\Users\User\AppData\Local\Programs\Python\Python310\lib\site-packages\django\core\handlers\exception.py", line 143, in response_for_exception
    log_response(
  File "C:\Users\User\AppData\Local\Programs\Python\Python310\lib\site-packages\django\utils\log.py", line 241, in log_response
    getattr(logger, level)(
  File "C:\Users\User\AppData\Local\Programs\Python\Python310\lib\logging\__init__.py", line 1497, in error
    self._log(ERROR, msg, args, **kwargs)
  File "C:\Users\User\AppData\Local\Programs\Python\Python310\lib\logging\__init__.py", line 1615, in _log
    self.handle(record)
  File "C:\Users\User\AppData\Local\Programs\Python\Python310\lib\logging\__init__.py", line 1625, in handle
    self.callHandlers(record)
  File "C:\Users\User\AppData\Local\Programs\Python\Python310\lib\logging\__init__.py", line 1687, in callHandlers
    hdlr.handle(record)
  File "C:\Users\User\AppData\Local\Programs\Python\Python310\lib\logging\__init__.py", line 967, in handle
    self.emit(record)
  File "C:\Users\User\PycharmProjects\my_portal\my_portal\settings.py", line 275, in emit
    self.server.send_message(msg, self.fromaddr, self.toaddrs)
  File "C:\Users\User\AppData\Local\Programs\Python\Python310\lib\smtplib.py", line 986, in send_message
    return self.sendmail(from_addr, to_addrs, flatmsg, mail_options,
  File "C:\Users\User\AppData\Local\Programs\Python\Python310\lib\smtplib.py", line 908, in sendmail
    raise SMTPDataError(code, resp)
smtplib.SMTPDataError: (554, b'5.7.1 Message rejected under suspicion of SPAM; https://ya.cc/1IrBc 1724955539-MIbwHU7VvmI0-fa9qjARd')

During handling of the above exception, another exception occurred:

Traceback (most recent call last):
  File "C:\Users\User\AppData\Local\Programs\Python\Python310\lib\site-packages\django\core\handlers\exception.py", line 55, in inner
    response = get_response(request)
  File "C:\Users\User\AppData\Local\Programs\Python\Python310\lib\site-packages\django\utils\deprecation.py", line 134, in __call__
    response = response or self.get_response(request)
  File "C:\Users\User\AppData\Local\Programs\Python\Python310\lib\site-packages\django\core\handlers\exception.py", line 57, in inner
    response = response_for_exception(request, exc)
  File "C:\Users\User\AppData\Local\Programs\Python\Python310\lib\site-packages\django\core\handlers\exception.py", line 143, in response_for_exception
    log_response(
  File "C:\Users\User\AppData\Local\Programs\Python\Python310\lib\site-packages\django\utils\log.py", line 241, in log_response
    getattr(logger, level)(
  File "C:\Users\User\AppData\Local\Programs\Python\Python310\lib\logging\__init__.py", line 1497, in error
    self._log(ERROR, msg, args, **kwargs)
  File "C:\Users\User\AppData\Local\Programs\Python\Python310\lib\logging\__init__.py", line 1615, in _log
    self.handle(record)
  File "C:\Users\User\AppData\Local\Programs\Python\Python310\lib\logging\__init__.py", line 1625, in handle
    self.callHandlers(record)
  File "C:\Users\User\AppData\Local\Programs\Python\Python310\lib\logging\__init__.py", line 1687, in callHandlers
    hdlr.handle(record)
  File "C:\Users\User\AppData\Local\Programs\Python\Python310\lib\logging\__init__.py", line 967, in handle
    self.emit(record)
  File "C:\Users\User\PycharmProjects\my_portal\my_portal\settings.py", line 275, in emit
    self.server.send_message(msg, self.fromaddr, self.toaddrs)
  File "C:\Users\User\AppData\Local\Programs\Python\Python310\lib\smtplib.py", line 986, in send_message
    return self.sendmail(from_addr, to_addrs, flatmsg, mail_options,
  File "C:\Users\User\AppData\Local\Programs\Python\Python310\lib\smtplib.py", line 908, in sendmail
    raise SMTPDataError(code, resp)
smtplib.SMTPDataError: (554, b'5.7.1 Message rejected under suspicion of SPAM; https://ya.cc/1IrBc 1724955539-MIbwHU7VvmI0-It3ZvrYU')

During handling of the above exception, another exception occurred:

Traceback (most recent call last):
  File "C:\Users\User\AppData\Local\Programs\Python\Python310\lib\site-packages\django\core\handlers\exception.py", line 55, in inner
    response = get_response(request)
  File "C:\Users\User\AppData\Local\Programs\Python\Python310\lib\site-packages\django\utils\deprecation.py", line 134, in __call__
    response = response or self.get_response(request)
  File "C:\Users\User\AppData\Local\Programs\Python\Python310\lib\site-packages\django\core\handlers\exception.py", line 57, in inner
    response = response_for_exception(request, exc)
  File "C:\Users\User\AppData\Local\Programs\Python\Python310\lib\site-packages\django\core\handlers\exception.py", line 143, in response_for_exception
    log_response(
  File "C:\Users\User\AppData\Local\Programs\Python\Python310\lib\site-packages\django\utils\log.py", line 241, in log_response
    getattr(logger, level)(
  File "C:\Users\User\AppData\Local\Programs\Python\Python310\lib\logging\__init__.py", line 1497, in error
    self._log(ERROR, msg, args, **kwargs)
  File "C:\Users\User\AppData\Local\Programs\Python\Python310\lib\logging\__init__.py", line 1615, in _log
    self.handle(record)
  File "C:\Users\User\AppData\Local\Programs\Python\Python310\lib\logging\__init__.py", line 1625, in handle
    self.callHandlers(record)
  File "C:\Users\User\AppData\Local\Programs\Python\Python310\lib\logging\__init__.py", line 1687, in callHandlers
    hdlr.handle(record)
  File "C:\Users\User\AppData\Local\Programs\Python\Python310\lib\logging\__init__.py", line 967, in handle
    self.emit(record)
  File "C:\Users\User\PycharmProjects\my_portal\my_portal\settings.py", line 275, in emit
    self.server.send_message(msg, self.fromaddr, self.toaddrs)
  File "C:\Users\User\AppData\Local\Programs\Python\Python310\lib\smtplib.py", line 986, in send_message
    return self.sendmail(from_addr, to_addrs, flatmsg, mail_options,
  File "C:\Users\User\AppData\Local\Programs\Python\Python310\lib\smtplib.py", line 908, in sendmail
    raise SMTPDataError(code, resp)
smtplib.SMTPDataError: (554, b'5.7.1 Message rejected under suspicion of SPAM; https://ya.cc/1IrBc 1724955540-MIbwHU7VvmI0-fJp7hE4r')

During handling of the above exception, another exception occurred:

Traceback (most recent call last):
  File "C:\Users\User\AppData\Local\Programs\Python\Python310\lib\site-packages\django\core\handlers\exception.py", line 55, in inner
    response = get_response(request)
  File "C:\Users\User\AppData\Local\Programs\Python\Python310\lib\site-packages\django\utils\deprecation.py", line 134, in __call__
    response = response or self.get_response(request)
  File "C:\Users\User\AppData\Local\Programs\Python\Python310\lib\site-packages\django\core\handlers\exception.py", line 57, in inner
    response = response_for_exception(request, exc)
  File "C:\Users\User\AppData\Local\Programs\Python\Python310\lib\site-packages\django\core\handlers\exception.py", line 143, in response_for_exception
    log_response(
  File "C:\Users\User\AppData\Local\Programs\Python\Python310\lib\site-packages\django\utils\log.py", line 241, in log_response
    getattr(logger, level)(
  File "C:\Users\User\AppData\Local\Programs\Python\Python310\lib\logging\__init__.py", line 1497, in error
    self._log(ERROR, msg, args, **kwargs)
  File "C:\Users\User\AppData\Local\Programs\Python\Python310\lib\logging\__init__.py", line 1615, in _log
    self.handle(record)
  File "C:\Users\User\AppData\Local\Programs\Python\Python310\lib\logging\__init__.py", line 1625, in handle
    self.callHandlers(record)
  File "C:\Users\User\AppData\Local\Programs\Python\Python310\lib\logging\__init__.py", line 1687, in callHandlers
    hdlr.handle(record)
  File "C:\Users\User\AppData\Local\Programs\Python\Python310\lib\logging\__init__.py", line 967, in handle
    self.emit(record)
  File "C:\Users\User\PycharmProjects\my_portal\my_portal\settings.py", line 275, in emit
    self.server.send_message(msg, self.fromaddr, self.toaddrs)
  File "C:\Users\User\AppData\Local\Programs\Python\Python310\lib\smtplib.py", line 986, in send_message
    return self.sendmail(from_addr, to_addrs, flatmsg, mail_options,
  File "C:\Users\User\AppData\Local\Programs\Python\Python310\lib\smtplib.py", line 908, in sendmail
    raise SMTPDataError(code, resp)
smtplib.SMTPDataError: (554, b'5.7.1 Message rejected under suspicion of SPAM; https://ya.cc/1IrBc 1724955540-MIbwHU7VvmI0-xLCQ6IvG')
ERROR 2024-08-29 21:19:01,582 log Internal Server Error: /news/
Traceback (most recent call last):
  File "C:\Users\User\AppData\Local\Programs\Python\Python310\lib\site-packages\django\template\base.py", line 502, in parse
    compile_func = self.tags[command]
KeyError: 'endblock'

During handling of the above exception, another exception occurred:

Traceback (most recent call last):
  File "C:\Users\User\AppData\Local\Programs\Python\Python310\lib\site-packages\django\core\handlers\exception.py", line 55, in inner
    response = get_response(request)
  File "C:\Users\User\AppData\Local\Programs\Python\Python310\lib\site-packages\django\core\handlers\base.py", line 220, in _get_response
    response = response.render()
  File "C:\Users\User\AppData\Local\Programs\Python\Python310\lib\site-packages\django\template\response.py", line 114, in render
    self.content = self.rendered_content
  File "C:\Users\User\AppData\Local\Programs\Python\Python310\lib\site-packages\django\template\response.py", line 90, in rendered_content
    template = self.resolve_template(self.template_name)
  File "C:\Users\User\AppData\Local\Programs\Python\Python310\lib\site-packages\django\template\response.py", line 72, in resolve_template
    return select_template(template, using=self.using)
  File "C:\Users\User\AppData\Local\Programs\Python\Python310\lib\site-packages\django\template\loader.py", line 42, in select_template
    return engine.get_template(template_name)
  File "C:\Users\User\AppData\Local\Programs\Python\Python310\lib\site-packages\django\template\backends\django.py", line 33, in get_template
    return Template(self.engine.get_template(template_name), self)
  File "C:\Users\User\AppData\Local\Programs\Python\Python310\lib\site-packages\django\template\engine.py", line 177, in get_template
    template, origin = self.find_template(template_name)
  File "C:\Users\User\AppData\Local\Programs\Python\Python310\lib\site-packages\django\template\engine.py", line 159, in find_template
    template = loader.get_template(name, skip=skip)
  File "C:\Users\User\AppData\Local\Programs\Python\Python310\lib\site-packages\django\template\loaders\cached.py", line 57, in get_template
    template = super().get_template(template_name, skip)
  File "C:\Users\User\AppData\Local\Programs\Python\Python310\lib\site-packages\django\template\loaders\base.py", line 28, in get_template
    return Template(
  File "C:\Users\User\AppData\Local\Programs\Python\Python310\lib\site-packages\django\template\base.py", line 154, in __init__
    self.nodelist = self.compile_nodelist()
  File "C:\Users\User\AppData\Local\Programs\Python\Python310\lib\site-packages\django\template\base.py", line 196, in compile_nodelist
    return parser.parse()
  File "C:\Users\User\AppData\Local\Programs\Python\Python310\lib\site-packages\django\template\base.py", line 510, in parse
    raise self.error(token, e)
  File "C:\Users\User\AppData\Local\Programs\Python\Python310\lib\site-packages\django\template\base.py", line 508, in parse
    compiled_result = compile_func(self, token)
  File "C:\Users\User\AppData\Local\Programs\Python\Python310\lib\site-packages\django\template\loader_tags.py", line 295, in do_extends
    nodelist = parser.parse()
  File "C:\Users\User\AppData\Local\Programs\Python\Python310\lib\site-packages\django\template\base.py", line 510, in parse
    raise self.error(token, e)
  File "C:\Users\User\AppData\Local\Programs\Python\Python310\lib\site-packages\django\template\base.py", line 508, in parse
    compiled_result = compile_func(self, token)
  File "C:\Users\User\AppData\Local\Programs\Python\Python310\lib\site-packages\django\template\loader_tags.py", line 234, in do_block
    nodelist = parser.parse(("endblock",))
  File "C:\Users\User\AppData\Local\Programs\Python\Python310\lib\site-packages\django\template\base.py", line 510, in parse
    raise self.error(token, e)
  File "C:\Users\User\AppData\Local\Programs\Python\Python310\lib\site-packages\django\template\base.py", line 508, in parse
    compiled_result = compile_func(self, token)
  File "C:\Users\User\AppData\Local\Programs\Python\Python310\lib\site-packages\django\templatetags\cache.py", line 84, in do_cache
    nodelist = parser.parse(("endcache",))
  File "C:\Users\User\AppData\Local\Programs\Python\Python310\lib\site-packages\django\template\base.py", line 504, in parse
    self.invalid_block_tag(token, command, parse_until)
  File "C:\Users\User\AppData\Local\Programs\Python\Python310\lib\site-packages\django\template\base.py", line 555, in invalid_block_tag
    raise self.error(
django.template.exceptions.TemplateSyntaxError: Invalid block tag on line 50: 'endblock', expected 'endcache'. Did you forget to register or load this tag?

During handling of the above exception, another exception occurred:

Traceback (most recent call last):
  File "C:\Users\User\AppData\Local\Programs\Python\Python310\lib\site-packages\django\core\handlers\exception.py", line 55, in inner
    response = get_response(request)
  File "C:\Users\User\AppData\Local\Programs\Python\Python310\lib\site-packages\allauth\account\middleware.py", line 37, in middleware
    response = get_response(request)
  File "C:\Users\User\AppData\Local\Programs\Python\Python310\lib\site-packages\django\core\handlers\exception.py", line 57, in inner
    response = response_for_exception(request, exc)
  File "C:\Users\User\AppData\Local\Programs\Python\Python310\lib\site-packages\django\core\handlers\exception.py", line 143, in response_for_exception
    log_response(
  File "C:\Users\User\AppData\Local\Programs\Python\Python310\lib\site-packages\django\utils\log.py", line 241, in log_response
    getattr(logger, level)(
  File "C:\Users\User\AppData\Local\Programs\Python\Python310\lib\logging\__init__.py", line 1497, in error
    self._log(ERROR, msg, args, **kwargs)
  File "C:\Users\User\AppData\Local\Programs\Python\Python310\lib\logging\__init__.py", line 1615, in _log
    self.handle(record)
  File "C:\Users\User\AppData\Local\Programs\Python\Python310\lib\logging\__init__.py", line 1625, in handle
    self.callHandlers(record)
  File "C:\Users\User\AppData\Local\Programs\Python\Python310\lib\logging\__init__.py", line 1687, in callHandlers
    hdlr.handle(record)
  File "C:\Users\User\AppData\Local\Programs\Python\Python310\lib\logging\__init__.py", line 967, in handle
    self.emit(record)
  File "C:\Users\User\PycharmProjects\my_portal\my_portal\settings.py", line 275, in emit
    self.server.send_message(msg, self.fromaddr, self.toaddrs)
  File "C:\Users\User\AppData\Local\Programs\Python\Python310\lib\smtplib.py", line 986, in send_message
    return self.sendmail(from_addr, to_addrs, flatmsg, mail_options,
  File "C:\Users\User\AppData\Local\Programs\Python\Python310\lib\smtplib.py", line 908, in sendmail
    raise SMTPDataError(code, resp)
smtplib.SMTPDataError: (554, b'5.7.1 Message rejected under suspicion of SPAM; https://ya.cc/1IrBc 1724955539-MIbwHU7VvmI0-LIG9Mnkh')

During handling of the above exception, another exception occurred:

Traceback (most recent call last):
  File "C:\Users\User\AppData\Local\Programs\Python\Python310\lib\site-packages\django\core\handlers\exception.py", line 55, in inner
    response = get_response(request)
  File "C:\Users\User\AppData\Local\Programs\Python\Python310\lib\site-packages\django\utils\deprecation.py", line 134, in __call__
    response = response or self.get_response(request)
  File "C:\Users\User\AppData\Local\Programs\Python\Python310\lib\site-packages\django\core\handlers\exception.py", line 57, in inner
    response = response_for_exception(request, exc)
  File "C:\Users\User\AppData\Local\Programs\Python\Python310\lib\site-packages\django\core\handlers\exception.py", line 143, in response_for_exception
    log_response(
  File "C:\Users\User\AppData\Local\Programs\Python\Python310\lib\site-packages\django\utils\log.py", line 241, in log_response
    getattr(logger, level)(
  File "C:\Users\User\AppData\Local\Programs\Python\Python310\lib\logging\__init__.py", line 1497, in error
    self._log(ERROR, msg, args, **kwargs)
  File "C:\Users\User\AppData\Local\Programs\Python\Python310\lib\logging\__init__.py", line 1615, in _log
    self.handle(record)
  File "C:\Users\User\AppData\Local\Programs\Python\Python310\lib\logging\__init__.py", line 1625, in handle
    self.callHandlers(record)
  File "C:\Users\User\AppData\Local\Programs\Python\Python310\lib\logging\__init__.py", line 1687, in callHandlers
    hdlr.handle(record)
  File "C:\Users\User\AppData\Local\Programs\Python\Python310\lib\logging\__init__.py", line 967, in handle
    self.emit(record)
  File "C:\Users\User\PycharmProjects\my_portal\my_portal\settings.py", line 275, in emit
    self.server.send_message(msg, self.fromaddr, self.toaddrs)
  File "C:\Users\User\AppData\Local\Programs\Python\Python310\lib\smtplib.py", line 986, in send_message
    return self.sendmail(from_addr, to_addrs, flatmsg, mail_options,
  File "C:\Users\User\AppData\Local\Programs\Python\Python310\lib\smtplib.py", line 908, in sendmail
    raise SMTPDataError(code, resp)
smtplib.SMTPDataError: (554, b'5.7.1 Message rejected under suspicion of SPAM; https://ya.cc/1IrBc 1724955539-MIbwHU7VvmI0-fa9qjARd')

During handling of the above exception, another exception occurred:

Traceback (most recent call last):
  File "C:\Users\User\AppData\Local\Programs\Python\Python310\lib\site-packages\django\core\handlers\exception.py", line 55, in inner
    response = get_response(request)
  File "C:\Users\User\AppData\Local\Programs\Python\Python310\lib\site-packages\django\utils\deprecation.py", line 134, in __call__
    response = response or self.get_response(request)
  File "C:\Users\User\AppData\Local\Programs\Python\Python310\lib\site-packages\django\core\handlers\exception.py", line 57, in inner
    response = response_for_exception(request, exc)
  File "C:\Users\User\AppData\Local\Programs\Python\Python310\lib\site-packages\django\core\handlers\exception.py", line 143, in response_for_exception
    log_response(
  File "C:\Users\User\AppData\Local\Programs\Python\Python310\lib\site-packages\django\utils\log.py", line 241, in log_response
    getattr(logger, level)(
  File "C:\Users\User\AppData\Local\Programs\Python\Python310\lib\logging\__init__.py", line 1497, in error
    self._log(ERROR, msg, args, **kwargs)
  File "C:\Users\User\AppData\Local\Programs\Python\Python310\lib\logging\__init__.py", line 1615, in _log
    self.handle(record)
  File "C:\Users\User\AppData\Local\Programs\Python\Python310\lib\logging\__init__.py", line 1625, in handle
    self.callHandlers(record)
  File "C:\Users\User\AppData\Local\Programs\Python\Python310\lib\logging\__init__.py", line 1687, in callHandlers
    hdlr.handle(record)
  File "C:\Users\User\AppData\Local\Programs\Python\Python310\lib\logging\__init__.py", line 967, in handle
    self.emit(record)
  File "C:\Users\User\PycharmProjects\my_portal\my_portal\settings.py", line 275, in emit
    self.server.send_message(msg, self.fromaddr, self.toaddrs)
  File "C:\Users\User\AppData\Local\Programs\Python\Python310\lib\smtplib.py", line 986, in send_message
    return self.sendmail(from_addr, to_addrs, flatmsg, mail_options,
  File "C:\Users\User\AppData\Local\Programs\Python\Python310\lib\smtplib.py", line 908, in sendmail
    raise SMTPDataError(code, resp)
smtplib.SMTPDataError: (554, b'5.7.1 Message rejected under suspicion of SPAM; https://ya.cc/1IrBc 1724955539-MIbwHU7VvmI0-It3ZvrYU')

During handling of the above exception, another exception occurred:

Traceback (most recent call last):
  File "C:\Users\User\AppData\Local\Programs\Python\Python310\lib\site-packages\django\core\handlers\exception.py", line 55, in inner
    response = get_response(request)
  File "C:\Users\User\AppData\Local\Programs\Python\Python310\lib\site-packages\django\utils\deprecation.py", line 134, in __call__
    response = response or self.get_response(request)
  File "C:\Users\User\AppData\Local\Programs\Python\Python310\lib\site-packages\django\core\handlers\exception.py", line 57, in inner
    response = response_for_exception(request, exc)
  File "C:\Users\User\AppData\Local\Programs\Python\Python310\lib\site-packages\django\core\handlers\exception.py", line 143, in response_for_exception
    log_response(
  File "C:\Users\User\AppData\Local\Programs\Python\Python310\lib\site-packages\django\utils\log.py", line 241, in log_response
    getattr(logger, level)(
  File "C:\Users\User\AppData\Local\Programs\Python\Python310\lib\logging\__init__.py", line 1497, in error
    self._log(ERROR, msg, args, **kwargs)
  File "C:\Users\User\AppData\Local\Programs\Python\Python310\lib\logging\__init__.py", line 1615, in _log
    self.handle(record)
  File "C:\Users\User\AppData\Local\Programs\Python\Python310\lib\logging\__init__.py", line 1625, in handle
    self.callHandlers(record)
  File "C:\Users\User\AppData\Local\Programs\Python\Python310\lib\logging\__init__.py", line 1687, in callHandlers
    hdlr.handle(record)
  File "C:\Users\User\AppData\Local\Programs\Python\Python310\lib\logging\__init__.py", line 967, in handle
    self.emit(record)
  File "C:\Users\User\PycharmProjects\my_portal\my_portal\settings.py", line 275, in emit
    self.server.send_message(msg, self.fromaddr, self.toaddrs)
  File "C:\Users\User\AppData\Local\Programs\Python\Python310\lib\smtplib.py", line 986, in send_message
    return self.sendmail(from_addr, to_addrs, flatmsg, mail_options,
  File "C:\Users\User\AppData\Local\Programs\Python\Python310\lib\smtplib.py", line 908, in sendmail
    raise SMTPDataError(code, resp)
smtplib.SMTPDataError: (554, b'5.7.1 Message rejected under suspicion of SPAM; https://ya.cc/1IrBc 1724955540-MIbwHU7VvmI0-fJp7hE4r')

During handling of the above exception, another exception occurred:

Traceback (most recent call last):
  File "C:\Users\User\AppData\Local\Programs\Python\Python310\lib\site-packages\django\core\handlers\exception.py", line 55, in inner
    response = get_response(request)
  File "C:\Users\User\AppData\Local\Programs\Python\Python310\lib\site-packages\django\utils\deprecation.py", line 134, in __call__
    response = response or self.get_response(request)
  File "C:\Users\User\AppData\Local\Programs\Python\Python310\lib\site-packages\django\core\handlers\exception.py", line 57, in inner
    response = response_for_exception(request, exc)
  File "C:\Users\User\AppData\Local\Programs\Python\Python310\lib\site-packages\django\core\handlers\exception.py", line 143, in response_for_exception
    log_response(
  File "C:\Users\User\AppData\Local\Programs\Python\Python310\lib\site-packages\django\utils\log.py", line 241, in log_response
    getattr(logger, level)(
  File "C:\Users\User\AppData\Local\Programs\Python\Python310\lib\logging\__init__.py", line 1497, in error
    self._log(ERROR, msg, args, **kwargs)
  File "C:\Users\User\AppData\Local\Programs\Python\Python310\lib\logging\__init__.py", line 1615, in _log
    self.handle(record)
  File "C:\Users\User\AppData\Local\Programs\Python\Python310\lib\logging\__init__.py", line 1625, in handle
    self.callHandlers(record)
  File "C:\Users\User\AppData\Local\Programs\Python\Python310\lib\logging\__init__.py", line 1687, in callHandlers
    hdlr.handle(record)
  File "C:\Users\User\AppData\Local\Programs\Python\Python310\lib\logging\__init__.py", line 967, in handle
    self.emit(record)
  File "C:\Users\User\PycharmProjects\my_portal\my_portal\settings.py", line 275, in emit
    self.server.send_message(msg, self.fromaddr, self.toaddrs)
  File "C:\Users\User\AppData\Local\Programs\Python\Python310\lib\smtplib.py", line 986, in send_message
    return self.sendmail(from_addr, to_addrs, flatmsg, mail_options,
  File "C:\Users\User\AppData\Local\Programs\Python\Python310\lib\smtplib.py", line 908, in sendmail
    raise SMTPDataError(code, resp)
smtplib.SMTPDataError: (554, b'5.7.1 Message rejected under suspicion of SPAM; https://ya.cc/1IrBc 1724955540-MIbwHU7VvmI0-xLCQ6IvG')

During handling of the above exception, another exception occurred:

Traceback (most recent call last):
  File "C:\Users\User\AppData\Local\Programs\Python\Python310\lib\site-packages\django\core\handlers\exception.py", line 55, in inner
    response = get_response(request)
  File "C:\Users\User\AppData\Local\Programs\Python\Python310\lib\site-packages\django\utils\deprecation.py", line 134, in __call__
    response = response or self.get_response(request)
  File "C:\Users\User\AppData\Local\Programs\Python\Python310\lib\site-packages\django\core\handlers\exception.py", line 57, in inner
    response = response_for_exception(request, exc)
  File "C:\Users\User\AppData\Local\Programs\Python\Python310\lib\site-packages\django\core\handlers\exception.py", line 143, in response_for_exception
    log_response(
  File "C:\Users\User\AppData\Local\Programs\Python\Python310\lib\site-packages\django\utils\log.py", line 241, in log_response
    getattr(logger, level)(
  File "C:\Users\User\AppData\Local\Programs\Python\Python310\lib\logging\__init__.py", line 1497, in error
    self._log(ERROR, msg, args, **kwargs)
  File "C:\Users\User\AppData\Local\Programs\Python\Python310\lib\logging\__init__.py", line 1615, in _log
    self.handle(record)
  File "C:\Users\User\AppData\Local\Programs\Python\Python310\lib\logging\__init__.py", line 1625, in handle
    self.callHandlers(record)
  File "C:\Users\User\AppData\Local\Programs\Python\Python310\lib\logging\__init__.py", line 1687, in callHandlers
    hdlr.handle(record)
  File "C:\Users\User\AppData\Local\Programs\Python\Python310\lib\logging\__init__.py", line 967, in handle
    self.emit(record)
  File "C:\Users\User\PycharmProjects\my_portal\my_portal\settings.py", line 275, in emit
    self.server.send_message(msg, self.fromaddr, self.toaddrs)
  File "C:\Users\User\AppData\Local\Programs\Python\Python310\lib\smtplib.py", line 986, in send_message
    return self.sendmail(from_addr, to_addrs, flatmsg, mail_options,
  File "C:\Users\User\AppData\Local\Programs\Python\Python310\lib\smtplib.py", line 908, in sendmail
    raise SMTPDataError(code, resp)
smtplib.SMTPDataError: (554, b'5.7.1 Message rejected under suspicion of SPAM; https://ya.cc/1IrBc 1724955541-MIbwHU7VvmI0-2Mm21fZy')
ERROR 2024-08-29 21:19:01,663 log Internal Server Error: /news/
Traceback (most recent call last):
  File "C:\Users\User\AppData\Local\Programs\Python\Python310\lib\site-packages\django\template\base.py", line 502, in parse
    compile_func = self.tags[command]
KeyError: 'endblock'

During handling of the above exception, another exception occurred:

Traceback (most recent call last):
  File "C:\Users\User\AppData\Local\Programs\Python\Python310\lib\site-packages\django\core\handlers\exception.py", line 55, in inner
    response = get_response(request)
  File "C:\Users\User\AppData\Local\Programs\Python\Python310\lib\site-packages\django\core\handlers\base.py", line 220, in _get_response
    response = response.render()
  File "C:\Users\User\AppData\Local\Programs\Python\Python310\lib\site-packages\django\template\response.py", line 114, in render
    self.content = self.rendered_content
  File "C:\Users\User\AppData\Local\Programs\Python\Python310\lib\site-packages\django\template\response.py", line 90, in rendered_content
    template = self.resolve_template(self.template_name)
  File "C:\Users\User\AppData\Local\Programs\Python\Python310\lib\site-packages\django\template\response.py", line 72, in resolve_template
    return select_template(template, using=self.using)
  File "C:\Users\User\AppData\Local\Programs\Python\Python310\lib\site-packages\django\template\loader.py", line 42, in select_template
    return engine.get_template(template_name)
  File "C:\Users\User\AppData\Local\Programs\Python\Python310\lib\site-packages\django\template\backends\django.py", line 33, in get_template
    return Template(self.engine.get_template(template_name), self)
  File "C:\Users\User\AppData\Local\Programs\Python\Python310\lib\site-packages\django\template\engine.py", line 177, in get_template
    template, origin = self.find_template(template_name)
  File "C:\Users\User\AppData\Local\Programs\Python\Python310\lib\site-packages\django\template\engine.py", line 159, in find_template
    template = loader.get_template(name, skip=skip)
  File "C:\Users\User\AppData\Local\Programs\Python\Python310\lib\site-packages\django\template\loaders\cached.py", line 57, in get_template
    template = super().get_template(template_name, skip)
  File "C:\Users\User\AppData\Local\Programs\Python\Python310\lib\site-packages\django\template\loaders\base.py", line 28, in get_template
    return Template(
  File "C:\Users\User\AppData\Local\Programs\Python\Python310\lib\site-packages\django\template\base.py", line 154, in __init__
    self.nodelist = self.compile_nodelist()
  File "C:\Users\User\AppData\Local\Programs\Python\Python310\lib\site-packages\django\template\base.py", line 196, in compile_nodelist
    return parser.parse()
  File "C:\Users\User\AppData\Local\Programs\Python\Python310\lib\site-packages\django\template\base.py", line 510, in parse
    raise self.error(token, e)
  File "C:\Users\User\AppData\Local\Programs\Python\Python310\lib\site-packages\django\template\base.py", line 508, in parse
    compiled_result = compile_func(self, token)
  File "C:\Users\User\AppData\Local\Programs\Python\Python310\lib\site-packages\django\template\loader_tags.py", line 295, in do_extends
    nodelist = parser.parse()
  File "C:\Users\User\AppData\Local\Programs\Python\Python310\lib\site-packages\django\template\base.py", line 510, in parse
    raise self.error(token, e)
  File "C:\Users\User\AppData\Local\Programs\Python\Python310\lib\site-packages\django\template\base.py", line 508, in parse
    compiled_result = compile_func(self, token)
  File "C:\Users\User\AppData\Local\Programs\Python\Python310\lib\site-packages\django\template\loader_tags.py", line 234, in do_block
    nodelist = parser.parse(("endblock",))
  File "C:\Users\User\AppData\Local\Programs\Python\Python310\lib\site-packages\django\template\base.py", line 510, in parse
    raise self.error(token, e)
  File "C:\Users\User\AppData\Local\Programs\Python\Python310\lib\site-packages\django\template\base.py", line 508, in parse
    compiled_result = compile_func(self, token)
  File "C:\Users\User\AppData\Local\Programs\Python\Python310\lib\site-packages\django\templatetags\cache.py", line 84, in do_cache
    nodelist = parser.parse(("endcache",))
  File "C:\Users\User\AppData\Local\Programs\Python\Python310\lib\site-packages\django\template\base.py", line 504, in parse
    self.invalid_block_tag(token, command, parse_until)
  File "C:\Users\User\AppData\Local\Programs\Python\Python310\lib\site-packages\django\template\base.py", line 555, in invalid_block_tag
    raise self.error(
django.template.exceptions.TemplateSyntaxError: Invalid block tag on line 50: 'endblock', expected 'endcache'. Did you forget to register or load this tag?
ERROR 2024-08-29 21:19:02,070 log Internal Server Error: /news/
Traceback (most recent call last):
  File "C:\Users\User\AppData\Local\Programs\Python\Python310\lib\site-packages\django\template\base.py", line 502, in parse
    compile_func = self.tags[command]
KeyError: 'endblock'

During handling of the above exception, another exception occurred:

Traceback (most recent call last):
  File "C:\Users\User\AppData\Local\Programs\Python\Python310\lib\site-packages\django\core\handlers\exception.py", line 55, in inner
    response = get_response(request)
  File "C:\Users\User\AppData\Local\Programs\Python\Python310\lib\site-packages\django\core\handlers\base.py", line 220, in _get_response
    response = response.render()
  File "C:\Users\User\AppData\Local\Programs\Python\Python310\lib\site-packages\django\template\response.py", line 114, in render
    self.content = self.rendered_content
  File "C:\Users\User\AppData\Local\Programs\Python\Python310\lib\site-packages\django\template\response.py", line 90, in rendered_content
    template = self.resolve_template(self.template_name)
  File "C:\Users\User\AppData\Local\Programs\Python\Python310\lib\site-packages\django\template\response.py", line 72, in resolve_template
    return select_template(template, using=self.using)
  File "C:\Users\User\AppData\Local\Programs\Python\Python310\lib\site-packages\django\template\loader.py", line 42, in select_template
    return engine.get_template(template_name)
  File "C:\Users\User\AppData\Local\Programs\Python\Python310\lib\site-packages\django\template\backends\django.py", line 33, in get_template
    return Template(self.engine.get_template(template_name), self)
  File "C:\Users\User\AppData\Local\Programs\Python\Python310\lib\site-packages\django\template\engine.py", line 177, in get_template
    template, origin = self.find_template(template_name)
  File "C:\Users\User\AppData\Local\Programs\Python\Python310\lib\site-packages\django\template\engine.py", line 159, in find_template
    template = loader.get_template(name, skip=skip)
  File "C:\Users\User\AppData\Local\Programs\Python\Python310\lib\site-packages\django\template\loaders\cached.py", line 57, in get_template
    template = super().get_template(template_name, skip)
  File "C:\Users\User\AppData\Local\Programs\Python\Python310\lib\site-packages\django\template\loaders\base.py", line 28, in get_template
    return Template(
  File "C:\Users\User\AppData\Local\Programs\Python\Python310\lib\site-packages\django\template\base.py", line 154, in __init__
    self.nodelist = self.compile_nodelist()
  File "C:\Users\User\AppData\Local\Programs\Python\Python310\lib\site-packages\django\template\base.py", line 196, in compile_nodelist
    return parser.parse()
  File "C:\Users\User\AppData\Local\Programs\Python\Python310\lib\site-packages\django\template\base.py", line 510, in parse
    raise self.error(token, e)
  File "C:\Users\User\AppData\Local\Programs\Python\Python310\lib\site-packages\django\template\base.py", line 508, in parse
    compiled_result = compile_func(self, token)
  File "C:\Users\User\AppData\Local\Programs\Python\Python310\lib\site-packages\django\template\loader_tags.py", line 295, in do_extends
    nodelist = parser.parse()
  File "C:\Users\User\AppData\Local\Programs\Python\Python310\lib\site-packages\django\template\base.py", line 510, in parse
    raise self.error(token, e)
  File "C:\Users\User\AppData\Local\Programs\Python\Python310\lib\site-packages\django\template\base.py", line 508, in parse
    compiled_result = compile_func(self, token)
  File "C:\Users\User\AppData\Local\Programs\Python\Python310\lib\site-packages\django\template\loader_tags.py", line 234, in do_block
    nodelist = parser.parse(("endblock",))
  File "C:\Users\User\AppData\Local\Programs\Python\Python310\lib\site-packages\django\template\base.py", line 510, in parse
    raise self.error(token, e)
  File "C:\Users\User\AppData\Local\Programs\Python\Python310\lib\site-packages\django\template\base.py", line 508, in parse
    compiled_result = compile_func(self, token)
  File "C:\Users\User\AppData\Local\Programs\Python\Python310\lib\site-packages\django\templatetags\cache.py", line 84, in do_cache
    nodelist = parser.parse(("endcache",))
  File "C:\Users\User\AppData\Local\Programs\Python\Python310\lib\site-packages\django\template\base.py", line 504, in parse
    self.invalid_block_tag(token, command, parse_until)
  File "C:\Users\User\AppData\Local\Programs\Python\Python310\lib\site-packages\django\template\base.py", line 555, in invalid_block_tag
    raise self.error(
django.template.exceptions.TemplateSyntaxError: Invalid block tag on line 50: 'endblock', expected 'endcache'. Did you forget to register or load this tag?

During handling of the above exception, another exception occurred:

Traceback (most recent call last):
  File "C:\Users\User\AppData\Local\Programs\Python\Python310\lib\site-packages\django\core\handlers\exception.py", line 55, in inner
    response = get_response(request)
  File "C:\Users\User\AppData\Local\Programs\Python\Python310\lib\site-packages\allauth\account\middleware.py", line 37, in middleware
    response = get_response(request)
  File "C:\Users\User\AppData\Local\Programs\Python\Python310\lib\site-packages\django\core\handlers\exception.py", line 57, in inner
    response = response_for_exception(request, exc)
  File "C:\Users\User\AppData\Local\Programs\Python\Python310\lib\site-packages\django\core\handlers\exception.py", line 143, in response_for_exception
    log_response(
  File "C:\Users\User\AppData\Local\Programs\Python\Python310\lib\site-packages\django\utils\log.py", line 241, in log_response
    getattr(logger, level)(
  File "C:\Users\User\AppData\Local\Programs\Python\Python310\lib\logging\__init__.py", line 1497, in error
    self._log(ERROR, msg, args, **kwargs)
  File "C:\Users\User\AppData\Local\Programs\Python\Python310\lib\logging\__init__.py", line 1615, in _log
    self.handle(record)
  File "C:\Users\User\AppData\Local\Programs\Python\Python310\lib\logging\__init__.py", line 1625, in handle
    self.callHandlers(record)
  File "C:\Users\User\AppData\Local\Programs\Python\Python310\lib\logging\__init__.py", line 1687, in callHandlers
    hdlr.handle(record)
  File "C:\Users\User\AppData\Local\Programs\Python\Python310\lib\logging\__init__.py", line 967, in handle
    self.emit(record)
  File "C:\Users\User\PycharmProjects\my_portal\my_portal\settings.py", line 275, in emit
    self.server.send_message(msg, self.fromaddr, self.toaddrs)
  File "C:\Users\User\AppData\Local\Programs\Python\Python310\lib\smtplib.py", line 986, in send_message
    return self.sendmail(from_addr, to_addrs, flatmsg, mail_options,
  File "C:\Users\User\AppData\Local\Programs\Python\Python310\lib\smtplib.py", line 908, in sendmail
    raise SMTPDataError(code, resp)
smtplib.SMTPDataError: (554, b'5.7.1 Message rejected under suspicion of SPAM; https://ya.cc/1IrBc 1724955539-MIbwHU7VvmI0-LIG9Mnkh')

During handling of the above exception, another exception occurred:

Traceback (most recent call last):
  File "C:\Users\User\AppData\Local\Programs\Python\Python310\lib\site-packages\django\core\handlers\exception.py", line 55, in inner
    response = get_response(request)
  File "C:\Users\User\AppData\Local\Programs\Python\Python310\lib\site-packages\django\utils\deprecation.py", line 134, in __call__
    response = response or self.get_response(request)
  File "C:\Users\User\AppData\Local\Programs\Python\Python310\lib\site-packages\django\core\handlers\exception.py", line 57, in inner
    response = response_for_exception(request, exc)
  File "C:\Users\User\AppData\Local\Programs\Python\Python310\lib\site-packages\django\core\handlers\exception.py", line 143, in response_for_exception
    log_response(
  File "C:\Users\User\AppData\Local\Programs\Python\Python310\lib\site-packages\django\utils\log.py", line 241, in log_response
    getattr(logger, level)(
  File "C:\Users\User\AppData\Local\Programs\Python\Python310\lib\logging\__init__.py", line 1497, in error
    self._log(ERROR, msg, args, **kwargs)
  File "C:\Users\User\AppData\Local\Programs\Python\Python310\lib\logging\__init__.py", line 1615, in _log
    self.handle(record)
  File "C:\Users\User\AppData\Local\Programs\Python\Python310\lib\logging\__init__.py", line 1625, in handle
    self.callHandlers(record)
  File "C:\Users\User\AppData\Local\Programs\Python\Python310\lib\logging\__init__.py", line 1687, in callHandlers
    hdlr.handle(record)
  File "C:\Users\User\AppData\Local\Programs\Python\Python310\lib\logging\__init__.py", line 967, in handle
    self.emit(record)
  File "C:\Users\User\PycharmProjects\my_portal\my_portal\settings.py", line 275, in emit
    self.server.send_message(msg, self.fromaddr, self.toaddrs)
  File "C:\Users\User\AppData\Local\Programs\Python\Python310\lib\smtplib.py", line 986, in send_message
    return self.sendmail(from_addr, to_addrs, flatmsg, mail_options,
  File "C:\Users\User\AppData\Local\Programs\Python\Python310\lib\smtplib.py", line 908, in sendmail
    raise SMTPDataError(code, resp)
smtplib.SMTPDataError: (554, b'5.7.1 Message rejected under suspicion of SPAM; https://ya.cc/1IrBc 1724955539-MIbwHU7VvmI0-fa9qjARd')

During handling of the above exception, another exception occurred:

Traceback (most recent call last):
  File "C:\Users\User\AppData\Local\Programs\Python\Python310\lib\site-packages\django\core\handlers\exception.py", line 55, in inner
    response = get_response(request)
  File "C:\Users\User\AppData\Local\Programs\Python\Python310\lib\site-packages\django\utils\deprecation.py", line 134, in __call__
    response = response or self.get_response(request)
  File "C:\Users\User\AppData\Local\Programs\Python\Python310\lib\site-packages\django\core\handlers\exception.py", line 57, in inner
    response = response_for_exception(request, exc)
  File "C:\Users\User\AppData\Local\Programs\Python\Python310\lib\site-packages\django\core\handlers\exception.py", line 143, in response_for_exception
    log_response(
  File "C:\Users\User\AppData\Local\Programs\Python\Python310\lib\site-packages\django\utils\log.py", line 241, in log_response
    getattr(logger, level)(
  File "C:\Users\User\AppData\Local\Programs\Python\Python310\lib\logging\__init__.py", line 1497, in error
    self._log(ERROR, msg, args, **kwargs)
  File "C:\Users\User\AppData\Local\Programs\Python\Python310\lib\logging\__init__.py", line 1615, in _log
    self.handle(record)
  File "C:\Users\User\AppData\Local\Programs\Python\Python310\lib\logging\__init__.py", line 1625, in handle
    self.callHandlers(record)
  File "C:\Users\User\AppData\Local\Programs\Python\Python310\lib\logging\__init__.py", line 1687, in callHandlers
    hdlr.handle(record)
  File "C:\Users\User\AppData\Local\Programs\Python\Python310\lib\logging\__init__.py", line 967, in handle
    self.emit(record)
  File "C:\Users\User\PycharmProjects\my_portal\my_portal\settings.py", line 275, in emit
    self.server.send_message(msg, self.fromaddr, self.toaddrs)
  File "C:\Users\User\AppData\Local\Programs\Python\Python310\lib\smtplib.py", line 986, in send_message
    return self.sendmail(from_addr, to_addrs, flatmsg, mail_options,
  File "C:\Users\User\AppData\Local\Programs\Python\Python310\lib\smtplib.py", line 908, in sendmail
    raise SMTPDataError(code, resp)
smtplib.SMTPDataError: (554, b'5.7.1 Message rejected under suspicion of SPAM; https://ya.cc/1IrBc 1724955539-MIbwHU7VvmI0-It3ZvrYU')

During handling of the above exception, another exception occurred:

Traceback (most recent call last):
  File "C:\Users\User\AppData\Local\Programs\Python\Python310\lib\site-packages\django\core\handlers\exception.py", line 55, in inner
    response = get_response(request)
  File "C:\Users\User\AppData\Local\Programs\Python\Python310\lib\site-packages\django\utils\deprecation.py", line 134, in __call__
    response = response or self.get_response(request)
  File "C:\Users\User\AppData\Local\Programs\Python\Python310\lib\site-packages\django\core\handlers\exception.py", line 57, in inner
    response = response_for_exception(request, exc)
  File "C:\Users\User\AppData\Local\Programs\Python\Python310\lib\site-packages\django\core\handlers\exception.py", line 143, in response_for_exception
    log_response(
  File "C:\Users\User\AppData\Local\Programs\Python\Python310\lib\site-packages\django\utils\log.py", line 241, in log_response
    getattr(logger, level)(
  File "C:\Users\User\AppData\Local\Programs\Python\Python310\lib\logging\__init__.py", line 1497, in error
    self._log(ERROR, msg, args, **kwargs)
  File "C:\Users\User\AppData\Local\Programs\Python\Python310\lib\logging\__init__.py", line 1615, in _log
    self.handle(record)
  File "C:\Users\User\AppData\Local\Programs\Python\Python310\lib\logging\__init__.py", line 1625, in handle
    self.callHandlers(record)
  File "C:\Users\User\AppData\Local\Programs\Python\Python310\lib\logging\__init__.py", line 1687, in callHandlers
    hdlr.handle(record)
  File "C:\Users\User\AppData\Local\Programs\Python\Python310\lib\logging\__init__.py", line 967, in handle
    self.emit(record)
  File "C:\Users\User\PycharmProjects\my_portal\my_portal\settings.py", line 275, in emit
    self.server.send_message(msg, self.fromaddr, self.toaddrs)
  File "C:\Users\User\AppData\Local\Programs\Python\Python310\lib\smtplib.py", line 986, in send_message
    return self.sendmail(from_addr, to_addrs, flatmsg, mail_options,
  File "C:\Users\User\AppData\Local\Programs\Python\Python310\lib\smtplib.py", line 908, in sendmail
    raise SMTPDataError(code, resp)
smtplib.SMTPDataError: (554, b'5.7.1 Message rejected under suspicion of SPAM; https://ya.cc/1IrBc 1724955540-MIbwHU7VvmI0-fJp7hE4r')

During handling of the above exception, another exception occurred:

Traceback (most recent call last):
  File "C:\Users\User\AppData\Local\Programs\Python\Python310\lib\site-packages\django\core\handlers\exception.py", line 55, in inner
    response = get_response(request)
  File "C:\Users\User\AppData\Local\Programs\Python\Python310\lib\site-packages\django\utils\deprecation.py", line 134, in __call__
    response = response or self.get_response(request)
  File "C:\Users\User\AppData\Local\Programs\Python\Python310\lib\site-packages\django\core\handlers\exception.py", line 57, in inner
    response = response_for_exception(request, exc)
  File "C:\Users\User\AppData\Local\Programs\Python\Python310\lib\site-packages\django\core\handlers\exception.py", line 143, in response_for_exception
    log_response(
  File "C:\Users\User\AppData\Local\Programs\Python\Python310\lib\site-packages\django\utils\log.py", line 241, in log_response
    getattr(logger, level)(
  File "C:\Users\User\AppData\Local\Programs\Python\Python310\lib\logging\__init__.py", line 1497, in error
    self._log(ERROR, msg, args, **kwargs)
  File "C:\Users\User\AppData\Local\Programs\Python\Python310\lib\logging\__init__.py", line 1615, in _log
    self.handle(record)
  File "C:\Users\User\AppData\Local\Programs\Python\Python310\lib\logging\__init__.py", line 1625, in handle
    self.callHandlers(record)
  File "C:\Users\User\AppData\Local\Programs\Python\Python310\lib\logging\__init__.py", line 1687, in callHandlers
    hdlr.handle(record)
  File "C:\Users\User\AppData\Local\Programs\Python\Python310\lib\logging\__init__.py", line 967, in handle
    self.emit(record)
  File "C:\Users\User\PycharmProjects\my_portal\my_portal\settings.py", line 275, in emit
    self.server.send_message(msg, self.fromaddr, self.toaddrs)
  File "C:\Users\User\AppData\Local\Programs\Python\Python310\lib\smtplib.py", line 986, in send_message
    return self.sendmail(from_addr, to_addrs, flatmsg, mail_options,
  File "C:\Users\User\AppData\Local\Programs\Python\Python310\lib\smtplib.py", line 908, in sendmail
    raise SMTPDataError(code, resp)
smtplib.SMTPDataError: (554, b'5.7.1 Message rejected under suspicion of SPAM; https://ya.cc/1IrBc 1724955540-MIbwHU7VvmI0-xLCQ6IvG')

During handling of the above exception, another exception occurred:

Traceback (most recent call last):
  File "C:\Users\User\AppData\Local\Programs\Python\Python310\lib\site-packages\django\core\handlers\exception.py", line 55, in inner
    response = get_response(request)
  File "C:\Users\User\AppData\Local\Programs\Python\Python310\lib\site-packages\django\utils\deprecation.py", line 134, in __call__
    response = response or self.get_response(request)
  File "C:\Users\User\AppData\Local\Programs\Python\Python310\lib\site-packages\django\core\handlers\exception.py", line 57, in inner
    response = response_for_exception(request, exc)
  File "C:\Users\User\AppData\Local\Programs\Python\Python310\lib\site-packages\django\core\handlers\exception.py", line 143, in response_for_exception
    log_response(
  File "C:\Users\User\AppData\Local\Programs\Python\Python310\lib\site-packages\django\utils\log.py", line 241, in log_response
    getattr(logger, level)(
  File "C:\Users\User\AppData\Local\Programs\Python\Python310\lib\logging\__init__.py", line 1497, in error
    self._log(ERROR, msg, args, **kwargs)
  File "C:\Users\User\AppData\Local\Programs\Python\Python310\lib\logging\__init__.py", line 1615, in _log
    self.handle(record)
  File "C:\Users\User\AppData\Local\Programs\Python\Python310\lib\logging\__init__.py", line 1625, in handle
    self.callHandlers(record)
  File "C:\Users\User\AppData\Local\Programs\Python\Python310\lib\logging\__init__.py", line 1687, in callHandlers
    hdlr.handle(record)
  File "C:\Users\User\AppData\Local\Programs\Python\Python310\lib\logging\__init__.py", line 967, in handle
    self.emit(record)
  File "C:\Users\User\PycharmProjects\my_portal\my_portal\settings.py", line 275, in emit
    self.server.send_message(msg, self.fromaddr, self.toaddrs)
  File "C:\Users\User\AppData\Local\Programs\Python\Python310\lib\smtplib.py", line 986, in send_message
    return self.sendmail(from_addr, to_addrs, flatmsg, mail_options,
  File "C:\Users\User\AppData\Local\Programs\Python\Python310\lib\smtplib.py", line 908, in sendmail
    raise SMTPDataError(code, resp)
smtplib.SMTPDataError: (554, b'5.7.1 Message rejected under suspicion of SPAM; https://ya.cc/1IrBc 1724955541-MIbwHU7VvmI0-2Mm21fZy')

During handling of the above exception, another exception occurred:

Traceback (most recent call last):
  File "C:\Users\User\AppData\Local\Programs\Python\Python310\lib\site-packages\django\core\handlers\exception.py", line 55, in inner
    response = get_response(request)
  File "C:\Users\User\AppData\Local\Programs\Python\Python310\lib\site-packages\django\utils\deprecation.py", line 134, in __call__
    response = response or self.get_response(request)
  File "C:\Users\User\AppData\Local\Programs\Python\Python310\lib\site-packages\django\core\handlers\exception.py", line 57, in inner
    response = response_for_exception(request, exc)
  File "C:\Users\User\AppData\Local\Programs\Python\Python310\lib\site-packages\django\core\handlers\exception.py", line 143, in response_for_exception
    log_response(
  File "C:\Users\User\AppData\Local\Programs\Python\Python310\lib\site-packages\django\utils\log.py", line 241, in log_response
    getattr(logger, level)(
  File "C:\Users\User\AppData\Local\Programs\Python\Python310\lib\logging\__init__.py", line 1497, in error
    self._log(ERROR, msg, args, **kwargs)
  File "C:\Users\User\AppData\Local\Programs\Python\Python310\lib\logging\__init__.py", line 1615, in _log
    self.handle(record)
  File "C:\Users\User\AppData\Local\Programs\Python\Python310\lib\logging\__init__.py", line 1625, in handle
    self.callHandlers(record)
  File "C:\Users\User\AppData\Local\Programs\Python\Python310\lib\logging\__init__.py", line 1687, in callHandlers
    hdlr.handle(record)
  File "C:\Users\User\AppData\Local\Programs\Python\Python310\lib\logging\__init__.py", line 967, in handle
    self.emit(record)
  File "C:\Users\User\PycharmProjects\my_portal\my_portal\settings.py", line 275, in emit
    self.server.send_message(msg, self.fromaddr, self.toaddrs)
  File "C:\Users\User\AppData\Local\Programs\Python\Python310\lib\smtplib.py", line 986, in send_message
    return self.sendmail(from_addr, to_addrs, flatmsg, mail_options,
  File "C:\Users\User\AppData\Local\Programs\Python\Python310\lib\smtplib.py", line 908, in sendmail
    raise SMTPDataError(code, resp)
smtplib.SMTPDataError: (554, b'5.7.1 Message rejected under suspicion of SPAM; https://ya.cc/1IrBc 1724955541-MIbwHU7VvmI0-MMxzvQe8')
ERROR 2024-08-29 21:19:02,372 log Internal Server Error: /news/
Traceback (most recent call last):
  File "C:\Users\User\AppData\Local\Programs\Python\Python310\lib\site-packages\django\template\base.py", line 502, in parse
    compile_func = self.tags[command]
KeyError: 'endblock'

During handling of the above exception, another exception occurred:

Traceback (most recent call last):
  File "C:\Users\User\AppData\Local\Programs\Python\Python310\lib\site-packages\django\core\handlers\exception.py", line 55, in inner
    response = get_response(request)
  File "C:\Users\User\AppData\Local\Programs\Python\Python310\lib\site-packages\django\core\handlers\base.py", line 220, in _get_response
    response = response.render()
  File "C:\Users\User\AppData\Local\Programs\Python\Python310\lib\site-packages\django\template\response.py", line 114, in render
    self.content = self.rendered_content
  File "C:\Users\User\AppData\Local\Programs\Python\Python310\lib\site-packages\django\template\response.py", line 90, in rendered_content
    template = self.resolve_template(self.template_name)
  File "C:\Users\User\AppData\Local\Programs\Python\Python310\lib\site-packages\django\template\response.py", line 72, in resolve_template
    return select_template(template, using=self.using)
  File "C:\Users\User\AppData\Local\Programs\Python\Python310\lib\site-packages\django\template\loader.py", line 42, in select_template
    return engine.get_template(template_name)
  File "C:\Users\User\AppData\Local\Programs\Python\Python310\lib\site-packages\django\template\backends\django.py", line 33, in get_template
    return Template(self.engine.get_template(template_name), self)
  File "C:\Users\User\AppData\Local\Programs\Python\Python310\lib\site-packages\django\template\engine.py", line 177, in get_template
    template, origin = self.find_template(template_name)
  File "C:\Users\User\AppData\Local\Programs\Python\Python310\lib\site-packages\django\template\engine.py", line 159, in find_template
    template = loader.get_template(name, skip=skip)
  File "C:\Users\User\AppData\Local\Programs\Python\Python310\lib\site-packages\django\template\loaders\cached.py", line 57, in get_template
    template = super().get_template(template_name, skip)
  File "C:\Users\User\AppData\Local\Programs\Python\Python310\lib\site-packages\django\template\loaders\base.py", line 28, in get_template
    return Template(
  File "C:\Users\User\AppData\Local\Programs\Python\Python310\lib\site-packages\django\template\base.py", line 154, in __init__
    self.nodelist = self.compile_nodelist()
  File "C:\Users\User\AppData\Local\Programs\Python\Python310\lib\site-packages\django\template\base.py", line 196, in compile_nodelist
    return parser.parse()
  File "C:\Users\User\AppData\Local\Programs\Python\Python310\lib\site-packages\django\template\base.py", line 510, in parse
    raise self.error(token, e)
  File "C:\Users\User\AppData\Local\Programs\Python\Python310\lib\site-packages\django\template\base.py", line 508, in parse
    compiled_result = compile_func(self, token)
  File "C:\Users\User\AppData\Local\Programs\Python\Python310\lib\site-packages\django\template\loader_tags.py", line 295, in do_extends
    nodelist = parser.parse()
  File "C:\Users\User\AppData\Local\Programs\Python\Python310\lib\site-packages\django\template\base.py", line 510, in parse
    raise self.error(token, e)
  File "C:\Users\User\AppData\Local\Programs\Python\Python310\lib\site-packages\django\template\base.py", line 508, in parse
    compiled_result = compile_func(self, token)
  File "C:\Users\User\AppData\Local\Programs\Python\Python310\lib\site-packages\django\template\loader_tags.py", line 234, in do_block
    nodelist = parser.parse(("endblock",))
  File "C:\Users\User\AppData\Local\Programs\Python\Python310\lib\site-packages\django\template\base.py", line 510, in parse
    raise self.error(token, e)
  File "C:\Users\User\AppData\Local\Programs\Python\Python310\lib\site-packages\django\template\base.py", line 508, in parse
    compiled_result = compile_func(self, token)
  File "C:\Users\User\AppData\Local\Programs\Python\Python310\lib\site-packages\django\templatetags\cache.py", line 84, in do_cache
    nodelist = parser.parse(("endcache",))
  File "C:\Users\User\AppData\Local\Programs\Python\Python310\lib\site-packages\django\template\base.py", line 504, in parse
    self.invalid_block_tag(token, command, parse_until)
  File "C:\Users\User\AppData\Local\Programs\Python\Python310\lib\site-packages\django\template\base.py", line 555, in invalid_block_tag
    raise self.error(
django.template.exceptions.TemplateSyntaxError: Invalid block tag on line 50: 'endblock', expected 'endcache'. Did you forget to register or load this tag?

During handling of the above exception, another exception occurred:

Traceback (most recent call last):
  File "C:\Users\User\AppData\Local\Programs\Python\Python310\lib\site-packages\django\core\handlers\exception.py", line 55, in inner
    response = get_response(request)
  File "C:\Users\User\AppData\Local\Programs\Python\Python310\lib\site-packages\allauth\account\middleware.py", line 37, in middleware
    response = get_response(request)
  File "C:\Users\User\AppData\Local\Programs\Python\Python310\lib\site-packages\django\core\handlers\exception.py", line 57, in inner
    response = response_for_exception(request, exc)
  File "C:\Users\User\AppData\Local\Programs\Python\Python310\lib\site-packages\django\core\handlers\exception.py", line 143, in response_for_exception
    log_response(
  File "C:\Users\User\AppData\Local\Programs\Python\Python310\lib\site-packages\django\utils\log.py", line 241, in log_response
    getattr(logger, level)(
  File "C:\Users\User\AppData\Local\Programs\Python\Python310\lib\logging\__init__.py", line 1497, in error
    self._log(ERROR, msg, args, **kwargs)
  File "C:\Users\User\AppData\Local\Programs\Python\Python310\lib\logging\__init__.py", line 1615, in _log
    self.handle(record)
  File "C:\Users\User\AppData\Local\Programs\Python\Python310\lib\logging\__init__.py", line 1625, in handle
    self.callHandlers(record)
  File "C:\Users\User\AppData\Local\Programs\Python\Python310\lib\logging\__init__.py", line 1687, in callHandlers
    hdlr.handle(record)
  File "C:\Users\User\AppData\Local\Programs\Python\Python310\lib\logging\__init__.py", line 967, in handle
    self.emit(record)
  File "C:\Users\User\PycharmProjects\my_portal\my_portal\settings.py", line 275, in emit
    self.server.send_message(msg, self.fromaddr, self.toaddrs)
  File "C:\Users\User\AppData\Local\Programs\Python\Python310\lib\smtplib.py", line 986, in send_message
    return self.sendmail(from_addr, to_addrs, flatmsg, mail_options,
  File "C:\Users\User\AppData\Local\Programs\Python\Python310\lib\smtplib.py", line 908, in sendmail
    raise SMTPDataError(code, resp)
smtplib.SMTPDataError: (554, b'5.7.1 Message rejected under suspicion of SPAM; https://ya.cc/1IrBc 1724955542-MIbwHU7VvmI0-2bIgsNww')
ERROR 2024-08-29 21:19:02,830 log Internal Server Error: /news/
Traceback (most recent call last):
  File "C:\Users\User\AppData\Local\Programs\Python\Python310\lib\site-packages\django\template\base.py", line 502, in parse
    compile_func = self.tags[command]
KeyError: 'endblock'

During handling of the above exception, another exception occurred:

Traceback (most recent call last):
  File "C:\Users\User\AppData\Local\Programs\Python\Python310\lib\site-packages\django\core\handlers\exception.py", line 55, in inner
    response = get_response(request)
  File "C:\Users\User\AppData\Local\Programs\Python\Python310\lib\site-packages\django\core\handlers\base.py", line 220, in _get_response
    response = response.render()
  File "C:\Users\User\AppData\Local\Programs\Python\Python310\lib\site-packages\django\template\response.py", line 114, in render
    self.content = self.rendered_content
  File "C:\Users\User\AppData\Local\Programs\Python\Python310\lib\site-packages\django\template\response.py", line 90, in rendered_content
    template = self.resolve_template(self.template_name)
  File "C:\Users\User\AppData\Local\Programs\Python\Python310\lib\site-packages\django\template\response.py", line 72, in resolve_template
    return select_template(template, using=self.using)
  File "C:\Users\User\AppData\Local\Programs\Python\Python310\lib\site-packages\django\template\loader.py", line 42, in select_template
    return engine.get_template(template_name)
  File "C:\Users\User\AppData\Local\Programs\Python\Python310\lib\site-packages\django\template\backends\django.py", line 33, in get_template
    return Template(self.engine.get_template(template_name), self)
  File "C:\Users\User\AppData\Local\Programs\Python\Python310\lib\site-packages\django\template\engine.py", line 177, in get_template
    template, origin = self.find_template(template_name)
  File "C:\Users\User\AppData\Local\Programs\Python\Python310\lib\site-packages\django\template\engine.py", line 159, in find_template
    template = loader.get_template(name, skip=skip)
  File "C:\Users\User\AppData\Local\Programs\Python\Python310\lib\site-packages\django\template\loaders\cached.py", line 57, in get_template
    template = super().get_template(template_name, skip)
  File "C:\Users\User\AppData\Local\Programs\Python\Python310\lib\site-packages\django\template\loaders\base.py", line 28, in get_template
    return Template(
  File "C:\Users\User\AppData\Local\Programs\Python\Python310\lib\site-packages\django\template\base.py", line 154, in __init__
    self.nodelist = self.compile_nodelist()
  File "C:\Users\User\AppData\Local\Programs\Python\Python310\lib\site-packages\django\template\base.py", line 196, in compile_nodelist
    return parser.parse()
  File "C:\Users\User\AppData\Local\Programs\Python\Python310\lib\site-packages\django\template\base.py", line 510, in parse
    raise self.error(token, e)
  File "C:\Users\User\AppData\Local\Programs\Python\Python310\lib\site-packages\django\template\base.py", line 508, in parse
    compiled_result = compile_func(self, token)
  File "C:\Users\User\AppData\Local\Programs\Python\Python310\lib\site-packages\django\template\loader_tags.py", line 295, in do_extends
    nodelist = parser.parse()
  File "C:\Users\User\AppData\Local\Programs\Python\Python310\lib\site-packages\django\template\base.py", line 510, in parse
    raise self.error(token, e)
  File "C:\Users\User\AppData\Local\Programs\Python\Python310\lib\site-packages\django\template\base.py", line 508, in parse
    compiled_result = compile_func(self, token)
  File "C:\Users\User\AppData\Local\Programs\Python\Python310\lib\site-packages\django\template\loader_tags.py", line 234, in do_block
    nodelist = parser.parse(("endblock",))
  File "C:\Users\User\AppData\Local\Programs\Python\Python310\lib\site-packages\django\template\base.py", line 510, in parse
    raise self.error(token, e)
  File "C:\Users\User\AppData\Local\Programs\Python\Python310\lib\site-packages\django\template\base.py", line 508, in parse
    compiled_result = compile_func(self, token)
  File "C:\Users\User\AppData\Local\Programs\Python\Python310\lib\site-packages\django\templatetags\cache.py", line 84, in do_cache
    nodelist = parser.parse(("endcache",))
  File "C:\Users\User\AppData\Local\Programs\Python\Python310\lib\site-packages\django\template\base.py", line 504, in parse
    self.invalid_block_tag(token, command, parse_until)
  File "C:\Users\User\AppData\Local\Programs\Python\Python310\lib\site-packages\django\template\base.py", line 555, in invalid_block_tag
    raise self.error(
django.template.exceptions.TemplateSyntaxError: Invalid block tag on line 50: 'endblock', expected 'endcache'. Did you forget to register or load this tag?

During handling of the above exception, another exception occurred:

Traceback (most recent call last):
  File "C:\Users\User\AppData\Local\Programs\Python\Python310\lib\site-packages\django\core\handlers\exception.py", line 55, in inner
    response = get_response(request)
  File "C:\Users\User\AppData\Local\Programs\Python\Python310\lib\site-packages\allauth\account\middleware.py", line 37, in middleware
    response = get_response(request)
  File "C:\Users\User\AppData\Local\Programs\Python\Python310\lib\site-packages\django\core\handlers\exception.py", line 57, in inner
    response = response_for_exception(request, exc)
  File "C:\Users\User\AppData\Local\Programs\Python\Python310\lib\site-packages\django\core\handlers\exception.py", line 143, in response_for_exception
    log_response(
  File "C:\Users\User\AppData\Local\Programs\Python\Python310\lib\site-packages\django\utils\log.py", line 241, in log_response
    getattr(logger, level)(
  File "C:\Users\User\AppData\Local\Programs\Python\Python310\lib\logging\__init__.py", line 1497, in error
    self._log(ERROR, msg, args, **kwargs)
  File "C:\Users\User\AppData\Local\Programs\Python\Python310\lib\logging\__init__.py", line 1615, in _log
    self.handle(record)
  File "C:\Users\User\AppData\Local\Programs\Python\Python310\lib\logging\__init__.py", line 1625, in handle
    self.callHandlers(record)
  File "C:\Users\User\AppData\Local\Programs\Python\Python310\lib\logging\__init__.py", line 1687, in callHandlers
    hdlr.handle(record)
  File "C:\Users\User\AppData\Local\Programs\Python\Python310\lib\logging\__init__.py", line 967, in handle
    self.emit(record)
  File "C:\Users\User\PycharmProjects\my_portal\my_portal\settings.py", line 275, in emit
    self.server.send_message(msg, self.fromaddr, self.toaddrs)
  File "C:\Users\User\AppData\Local\Programs\Python\Python310\lib\smtplib.py", line 986, in send_message
    return self.sendmail(from_addr, to_addrs, flatmsg, mail_options,
  File "C:\Users\User\AppData\Local\Programs\Python\Python310\lib\smtplib.py", line 908, in sendmail
    raise SMTPDataError(code, resp)
smtplib.SMTPDataError: (554, b'5.7.1 Message rejected under suspicion of SPAM; https://ya.cc/1IrBc 1724955539-MIbwHU7VvmI0-LIG9Mnkh')

During handling of the above exception, another exception occurred:

Traceback (most recent call last):
  File "C:\Users\User\AppData\Local\Programs\Python\Python310\lib\site-packages\django\core\handlers\exception.py", line 55, in inner
    response = get_response(request)
  File "C:\Users\User\AppData\Local\Programs\Python\Python310\lib\site-packages\django\utils\deprecation.py", line 134, in __call__
    response = response or self.get_response(request)
  File "C:\Users\User\AppData\Local\Programs\Python\Python310\lib\site-packages\django\core\handlers\exception.py", line 57, in inner
    response = response_for_exception(request, exc)
  File "C:\Users\User\AppData\Local\Programs\Python\Python310\lib\site-packages\django\core\handlers\exception.py", line 143, in response_for_exception
    log_response(
  File "C:\Users\User\AppData\Local\Programs\Python\Python310\lib\site-packages\django\utils\log.py", line 241, in log_response
    getattr(logger, level)(
  File "C:\Users\User\AppData\Local\Programs\Python\Python310\lib\logging\__init__.py", line 1497, in error
    self._log(ERROR, msg, args, **kwargs)
  File "C:\Users\User\AppData\Local\Programs\Python\Python310\lib\logging\__init__.py", line 1615, in _log
    self.handle(record)
  File "C:\Users\User\AppData\Local\Programs\Python\Python310\lib\logging\__init__.py", line 1625, in handle
    self.callHandlers(record)
  File "C:\Users\User\AppData\Local\Programs\Python\Python310\lib\logging\__init__.py", line 1687, in callHandlers
    hdlr.handle(record)
  File "C:\Users\User\AppData\Local\Programs\Python\Python310\lib\logging\__init__.py", line 967, in handle
    self.emit(record)
  File "C:\Users\User\PycharmProjects\my_portal\my_portal\settings.py", line 275, in emit
    self.server.send_message(msg, self.fromaddr, self.toaddrs)
  File "C:\Users\User\AppData\Local\Programs\Python\Python310\lib\smtplib.py", line 986, in send_message
    return self.sendmail(from_addr, to_addrs, flatmsg, mail_options,
  File "C:\Users\User\AppData\Local\Programs\Python\Python310\lib\smtplib.py", line 908, in sendmail
    raise SMTPDataError(code, resp)
smtplib.SMTPDataError: (554, b'5.7.1 Message rejected under suspicion of SPAM; https://ya.cc/1IrBc 1724955539-MIbwHU7VvmI0-fa9qjARd')

During handling of the above exception, another exception occurred:

Traceback (most recent call last):
  File "C:\Users\User\AppData\Local\Programs\Python\Python310\lib\site-packages\django\core\handlers\exception.py", line 55, in inner
    response = get_response(request)
  File "C:\Users\User\AppData\Local\Programs\Python\Python310\lib\site-packages\django\utils\deprecation.py", line 134, in __call__
    response = response or self.get_response(request)
  File "C:\Users\User\AppData\Local\Programs\Python\Python310\lib\site-packages\django\core\handlers\exception.py", line 57, in inner
    response = response_for_exception(request, exc)
  File "C:\Users\User\AppData\Local\Programs\Python\Python310\lib\site-packages\django\core\handlers\exception.py", line 143, in response_for_exception
    log_response(
  File "C:\Users\User\AppData\Local\Programs\Python\Python310\lib\site-packages\django\utils\log.py", line 241, in log_response
    getattr(logger, level)(
  File "C:\Users\User\AppData\Local\Programs\Python\Python310\lib\logging\__init__.py", line 1497, in error
    self._log(ERROR, msg, args, **kwargs)
  File "C:\Users\User\AppData\Local\Programs\Python\Python310\lib\logging\__init__.py", line 1615, in _log
    self.handle(record)
  File "C:\Users\User\AppData\Local\Programs\Python\Python310\lib\logging\__init__.py", line 1625, in handle
    self.callHandlers(record)
  File "C:\Users\User\AppData\Local\Programs\Python\Python310\lib\logging\__init__.py", line 1687, in callHandlers
    hdlr.handle(record)
  File "C:\Users\User\AppData\Local\Programs\Python\Python310\lib\logging\__init__.py", line 967, in handle
    self.emit(record)
  File "C:\Users\User\PycharmProjects\my_portal\my_portal\settings.py", line 275, in emit
    self.server.send_message(msg, self.fromaddr, self.toaddrs)
  File "C:\Users\User\AppData\Local\Programs\Python\Python310\lib\smtplib.py", line 986, in send_message
    return self.sendmail(from_addr, to_addrs, flatmsg, mail_options,
  File "C:\Users\User\AppData\Local\Programs\Python\Python310\lib\smtplib.py", line 908, in sendmail
    raise SMTPDataError(code, resp)
smtplib.SMTPDataError: (554, b'5.7.1 Message rejected under suspicion of SPAM; https://ya.cc/1IrBc 1724955539-MIbwHU7VvmI0-It3ZvrYU')

During handling of the above exception, another exception occurred:

Traceback (most recent call last):
  File "C:\Users\User\AppData\Local\Programs\Python\Python310\lib\site-packages\django\core\handlers\exception.py", line 55, in inner
    response = get_response(request)
  File "C:\Users\User\AppData\Local\Programs\Python\Python310\lib\site-packages\django\utils\deprecation.py", line 134, in __call__
    response = response or self.get_response(request)
  File "C:\Users\User\AppData\Local\Programs\Python\Python310\lib\site-packages\django\core\handlers\exception.py", line 57, in inner
    response = response_for_exception(request, exc)
  File "C:\Users\User\AppData\Local\Programs\Python\Python310\lib\site-packages\django\core\handlers\exception.py", line 143, in response_for_exception
    log_response(
  File "C:\Users\User\AppData\Local\Programs\Python\Python310\lib\site-packages\django\utils\log.py", line 241, in log_response
    getattr(logger, level)(
  File "C:\Users\User\AppData\Local\Programs\Python\Python310\lib\logging\__init__.py", line 1497, in error
    self._log(ERROR, msg, args, **kwargs)
  File "C:\Users\User\AppData\Local\Programs\Python\Python310\lib\logging\__init__.py", line 1615, in _log
    self.handle(record)
  File "C:\Users\User\AppData\Local\Programs\Python\Python310\lib\logging\__init__.py", line 1625, in handle
    self.callHandlers(record)
  File "C:\Users\User\AppData\Local\Programs\Python\Python310\lib\logging\__init__.py", line 1687, in callHandlers
    hdlr.handle(record)
  File "C:\Users\User\AppData\Local\Programs\Python\Python310\lib\logging\__init__.py", line 967, in handle
    self.emit(record)
  File "C:\Users\User\PycharmProjects\my_portal\my_portal\settings.py", line 275, in emit
    self.server.send_message(msg, self.fromaddr, self.toaddrs)
  File "C:\Users\User\AppData\Local\Programs\Python\Python310\lib\smtplib.py", line 986, in send_message
    return self.sendmail(from_addr, to_addrs, flatmsg, mail_options,
  File "C:\Users\User\AppData\Local\Programs\Python\Python310\lib\smtplib.py", line 908, in sendmail
    raise SMTPDataError(code, resp)
smtplib.SMTPDataError: (554, b'5.7.1 Message rejected under suspicion of SPAM; https://ya.cc/1IrBc 1724955540-MIbwHU7VvmI0-fJp7hE4r')

During handling of the above exception, another exception occurred:

Traceback (most recent call last):
  File "C:\Users\User\AppData\Local\Programs\Python\Python310\lib\site-packages\django\core\handlers\exception.py", line 55, in inner
    response = get_response(request)
  File "C:\Users\User\AppData\Local\Programs\Python\Python310\lib\site-packages\django\utils\deprecation.py", line 134, in __call__
    response = response or self.get_response(request)
  File "C:\Users\User\AppData\Local\Programs\Python\Python310\lib\site-packages\django\core\handlers\exception.py", line 57, in inner
    response = response_for_exception(request, exc)
  File "C:\Users\User\AppData\Local\Programs\Python\Python310\lib\site-packages\django\core\handlers\exception.py", line 143, in response_for_exception
    log_response(
  File "C:\Users\User\AppData\Local\Programs\Python\Python310\lib\site-packages\django\utils\log.py", line 241, in log_response
    getattr(logger, level)(
  File "C:\Users\User\AppData\Local\Programs\Python\Python310\lib\logging\__init__.py", line 1497, in error
    self._log(ERROR, msg, args, **kwargs)
  File "C:\Users\User\AppData\Local\Programs\Python\Python310\lib\logging\__init__.py", line 1615, in _log
    self.handle(record)
  File "C:\Users\User\AppData\Local\Programs\Python\Python310\lib\logging\__init__.py", line 1625, in handle
    self.callHandlers(record)
  File "C:\Users\User\AppData\Local\Programs\Python\Python310\lib\logging\__init__.py", line 1687, in callHandlers
    hdlr.handle(record)
  File "C:\Users\User\AppData\Local\Programs\Python\Python310\lib\logging\__init__.py", line 967, in handle
    self.emit(record)
  File "C:\Users\User\PycharmProjects\my_portal\my_portal\settings.py", line 275, in emit
    self.server.send_message(msg, self.fromaddr, self.toaddrs)
  File "C:\Users\User\AppData\Local\Programs\Python\Python310\lib\smtplib.py", line 986, in send_message
    return self.sendmail(from_addr, to_addrs, flatmsg, mail_options,
  File "C:\Users\User\AppData\Local\Programs\Python\Python310\lib\smtplib.py", line 908, in sendmail
    raise SMTPDataError(code, resp)
smtplib.SMTPDataError: (554, b'5.7.1 Message rejected under suspicion of SPAM; https://ya.cc/1IrBc 1724955540-MIbwHU7VvmI0-xLCQ6IvG')

During handling of the above exception, another exception occurred:

Traceback (most recent call last):
  File "C:\Users\User\AppData\Local\Programs\Python\Python310\lib\site-packages\django\core\handlers\exception.py", line 55, in inner
    response = get_response(request)
  File "C:\Users\User\AppData\Local\Programs\Python\Python310\lib\site-packages\django\utils\deprecation.py", line 134, in __call__
    response = response or self.get_response(request)
  File "C:\Users\User\AppData\Local\Programs\Python\Python310\lib\site-packages\django\core\handlers\exception.py", line 57, in inner
    response = response_for_exception(request, exc)
  File "C:\Users\User\AppData\Local\Programs\Python\Python310\lib\site-packages\django\core\handlers\exception.py", line 143, in response_for_exception
    log_response(
  File "C:\Users\User\AppData\Local\Programs\Python\Python310\lib\site-packages\django\utils\log.py", line 241, in log_response
    getattr(logger, level)(
  File "C:\Users\User\AppData\Local\Programs\Python\Python310\lib\logging\__init__.py", line 1497, in error
    self._log(ERROR, msg, args, **kwargs)
  File "C:\Users\User\AppData\Local\Programs\Python\Python310\lib\logging\__init__.py", line 1615, in _log
    self.handle(record)
  File "C:\Users\User\AppData\Local\Programs\Python\Python310\lib\logging\__init__.py", line 1625, in handle
    self.callHandlers(record)
  File "C:\Users\User\AppData\Local\Programs\Python\Python310\lib\logging\__init__.py", line 1687, in callHandlers
    hdlr.handle(record)
  File "C:\Users\User\AppData\Local\Programs\Python\Python310\lib\logging\__init__.py", line 967, in handle
    self.emit(record)
  File "C:\Users\User\PycharmProjects\my_portal\my_portal\settings.py", line 275, in emit
    self.server.send_message(msg, self.fromaddr, self.toaddrs)
  File "C:\Users\User\AppData\Local\Programs\Python\Python310\lib\smtplib.py", line 986, in send_message
    return self.sendmail(from_addr, to_addrs, flatmsg, mail_options,
  File "C:\Users\User\AppData\Local\Programs\Python\Python310\lib\smtplib.py", line 908, in sendmail
    raise SMTPDataError(code, resp)
smtplib.SMTPDataError: (554, b'5.7.1 Message rejected under suspicion of SPAM; https://ya.cc/1IrBc 1724955541-MIbwHU7VvmI0-2Mm21fZy')

During handling of the above exception, another exception occurred:

Traceback (most recent call last):
  File "C:\Users\User\AppData\Local\Programs\Python\Python310\lib\site-packages\django\core\handlers\exception.py", line 55, in inner
    response = get_response(request)
  File "C:\Users\User\AppData\Local\Programs\Python\Python310\lib\site-packages\django\utils\deprecation.py", line 134, in __call__
    response = response or self.get_response(request)
  File "C:\Users\User\AppData\Local\Programs\Python\Python310\lib\site-packages\django\core\handlers\exception.py", line 57, in inner
    response = response_for_exception(request, exc)
  File "C:\Users\User\AppData\Local\Programs\Python\Python310\lib\site-packages\django\core\handlers\exception.py", line 143, in response_for_exception
    log_response(
  File "C:\Users\User\AppData\Local\Programs\Python\Python310\lib\site-packages\django\utils\log.py", line 241, in log_response
    getattr(logger, level)(
  File "C:\Users\User\AppData\Local\Programs\Python\Python310\lib\logging\__init__.py", line 1497, in error
    self._log(ERROR, msg, args, **kwargs)
  File "C:\Users\User\AppData\Local\Programs\Python\Python310\lib\logging\__init__.py", line 1615, in _log
    self.handle(record)
  File "C:\Users\User\AppData\Local\Programs\Python\Python310\lib\logging\__init__.py", line 1625, in handle
    self.callHandlers(record)
  File "C:\Users\User\AppData\Local\Programs\Python\Python310\lib\logging\__init__.py", line 1687, in callHandlers
    hdlr.handle(record)
  File "C:\Users\User\AppData\Local\Programs\Python\Python310\lib\logging\__init__.py", line 967, in handle
    self.emit(record)
  File "C:\Users\User\PycharmProjects\my_portal\my_portal\settings.py", line 275, in emit
    self.server.send_message(msg, self.fromaddr, self.toaddrs)
  File "C:\Users\User\AppData\Local\Programs\Python\Python310\lib\smtplib.py", line 986, in send_message
    return self.sendmail(from_addr, to_addrs, flatmsg, mail_options,
  File "C:\Users\User\AppData\Local\Programs\Python\Python310\lib\smtplib.py", line 908, in sendmail
    raise SMTPDataError(code, resp)
smtplib.SMTPDataError: (554, b'5.7.1 Message rejected under suspicion of SPAM; https://ya.cc/1IrBc 1724955541-MIbwHU7VvmI0-MMxzvQe8')

During handling of the above exception, another exception occurred:

Traceback (most recent call last):
  File "C:\Users\User\AppData\Local\Programs\Python\Python310\lib\site-packages\django\core\handlers\exception.py", line 55, in inner
    response = get_response(request)
  File "C:\Users\User\AppData\Local\Programs\Python\Python310\lib\site-packages\django\utils\deprecation.py", line 134, in __call__
    response = response or self.get_response(request)
  File "C:\Users\User\AppData\Local\Programs\Python\Python310\lib\site-packages\django\core\handlers\exception.py", line 57, in inner
    response = response_for_exception(request, exc)
  File "C:\Users\User\AppData\Local\Programs\Python\Python310\lib\site-packages\django\core\handlers\exception.py", line 143, in response_for_exception
    log_response(
  File "C:\Users\User\AppData\Local\Programs\Python\Python310\lib\site-packages\django\utils\log.py", line 241, in log_response
    getattr(logger, level)(
  File "C:\Users\User\AppData\Local\Programs\Python\Python310\lib\logging\__init__.py", line 1497, in error
    self._log(ERROR, msg, args, **kwargs)
  File "C:\Users\User\AppData\Local\Programs\Python\Python310\lib\logging\__init__.py", line 1615, in _log
    self.handle(record)
  File "C:\Users\User\AppData\Local\Programs\Python\Python310\lib\logging\__init__.py", line 1625, in handle
    self.callHandlers(record)
  File "C:\Users\User\AppData\Local\Programs\Python\Python310\lib\logging\__init__.py", line 1687, in callHandlers
    hdlr.handle(record)
  File "C:\Users\User\AppData\Local\Programs\Python\Python310\lib\logging\__init__.py", line 967, in handle
    self.emit(record)
  File "C:\Users\User\PycharmProjects\my_portal\my_portal\settings.py", line 275, in emit
    self.server.send_message(msg, self.fromaddr, self.toaddrs)
  File "C:\Users\User\AppData\Local\Programs\Python\Python310\lib\smtplib.py", line 986, in send_message
    return self.sendmail(from_addr, to_addrs, flatmsg, mail_options,
  File "C:\Users\User\AppData\Local\Programs\Python\Python310\lib\smtplib.py", line 908, in sendmail
    raise SMTPDataError(code, resp)
smtplib.SMTPDataError: (554, b'5.7.1 Message rejected under suspicion of SPAM; https://ya.cc/1IrBc 1724955542-MIbwHU7VvmI0-RTiU2hKr')
ERROR 2024-08-29 21:19:03,126 log Internal Server Error: /news/
Traceback (most recent call last):
  File "C:\Users\User\AppData\Local\Programs\Python\Python310\lib\site-packages\django\template\base.py", line 502, in parse
    compile_func = self.tags[command]
KeyError: 'endblock'

During handling of the above exception, another exception occurred:

Traceback (most recent call last):
  File "C:\Users\User\AppData\Local\Programs\Python\Python310\lib\site-packages\django\core\handlers\exception.py", line 55, in inner
    response = get_response(request)
  File "C:\Users\User\AppData\Local\Programs\Python\Python310\lib\site-packages\django\core\handlers\base.py", line 220, in _get_response
    response = response.render()
  File "C:\Users\User\AppData\Local\Programs\Python\Python310\lib\site-packages\django\template\response.py", line 114, in render
    self.content = self.rendered_content
  File "C:\Users\User\AppData\Local\Programs\Python\Python310\lib\site-packages\django\template\response.py", line 90, in rendered_content
    template = self.resolve_template(self.template_name)
  File "C:\Users\User\AppData\Local\Programs\Python\Python310\lib\site-packages\django\template\response.py", line 72, in resolve_template
    return select_template(template, using=self.using)
  File "C:\Users\User\AppData\Local\Programs\Python\Python310\lib\site-packages\django\template\loader.py", line 42, in select_template
    return engine.get_template(template_name)
  File "C:\Users\User\AppData\Local\Programs\Python\Python310\lib\site-packages\django\template\backends\django.py", line 33, in get_template
    return Template(self.engine.get_template(template_name), self)
  File "C:\Users\User\AppData\Local\Programs\Python\Python310\lib\site-packages\django\template\engine.py", line 177, in get_template
    template, origin = self.find_template(template_name)
  File "C:\Users\User\AppData\Local\Programs\Python\Python310\lib\site-packages\django\template\engine.py", line 159, in find_template
    template = loader.get_template(name, skip=skip)
  File "C:\Users\User\AppData\Local\Programs\Python\Python310\lib\site-packages\django\template\loaders\cached.py", line 57, in get_template
    template = super().get_template(template_name, skip)
  File "C:\Users\User\AppData\Local\Programs\Python\Python310\lib\site-packages\django\template\loaders\base.py", line 28, in get_template
    return Template(
  File "C:\Users\User\AppData\Local\Programs\Python\Python310\lib\site-packages\django\template\base.py", line 154, in __init__
    self.nodelist = self.compile_nodelist()
  File "C:\Users\User\AppData\Local\Programs\Python\Python310\lib\site-packages\django\template\base.py", line 196, in compile_nodelist
    return parser.parse()
  File "C:\Users\User\AppData\Local\Programs\Python\Python310\lib\site-packages\django\template\base.py", line 510, in parse
    raise self.error(token, e)
  File "C:\Users\User\AppData\Local\Programs\Python\Python310\lib\site-packages\django\template\base.py", line 508, in parse
    compiled_result = compile_func(self, token)
  File "C:\Users\User\AppData\Local\Programs\Python\Python310\lib\site-packages\django\template\loader_tags.py", line 295, in do_extends
    nodelist = parser.parse()
  File "C:\Users\User\AppData\Local\Programs\Python\Python310\lib\site-packages\django\template\base.py", line 510, in parse
    raise self.error(token, e)
  File "C:\Users\User\AppData\Local\Programs\Python\Python310\lib\site-packages\django\template\base.py", line 508, in parse
    compiled_result = compile_func(self, token)
  File "C:\Users\User\AppData\Local\Programs\Python\Python310\lib\site-packages\django\template\loader_tags.py", line 234, in do_block
    nodelist = parser.parse(("endblock",))
  File "C:\Users\User\AppData\Local\Programs\Python\Python310\lib\site-packages\django\template\base.py", line 510, in parse
    raise self.error(token, e)
  File "C:\Users\User\AppData\Local\Programs\Python\Python310\lib\site-packages\django\template\base.py", line 508, in parse
    compiled_result = compile_func(self, token)
  File "C:\Users\User\AppData\Local\Programs\Python\Python310\lib\site-packages\django\templatetags\cache.py", line 84, in do_cache
    nodelist = parser.parse(("endcache",))
  File "C:\Users\User\AppData\Local\Programs\Python\Python310\lib\site-packages\django\template\base.py", line 504, in parse
    self.invalid_block_tag(token, command, parse_until)
  File "C:\Users\User\AppData\Local\Programs\Python\Python310\lib\site-packages\django\template\base.py", line 555, in invalid_block_tag
    raise self.error(
django.template.exceptions.TemplateSyntaxError: Invalid block tag on line 50: 'endblock', expected 'endcache'. Did you forget to register or load this tag?

During handling of the above exception, another exception occurred:

Traceback (most recent call last):
  File "C:\Users\User\AppData\Local\Programs\Python\Python310\lib\site-packages\django\core\handlers\exception.py", line 55, in inner
    response = get_response(request)
  File "C:\Users\User\AppData\Local\Programs\Python\Python310\lib\site-packages\allauth\account\middleware.py", line 37, in middleware
    response = get_response(request)
  File "C:\Users\User\AppData\Local\Programs\Python\Python310\lib\site-packages\django\core\handlers\exception.py", line 57, in inner
    response = response_for_exception(request, exc)
  File "C:\Users\User\AppData\Local\Programs\Python\Python310\lib\site-packages\django\core\handlers\exception.py", line 143, in response_for_exception
    log_response(
  File "C:\Users\User\AppData\Local\Programs\Python\Python310\lib\site-packages\django\utils\log.py", line 241, in log_response
    getattr(logger, level)(
  File "C:\Users\User\AppData\Local\Programs\Python\Python310\lib\logging\__init__.py", line 1497, in error
    self._log(ERROR, msg, args, **kwargs)
  File "C:\Users\User\AppData\Local\Programs\Python\Python310\lib\logging\__init__.py", line 1615, in _log
    self.handle(record)
  File "C:\Users\User\AppData\Local\Programs\Python\Python310\lib\logging\__init__.py", line 1625, in handle
    self.callHandlers(record)
  File "C:\Users\User\AppData\Local\Programs\Python\Python310\lib\logging\__init__.py", line 1687, in callHandlers
    hdlr.handle(record)
  File "C:\Users\User\AppData\Local\Programs\Python\Python310\lib\logging\__init__.py", line 967, in handle
    self.emit(record)
  File "C:\Users\User\PycharmProjects\my_portal\my_portal\settings.py", line 275, in emit
    self.server.send_message(msg, self.fromaddr, self.toaddrs)
  File "C:\Users\User\AppData\Local\Programs\Python\Python310\lib\smtplib.py", line 986, in send_message
    return self.sendmail(from_addr, to_addrs, flatmsg, mail_options,
  File "C:\Users\User\AppData\Local\Programs\Python\Python310\lib\smtplib.py", line 908, in sendmail
    raise SMTPDataError(code, resp)
smtplib.SMTPDataError: (554, b'5.7.1 Message rejected under suspicion of SPAM; https://ya.cc/1IrBc 1724955542-MIbwHU7VvmI0-2bIgsNww')

During handling of the above exception, another exception occurred:

Traceback (most recent call last):
  File "C:\Users\User\AppData\Local\Programs\Python\Python310\lib\site-packages\django\core\handlers\exception.py", line 55, in inner
    response = get_response(request)
  File "C:\Users\User\AppData\Local\Programs\Python\Python310\lib\site-packages\django\utils\deprecation.py", line 134, in __call__
    response = response or self.get_response(request)
  File "C:\Users\User\AppData\Local\Programs\Python\Python310\lib\site-packages\django\core\handlers\exception.py", line 57, in inner
    response = response_for_exception(request, exc)
  File "C:\Users\User\AppData\Local\Programs\Python\Python310\lib\site-packages\django\core\handlers\exception.py", line 143, in response_for_exception
    log_response(
  File "C:\Users\User\AppData\Local\Programs\Python\Python310\lib\site-packages\django\utils\log.py", line 241, in log_response
    getattr(logger, level)(
  File "C:\Users\User\AppData\Local\Programs\Python\Python310\lib\logging\__init__.py", line 1497, in error
    self._log(ERROR, msg, args, **kwargs)
  File "C:\Users\User\AppData\Local\Programs\Python\Python310\lib\logging\__init__.py", line 1615, in _log
    self.handle(record)
  File "C:\Users\User\AppData\Local\Programs\Python\Python310\lib\logging\__init__.py", line 1625, in handle
    self.callHandlers(record)
  File "C:\Users\User\AppData\Local\Programs\Python\Python310\lib\logging\__init__.py", line 1687, in callHandlers
    hdlr.handle(record)
  File "C:\Users\User\AppData\Local\Programs\Python\Python310\lib\logging\__init__.py", line 967, in handle
    self.emit(record)
  File "C:\Users\User\PycharmProjects\my_portal\my_portal\settings.py", line 275, in emit
    self.server.send_message(msg, self.fromaddr, self.toaddrs)
  File "C:\Users\User\AppData\Local\Programs\Python\Python310\lib\smtplib.py", line 986, in send_message
    return self.sendmail(from_addr, to_addrs, flatmsg, mail_options,
  File "C:\Users\User\AppData\Local\Programs\Python\Python310\lib\smtplib.py", line 908, in sendmail
    raise SMTPDataError(code, resp)
smtplib.SMTPDataError: (554, b'5.7.1 Message rejected under suspicion of SPAM; https://ya.cc/1IrBc 1724955542-MIbwHU7VvmI0-dRtpVdkk')
ERROR 2024-08-29 21:19:03,590 log Internal Server Error: /news/
Traceback (most recent call last):
  File "C:\Users\User\AppData\Local\Programs\Python\Python310\lib\site-packages\django\template\base.py", line 502, in parse
    compile_func = self.tags[command]
KeyError: 'endblock'

During handling of the above exception, another exception occurred:

Traceback (most recent call last):
  File "C:\Users\User\AppData\Local\Programs\Python\Python310\lib\site-packages\django\core\handlers\exception.py", line 55, in inner
    response = get_response(request)
  File "C:\Users\User\AppData\Local\Programs\Python\Python310\lib\site-packages\django\core\handlers\base.py", line 220, in _get_response
    response = response.render()
  File "C:\Users\User\AppData\Local\Programs\Python\Python310\lib\site-packages\django\template\response.py", line 114, in render
    self.content = self.rendered_content
  File "C:\Users\User\AppData\Local\Programs\Python\Python310\lib\site-packages\django\template\response.py", line 90, in rendered_content
    template = self.resolve_template(self.template_name)
  File "C:\Users\User\AppData\Local\Programs\Python\Python310\lib\site-packages\django\template\response.py", line 72, in resolve_template
    return select_template(template, using=self.using)
  File "C:\Users\User\AppData\Local\Programs\Python\Python310\lib\site-packages\django\template\loader.py", line 42, in select_template
    return engine.get_template(template_name)
  File "C:\Users\User\AppData\Local\Programs\Python\Python310\lib\site-packages\django\template\backends\django.py", line 33, in get_template
    return Template(self.engine.get_template(template_name), self)
  File "C:\Users\User\AppData\Local\Programs\Python\Python310\lib\site-packages\django\template\engine.py", line 177, in get_template
    template, origin = self.find_template(template_name)
  File "C:\Users\User\AppData\Local\Programs\Python\Python310\lib\site-packages\django\template\engine.py", line 159, in find_template
    template = loader.get_template(name, skip=skip)
  File "C:\Users\User\AppData\Local\Programs\Python\Python310\lib\site-packages\django\template\loaders\cached.py", line 57, in get_template
    template = super().get_template(template_name, skip)
  File "C:\Users\User\AppData\Local\Programs\Python\Python310\lib\site-packages\django\template\loaders\base.py", line 28, in get_template
    return Template(
  File "C:\Users\User\AppData\Local\Programs\Python\Python310\lib\site-packages\django\template\base.py", line 154, in __init__
    self.nodelist = self.compile_nodelist()
  File "C:\Users\User\AppData\Local\Programs\Python\Python310\lib\site-packages\django\template\base.py", line 196, in compile_nodelist
    return parser.parse()
  File "C:\Users\User\AppData\Local\Programs\Python\Python310\lib\site-packages\django\template\base.py", line 510, in parse
    raise self.error(token, e)
  File "C:\Users\User\AppData\Local\Programs\Python\Python310\lib\site-packages\django\template\base.py", line 508, in parse
    compiled_result = compile_func(self, token)
  File "C:\Users\User\AppData\Local\Programs\Python\Python310\lib\site-packages\django\template\loader_tags.py", line 295, in do_extends
    nodelist = parser.parse()
  File "C:\Users\User\AppData\Local\Programs\Python\Python310\lib\site-packages\django\template\base.py", line 510, in parse
    raise self.error(token, e)
  File "C:\Users\User\AppData\Local\Programs\Python\Python310\lib\site-packages\django\template\base.py", line 508, in parse
    compiled_result = compile_func(self, token)
  File "C:\Users\User\AppData\Local\Programs\Python\Python310\lib\site-packages\django\template\loader_tags.py", line 234, in do_block
    nodelist = parser.parse(("endblock",))
  File "C:\Users\User\AppData\Local\Programs\Python\Python310\lib\site-packages\django\template\base.py", line 510, in parse
    raise self.error(token, e)
  File "C:\Users\User\AppData\Local\Programs\Python\Python310\lib\site-packages\django\template\base.py", line 508, in parse
    compiled_result = compile_func(self, token)
  File "C:\Users\User\AppData\Local\Programs\Python\Python310\lib\site-packages\django\templatetags\cache.py", line 84, in do_cache
    nodelist = parser.parse(("endcache",))
  File "C:\Users\User\AppData\Local\Programs\Python\Python310\lib\site-packages\django\template\base.py", line 504, in parse
    self.invalid_block_tag(token, command, parse_until)
  File "C:\Users\User\AppData\Local\Programs\Python\Python310\lib\site-packages\django\template\base.py", line 555, in invalid_block_tag
    raise self.error(
django.template.exceptions.TemplateSyntaxError: Invalid block tag on line 50: 'endblock', expected 'endcache'. Did you forget to register or load this tag?

During handling of the above exception, another exception occurred:

Traceback (most recent call last):
  File "C:\Users\User\AppData\Local\Programs\Python\Python310\lib\site-packages\django\core\handlers\exception.py", line 55, in inner
    response = get_response(request)
  File "C:\Users\User\AppData\Local\Programs\Python\Python310\lib\site-packages\allauth\account\middleware.py", line 37, in middleware
    response = get_response(request)
  File "C:\Users\User\AppData\Local\Programs\Python\Python310\lib\site-packages\django\core\handlers\exception.py", line 57, in inner
    response = response_for_exception(request, exc)
  File "C:\Users\User\AppData\Local\Programs\Python\Python310\lib\site-packages\django\core\handlers\exception.py", line 143, in response_for_exception
    log_response(
  File "C:\Users\User\AppData\Local\Programs\Python\Python310\lib\site-packages\django\utils\log.py", line 241, in log_response
    getattr(logger, level)(
  File "C:\Users\User\AppData\Local\Programs\Python\Python310\lib\logging\__init__.py", line 1497, in error
    self._log(ERROR, msg, args, **kwargs)
  File "C:\Users\User\AppData\Local\Programs\Python\Python310\lib\logging\__init__.py", line 1615, in _log
    self.handle(record)
  File "C:\Users\User\AppData\Local\Programs\Python\Python310\lib\logging\__init__.py", line 1625, in handle
    self.callHandlers(record)
  File "C:\Users\User\AppData\Local\Programs\Python\Python310\lib\logging\__init__.py", line 1687, in callHandlers
    hdlr.handle(record)
  File "C:\Users\User\AppData\Local\Programs\Python\Python310\lib\logging\__init__.py", line 967, in handle
    self.emit(record)
  File "C:\Users\User\PycharmProjects\my_portal\my_portal\settings.py", line 275, in emit
    self.server.send_message(msg, self.fromaddr, self.toaddrs)
  File "C:\Users\User\AppData\Local\Programs\Python\Python310\lib\smtplib.py", line 986, in send_message
    return self.sendmail(from_addr, to_addrs, flatmsg, mail_options,
  File "C:\Users\User\AppData\Local\Programs\Python\Python310\lib\smtplib.py", line 908, in sendmail
    raise SMTPDataError(code, resp)
smtplib.SMTPDataError: (554, b'5.7.1 Message rejected under suspicion of SPAM; https://ya.cc/1IrBc 1724955539-MIbwHU7VvmI0-LIG9Mnkh')

During handling of the above exception, another exception occurred:

Traceback (most recent call last):
  File "C:\Users\User\AppData\Local\Programs\Python\Python310\lib\site-packages\django\core\handlers\exception.py", line 55, in inner
    response = get_response(request)
  File "C:\Users\User\AppData\Local\Programs\Python\Python310\lib\site-packages\django\utils\deprecation.py", line 134, in __call__
    response = response or self.get_response(request)
  File "C:\Users\User\AppData\Local\Programs\Python\Python310\lib\site-packages\django\core\handlers\exception.py", line 57, in inner
    response = response_for_exception(request, exc)
  File "C:\Users\User\AppData\Local\Programs\Python\Python310\lib\site-packages\django\core\handlers\exception.py", line 143, in response_for_exception
    log_response(
  File "C:\Users\User\AppData\Local\Programs\Python\Python310\lib\site-packages\django\utils\log.py", line 241, in log_response
    getattr(logger, level)(
  File "C:\Users\User\AppData\Local\Programs\Python\Python310\lib\logging\__init__.py", line 1497, in error
    self._log(ERROR, msg, args, **kwargs)
  File "C:\Users\User\AppData\Local\Programs\Python\Python310\lib\logging\__init__.py", line 1615, in _log
    self.handle(record)
  File "C:\Users\User\AppData\Local\Programs\Python\Python310\lib\logging\__init__.py", line 1625, in handle
    self.callHandlers(record)
  File "C:\Users\User\AppData\Local\Programs\Python\Python310\lib\logging\__init__.py", line 1687, in callHandlers
    hdlr.handle(record)
  File "C:\Users\User\AppData\Local\Programs\Python\Python310\lib\logging\__init__.py", line 967, in handle
    self.emit(record)
  File "C:\Users\User\PycharmProjects\my_portal\my_portal\settings.py", line 275, in emit
    self.server.send_message(msg, self.fromaddr, self.toaddrs)
  File "C:\Users\User\AppData\Local\Programs\Python\Python310\lib\smtplib.py", line 986, in send_message
    return self.sendmail(from_addr, to_addrs, flatmsg, mail_options,
  File "C:\Users\User\AppData\Local\Programs\Python\Python310\lib\smtplib.py", line 908, in sendmail
    raise SMTPDataError(code, resp)
smtplib.SMTPDataError: (554, b'5.7.1 Message rejected under suspicion of SPAM; https://ya.cc/1IrBc 1724955539-MIbwHU7VvmI0-fa9qjARd')

During handling of the above exception, another exception occurred:

Traceback (most recent call last):
  File "C:\Users\User\AppData\Local\Programs\Python\Python310\lib\site-packages\django\core\handlers\exception.py", line 55, in inner
    response = get_response(request)
  File "C:\Users\User\AppData\Local\Programs\Python\Python310\lib\site-packages\django\utils\deprecation.py", line 134, in __call__
    response = response or self.get_response(request)
  File "C:\Users\User\AppData\Local\Programs\Python\Python310\lib\site-packages\django\core\handlers\exception.py", line 57, in inner
    response = response_for_exception(request, exc)
  File "C:\Users\User\AppData\Local\Programs\Python\Python310\lib\site-packages\django\core\handlers\exception.py", line 143, in response_for_exception
    log_response(
  File "C:\Users\User\AppData\Local\Programs\Python\Python310\lib\site-packages\django\utils\log.py", line 241, in log_response
    getattr(logger, level)(
  File "C:\Users\User\AppData\Local\Programs\Python\Python310\lib\logging\__init__.py", line 1497, in error
    self._log(ERROR, msg, args, **kwargs)
  File "C:\Users\User\AppData\Local\Programs\Python\Python310\lib\logging\__init__.py", line 1615, in _log
    self.handle(record)
  File "C:\Users\User\AppData\Local\Programs\Python\Python310\lib\logging\__init__.py", line 1625, in handle
    self.callHandlers(record)
  File "C:\Users\User\AppData\Local\Programs\Python\Python310\lib\logging\__init__.py", line 1687, in callHandlers
    hdlr.handle(record)
  File "C:\Users\User\AppData\Local\Programs\Python\Python310\lib\logging\__init__.py", line 967, in handle
    self.emit(record)
  File "C:\Users\User\PycharmProjects\my_portal\my_portal\settings.py", line 275, in emit
    self.server.send_message(msg, self.fromaddr, self.toaddrs)
  File "C:\Users\User\AppData\Local\Programs\Python\Python310\lib\smtplib.py", line 986, in send_message
    return self.sendmail(from_addr, to_addrs, flatmsg, mail_options,
  File "C:\Users\User\AppData\Local\Programs\Python\Python310\lib\smtplib.py", line 908, in sendmail
    raise SMTPDataError(code, resp)
smtplib.SMTPDataError: (554, b'5.7.1 Message rejected under suspicion of SPAM; https://ya.cc/1IrBc 1724955539-MIbwHU7VvmI0-It3ZvrYU')

During handling of the above exception, another exception occurred:

Traceback (most recent call last):
  File "C:\Users\User\AppData\Local\Programs\Python\Python310\lib\site-packages\django\core\handlers\exception.py", line 55, in inner
    response = get_response(request)
  File "C:\Users\User\AppData\Local\Programs\Python\Python310\lib\site-packages\django\utils\deprecation.py", line 134, in __call__
    response = response or self.get_response(request)
  File "C:\Users\User\AppData\Local\Programs\Python\Python310\lib\site-packages\django\core\handlers\exception.py", line 57, in inner
    response = response_for_exception(request, exc)
  File "C:\Users\User\AppData\Local\Programs\Python\Python310\lib\site-packages\django\core\handlers\exception.py", line 143, in response_for_exception
    log_response(
  File "C:\Users\User\AppData\Local\Programs\Python\Python310\lib\site-packages\django\utils\log.py", line 241, in log_response
    getattr(logger, level)(
  File "C:\Users\User\AppData\Local\Programs\Python\Python310\lib\logging\__init__.py", line 1497, in error
    self._log(ERROR, msg, args, **kwargs)
  File "C:\Users\User\AppData\Local\Programs\Python\Python310\lib\logging\__init__.py", line 1615, in _log
    self.handle(record)
  File "C:\Users\User\AppData\Local\Programs\Python\Python310\lib\logging\__init__.py", line 1625, in handle
    self.callHandlers(record)
  File "C:\Users\User\AppData\Local\Programs\Python\Python310\lib\logging\__init__.py", line 1687, in callHandlers
    hdlr.handle(record)
  File "C:\Users\User\AppData\Local\Programs\Python\Python310\lib\logging\__init__.py", line 967, in handle
    self.emit(record)
  File "C:\Users\User\PycharmProjects\my_portal\my_portal\settings.py", line 275, in emit
    self.server.send_message(msg, self.fromaddr, self.toaddrs)
  File "C:\Users\User\AppData\Local\Programs\Python\Python310\lib\smtplib.py", line 986, in send_message
    return self.sendmail(from_addr, to_addrs, flatmsg, mail_options,
  File "C:\Users\User\AppData\Local\Programs\Python\Python310\lib\smtplib.py", line 908, in sendmail
    raise SMTPDataError(code, resp)
smtplib.SMTPDataError: (554, b'5.7.1 Message rejected under suspicion of SPAM; https://ya.cc/1IrBc 1724955540-MIbwHU7VvmI0-fJp7hE4r')

During handling of the above exception, another exception occurred:

Traceback (most recent call last):
  File "C:\Users\User\AppData\Local\Programs\Python\Python310\lib\site-packages\django\core\handlers\exception.py", line 55, in inner
    response = get_response(request)
  File "C:\Users\User\AppData\Local\Programs\Python\Python310\lib\site-packages\django\utils\deprecation.py", line 134, in __call__
    response = response or self.get_response(request)
  File "C:\Users\User\AppData\Local\Programs\Python\Python310\lib\site-packages\django\core\handlers\exception.py", line 57, in inner
    response = response_for_exception(request, exc)
  File "C:\Users\User\AppData\Local\Programs\Python\Python310\lib\site-packages\django\core\handlers\exception.py", line 143, in response_for_exception
    log_response(
  File "C:\Users\User\AppData\Local\Programs\Python\Python310\lib\site-packages\django\utils\log.py", line 241, in log_response
    getattr(logger, level)(
  File "C:\Users\User\AppData\Local\Programs\Python\Python310\lib\logging\__init__.py", line 1497, in error
    self._log(ERROR, msg, args, **kwargs)
  File "C:\Users\User\AppData\Local\Programs\Python\Python310\lib\logging\__init__.py", line 1615, in _log
    self.handle(record)
  File "C:\Users\User\AppData\Local\Programs\Python\Python310\lib\logging\__init__.py", line 1625, in handle
    self.callHandlers(record)
  File "C:\Users\User\AppData\Local\Programs\Python\Python310\lib\logging\__init__.py", line 1687, in callHandlers
    hdlr.handle(record)
  File "C:\Users\User\AppData\Local\Programs\Python\Python310\lib\logging\__init__.py", line 967, in handle
    self.emit(record)
  File "C:\Users\User\PycharmProjects\my_portal\my_portal\settings.py", line 275, in emit
    self.server.send_message(msg, self.fromaddr, self.toaddrs)
  File "C:\Users\User\AppData\Local\Programs\Python\Python310\lib\smtplib.py", line 986, in send_message
    return self.sendmail(from_addr, to_addrs, flatmsg, mail_options,
  File "C:\Users\User\AppData\Local\Programs\Python\Python310\lib\smtplib.py", line 908, in sendmail
    raise SMTPDataError(code, resp)
smtplib.SMTPDataError: (554, b'5.7.1 Message rejected under suspicion of SPAM; https://ya.cc/1IrBc 1724955540-MIbwHU7VvmI0-xLCQ6IvG')

During handling of the above exception, another exception occurred:

Traceback (most recent call last):
  File "C:\Users\User\AppData\Local\Programs\Python\Python310\lib\site-packages\django\core\handlers\exception.py", line 55, in inner
    response = get_response(request)
  File "C:\Users\User\AppData\Local\Programs\Python\Python310\lib\site-packages\django\utils\deprecation.py", line 134, in __call__
    response = response or self.get_response(request)
  File "C:\Users\User\AppData\Local\Programs\Python\Python310\lib\site-packages\django\core\handlers\exception.py", line 57, in inner
    response = response_for_exception(request, exc)
  File "C:\Users\User\AppData\Local\Programs\Python\Python310\lib\site-packages\django\core\handlers\exception.py", line 143, in response_for_exception
    log_response(
  File "C:\Users\User\AppData\Local\Programs\Python\Python310\lib\site-packages\django\utils\log.py", line 241, in log_response
    getattr(logger, level)(
  File "C:\Users\User\AppData\Local\Programs\Python\Python310\lib\logging\__init__.py", line 1497, in error
    self._log(ERROR, msg, args, **kwargs)
  File "C:\Users\User\AppData\Local\Programs\Python\Python310\lib\logging\__init__.py", line 1615, in _log
    self.handle(record)
  File "C:\Users\User\AppData\Local\Programs\Python\Python310\lib\logging\__init__.py", line 1625, in handle
    self.callHandlers(record)
  File "C:\Users\User\AppData\Local\Programs\Python\Python310\lib\logging\__init__.py", line 1687, in callHandlers
    hdlr.handle(record)
  File "C:\Users\User\AppData\Local\Programs\Python\Python310\lib\logging\__init__.py", line 967, in handle
    self.emit(record)
  File "C:\Users\User\PycharmProjects\my_portal\my_portal\settings.py", line 275, in emit
    self.server.send_message(msg, self.fromaddr, self.toaddrs)
  File "C:\Users\User\AppData\Local\Programs\Python\Python310\lib\smtplib.py", line 986, in send_message
    return self.sendmail(from_addr, to_addrs, flatmsg, mail_options,
  File "C:\Users\User\AppData\Local\Programs\Python\Python310\lib\smtplib.py", line 908, in sendmail
    raise SMTPDataError(code, resp)
smtplib.SMTPDataError: (554, b'5.7.1 Message rejected under suspicion of SPAM; https://ya.cc/1IrBc 1724955541-MIbwHU7VvmI0-2Mm21fZy')

During handling of the above exception, another exception occurred:

Traceback (most recent call last):
  File "C:\Users\User\AppData\Local\Programs\Python\Python310\lib\site-packages\django\core\handlers\exception.py", line 55, in inner
    response = get_response(request)
  File "C:\Users\User\AppData\Local\Programs\Python\Python310\lib\site-packages\django\utils\deprecation.py", line 134, in __call__
    response = response or self.get_response(request)
  File "C:\Users\User\AppData\Local\Programs\Python\Python310\lib\site-packages\django\core\handlers\exception.py", line 57, in inner
    response = response_for_exception(request, exc)
  File "C:\Users\User\AppData\Local\Programs\Python\Python310\lib\site-packages\django\core\handlers\exception.py", line 143, in response_for_exception
    log_response(
  File "C:\Users\User\AppData\Local\Programs\Python\Python310\lib\site-packages\django\utils\log.py", line 241, in log_response
    getattr(logger, level)(
  File "C:\Users\User\AppData\Local\Programs\Python\Python310\lib\logging\__init__.py", line 1497, in error
    self._log(ERROR, msg, args, **kwargs)
  File "C:\Users\User\AppData\Local\Programs\Python\Python310\lib\logging\__init__.py", line 1615, in _log
    self.handle(record)
  File "C:\Users\User\AppData\Local\Programs\Python\Python310\lib\logging\__init__.py", line 1625, in handle
    self.callHandlers(record)
  File "C:\Users\User\AppData\Local\Programs\Python\Python310\lib\logging\__init__.py", line 1687, in callHandlers
    hdlr.handle(record)
  File "C:\Users\User\AppData\Local\Programs\Python\Python310\lib\logging\__init__.py", line 967, in handle
    self.emit(record)
  File "C:\Users\User\PycharmProjects\my_portal\my_portal\settings.py", line 275, in emit
    self.server.send_message(msg, self.fromaddr, self.toaddrs)
  File "C:\Users\User\AppData\Local\Programs\Python\Python310\lib\smtplib.py", line 986, in send_message
    return self.sendmail(from_addr, to_addrs, flatmsg, mail_options,
  File "C:\Users\User\AppData\Local\Programs\Python\Python310\lib\smtplib.py", line 908, in sendmail
    raise SMTPDataError(code, resp)
smtplib.SMTPDataError: (554, b'5.7.1 Message rejected under suspicion of SPAM; https://ya.cc/1IrBc 1724955541-MIbwHU7VvmI0-MMxzvQe8')

During handling of the above exception, another exception occurred:

Traceback (most recent call last):
  File "C:\Users\User\AppData\Local\Programs\Python\Python310\lib\site-packages\django\core\handlers\exception.py", line 55, in inner
    response = get_response(request)
  File "C:\Users\User\AppData\Local\Programs\Python\Python310\lib\site-packages\django\utils\deprecation.py", line 134, in __call__
    response = response or self.get_response(request)
  File "C:\Users\User\AppData\Local\Programs\Python\Python310\lib\site-packages\django\core\handlers\exception.py", line 57, in inner
    response = response_for_exception(request, exc)
  File "C:\Users\User\AppData\Local\Programs\Python\Python310\lib\site-packages\django\core\handlers\exception.py", line 143, in response_for_exception
    log_response(
  File "C:\Users\User\AppData\Local\Programs\Python\Python310\lib\site-packages\django\utils\log.py", line 241, in log_response
    getattr(logger, level)(
  File "C:\Users\User\AppData\Local\Programs\Python\Python310\lib\logging\__init__.py", line 1497, in error
    self._log(ERROR, msg, args, **kwargs)
  File "C:\Users\User\AppData\Local\Programs\Python\Python310\lib\logging\__init__.py", line 1615, in _log
    self.handle(record)
  File "C:\Users\User\AppData\Local\Programs\Python\Python310\lib\logging\__init__.py", line 1625, in handle
    self.callHandlers(record)
  File "C:\Users\User\AppData\Local\Programs\Python\Python310\lib\logging\__init__.py", line 1687, in callHandlers
    hdlr.handle(record)
  File "C:\Users\User\AppData\Local\Programs\Python\Python310\lib\logging\__init__.py", line 967, in handle
    self.emit(record)
  File "C:\Users\User\PycharmProjects\my_portal\my_portal\settings.py", line 275, in emit
    self.server.send_message(msg, self.fromaddr, self.toaddrs)
  File "C:\Users\User\AppData\Local\Programs\Python\Python310\lib\smtplib.py", line 986, in send_message
    return self.sendmail(from_addr, to_addrs, flatmsg, mail_options,
  File "C:\Users\User\AppData\Local\Programs\Python\Python310\lib\smtplib.py", line 908, in sendmail
    raise SMTPDataError(code, resp)
smtplib.SMTPDataError: (554, b'5.7.1 Message rejected under suspicion of SPAM; https://ya.cc/1IrBc 1724955542-MIbwHU7VvmI0-RTiU2hKr')

During handling of the above exception, another exception occurred:

Traceback (most recent call last):
  File "C:\Users\User\AppData\Local\Programs\Python\Python310\lib\site-packages\django\core\handlers\exception.py", line 55, in inner
    response = get_response(request)
  File "C:\Users\User\AppData\Local\Programs\Python\Python310\lib\site-packages\django\utils\deprecation.py", line 134, in __call__
    response = response or self.get_response(request)
  File "C:\Users\User\AppData\Local\Programs\Python\Python310\lib\site-packages\django\core\handlers\exception.py", line 57, in inner
    response = response_for_exception(request, exc)
  File "C:\Users\User\AppData\Local\Programs\Python\Python310\lib\site-packages\django\core\handlers\exception.py", line 143, in response_for_exception
    log_response(
  File "C:\Users\User\AppData\Local\Programs\Python\Python310\lib\site-packages\django\utils\log.py", line 241, in log_response
    getattr(logger, level)(
  File "C:\Users\User\AppData\Local\Programs\Python\Python310\lib\logging\__init__.py", line 1497, in error
    self._log(ERROR, msg, args, **kwargs)
  File "C:\Users\User\AppData\Local\Programs\Python\Python310\lib\logging\__init__.py", line 1615, in _log
    self.handle(record)
  File "C:\Users\User\AppData\Local\Programs\Python\Python310\lib\logging\__init__.py", line 1625, in handle
    self.callHandlers(record)
  File "C:\Users\User\AppData\Local\Programs\Python\Python310\lib\logging\__init__.py", line 1687, in callHandlers
    hdlr.handle(record)
  File "C:\Users\User\AppData\Local\Programs\Python\Python310\lib\logging\__init__.py", line 967, in handle
    self.emit(record)
  File "C:\Users\User\PycharmProjects\my_portal\my_portal\settings.py", line 275, in emit
    self.server.send_message(msg, self.fromaddr, self.toaddrs)
  File "C:\Users\User\AppData\Local\Programs\Python\Python310\lib\smtplib.py", line 986, in send_message
    return self.sendmail(from_addr, to_addrs, flatmsg, mail_options,
  File "C:\Users\User\AppData\Local\Programs\Python\Python310\lib\smtplib.py", line 908, in sendmail
    raise SMTPDataError(code, resp)
smtplib.SMTPDataError: (554, b'5.7.1 Message rejected under suspicion of SPAM; https://ya.cc/1IrBc 1724955543-MIbwHU7VvmI0-dBPahyqC')
ERROR 2024-08-29 21:19:04,459 log Internal Server Error: /news/
Traceback (most recent call last):
  File "C:\Users\User\AppData\Local\Programs\Python\Python310\lib\site-packages\django\template\base.py", line 502, in parse
    compile_func = self.tags[command]
KeyError: 'endblock'

During handling of the above exception, another exception occurred:

Traceback (most recent call last):
  File "C:\Users\User\AppData\Local\Programs\Python\Python310\lib\site-packages\django\core\handlers\exception.py", line 55, in inner
    response = get_response(request)
  File "C:\Users\User\AppData\Local\Programs\Python\Python310\lib\site-packages\django\core\handlers\base.py", line 220, in _get_response
    response = response.render()
  File "C:\Users\User\AppData\Local\Programs\Python\Python310\lib\site-packages\django\template\response.py", line 114, in render
    self.content = self.rendered_content
  File "C:\Users\User\AppData\Local\Programs\Python\Python310\lib\site-packages\django\template\response.py", line 90, in rendered_content
    template = self.resolve_template(self.template_name)
  File "C:\Users\User\AppData\Local\Programs\Python\Python310\lib\site-packages\django\template\response.py", line 72, in resolve_template
    return select_template(template, using=self.using)
  File "C:\Users\User\AppData\Local\Programs\Python\Python310\lib\site-packages\django\template\loader.py", line 42, in select_template
    return engine.get_template(template_name)
  File "C:\Users\User\AppData\Local\Programs\Python\Python310\lib\site-packages\django\template\backends\django.py", line 33, in get_template
    return Template(self.engine.get_template(template_name), self)
  File "C:\Users\User\AppData\Local\Programs\Python\Python310\lib\site-packages\django\template\engine.py", line 177, in get_template
    template, origin = self.find_template(template_name)
  File "C:\Users\User\AppData\Local\Programs\Python\Python310\lib\site-packages\django\template\engine.py", line 159, in find_template
    template = loader.get_template(name, skip=skip)
  File "C:\Users\User\AppData\Local\Programs\Python\Python310\lib\site-packages\django\template\loaders\cached.py", line 57, in get_template
    template = super().get_template(template_name, skip)
  File "C:\Users\User\AppData\Local\Programs\Python\Python310\lib\site-packages\django\template\loaders\base.py", line 28, in get_template
    return Template(
  File "C:\Users\User\AppData\Local\Programs\Python\Python310\lib\site-packages\django\template\base.py", line 154, in __init__
    self.nodelist = self.compile_nodelist()
  File "C:\Users\User\AppData\Local\Programs\Python\Python310\lib\site-packages\django\template\base.py", line 196, in compile_nodelist
    return parser.parse()
  File "C:\Users\User\AppData\Local\Programs\Python\Python310\lib\site-packages\django\template\base.py", line 510, in parse
    raise self.error(token, e)
  File "C:\Users\User\AppData\Local\Programs\Python\Python310\lib\site-packages\django\template\base.py", line 508, in parse
    compiled_result = compile_func(self, token)
  File "C:\Users\User\AppData\Local\Programs\Python\Python310\lib\site-packages\django\template\loader_tags.py", line 295, in do_extends
    nodelist = parser.parse()
  File "C:\Users\User\AppData\Local\Programs\Python\Python310\lib\site-packages\django\template\base.py", line 510, in parse
    raise self.error(token, e)
  File "C:\Users\User\AppData\Local\Programs\Python\Python310\lib\site-packages\django\template\base.py", line 508, in parse
    compiled_result = compile_func(self, token)
  File "C:\Users\User\AppData\Local\Programs\Python\Python310\lib\site-packages\django\template\loader_tags.py", line 234, in do_block
    nodelist = parser.parse(("endblock",))
  File "C:\Users\User\AppData\Local\Programs\Python\Python310\lib\site-packages\django\template\base.py", line 510, in parse
    raise self.error(token, e)
  File "C:\Users\User\AppData\Local\Programs\Python\Python310\lib\site-packages\django\template\base.py", line 508, in parse
    compiled_result = compile_func(self, token)
  File "C:\Users\User\AppData\Local\Programs\Python\Python310\lib\site-packages\django\templatetags\cache.py", line 84, in do_cache
    nodelist = parser.parse(("endcache",))
  File "C:\Users\User\AppData\Local\Programs\Python\Python310\lib\site-packages\django\template\base.py", line 504, in parse
    self.invalid_block_tag(token, command, parse_until)
  File "C:\Users\User\AppData\Local\Programs\Python\Python310\lib\site-packages\django\template\base.py", line 555, in invalid_block_tag
    raise self.error(
django.template.exceptions.TemplateSyntaxError: Invalid block tag on line 50: 'endblock', expected 'endcache'. Did you forget to register or load this tag?

During handling of the above exception, another exception occurred:

Traceback (most recent call last):
  File "C:\Users\User\AppData\Local\Programs\Python\Python310\lib\site-packages\django\core\handlers\exception.py", line 55, in inner
    response = get_response(request)
  File "C:\Users\User\AppData\Local\Programs\Python\Python310\lib\site-packages\allauth\account\middleware.py", line 37, in middleware
    response = get_response(request)
  File "C:\Users\User\AppData\Local\Programs\Python\Python310\lib\site-packages\django\core\handlers\exception.py", line 57, in inner
    response = response_for_exception(request, exc)
  File "C:\Users\User\AppData\Local\Programs\Python\Python310\lib\site-packages\django\core\handlers\exception.py", line 143, in response_for_exception
    log_response(
  File "C:\Users\User\AppData\Local\Programs\Python\Python310\lib\site-packages\django\utils\log.py", line 241, in log_response
    getattr(logger, level)(
  File "C:\Users\User\AppData\Local\Programs\Python\Python310\lib\logging\__init__.py", line 1497, in error
    self._log(ERROR, msg, args, **kwargs)
  File "C:\Users\User\AppData\Local\Programs\Python\Python310\lib\logging\__init__.py", line 1615, in _log
    self.handle(record)
  File "C:\Users\User\AppData\Local\Programs\Python\Python310\lib\logging\__init__.py", line 1625, in handle
    self.callHandlers(record)
  File "C:\Users\User\AppData\Local\Programs\Python\Python310\lib\logging\__init__.py", line 1687, in callHandlers
    hdlr.handle(record)
  File "C:\Users\User\AppData\Local\Programs\Python\Python310\lib\logging\__init__.py", line 967, in handle
    self.emit(record)
  File "C:\Users\User\PycharmProjects\my_portal\my_portal\settings.py", line 275, in emit
    self.server.send_message(msg, self.fromaddr, self.toaddrs)
  File "C:\Users\User\AppData\Local\Programs\Python\Python310\lib\smtplib.py", line 986, in send_message
    return self.sendmail(from_addr, to_addrs, flatmsg, mail_options,
  File "C:\Users\User\AppData\Local\Programs\Python\Python310\lib\smtplib.py", line 908, in sendmail
    raise SMTPDataError(code, resp)
smtplib.SMTPDataError: (554, b'5.7.1 Message rejected under suspicion of SPAM; https://ya.cc/1IrBc 1724955539-MIbwHU7VvmI0-LIG9Mnkh')

During handling of the above exception, another exception occurred:

Traceback (most recent call last):
  File "C:\Users\User\AppData\Local\Programs\Python\Python310\lib\site-packages\django\core\handlers\exception.py", line 55, in inner
    response = get_response(request)
  File "C:\Users\User\AppData\Local\Programs\Python\Python310\lib\site-packages\django\utils\deprecation.py", line 134, in __call__
    response = response or self.get_response(request)
  File "C:\Users\User\AppData\Local\Programs\Python\Python310\lib\site-packages\django\core\handlers\exception.py", line 57, in inner
    response = response_for_exception(request, exc)
  File "C:\Users\User\AppData\Local\Programs\Python\Python310\lib\site-packages\django\core\handlers\exception.py", line 143, in response_for_exception
    log_response(
  File "C:\Users\User\AppData\Local\Programs\Python\Python310\lib\site-packages\django\utils\log.py", line 241, in log_response
    getattr(logger, level)(
  File "C:\Users\User\AppData\Local\Programs\Python\Python310\lib\logging\__init__.py", line 1497, in error
    self._log(ERROR, msg, args, **kwargs)
  File "C:\Users\User\AppData\Local\Programs\Python\Python310\lib\logging\__init__.py", line 1615, in _log
    self.handle(record)
  File "C:\Users\User\AppData\Local\Programs\Python\Python310\lib\logging\__init__.py", line 1625, in handle
    self.callHandlers(record)
  File "C:\Users\User\AppData\Local\Programs\Python\Python310\lib\logging\__init__.py", line 1687, in callHandlers
    hdlr.handle(record)
  File "C:\Users\User\AppData\Local\Programs\Python\Python310\lib\logging\__init__.py", line 967, in handle
    self.emit(record)
  File "C:\Users\User\PycharmProjects\my_portal\my_portal\settings.py", line 275, in emit
    self.server.send_message(msg, self.fromaddr, self.toaddrs)
  File "C:\Users\User\AppData\Local\Programs\Python\Python310\lib\smtplib.py", line 986, in send_message
    return self.sendmail(from_addr, to_addrs, flatmsg, mail_options,
  File "C:\Users\User\AppData\Local\Programs\Python\Python310\lib\smtplib.py", line 908, in sendmail
    raise SMTPDataError(code, resp)
smtplib.SMTPDataError: (554, b'5.7.1 Message rejected under suspicion of SPAM; https://ya.cc/1IrBc 1724955539-MIbwHU7VvmI0-fa9qjARd')

During handling of the above exception, another exception occurred:

Traceback (most recent call last):
  File "C:\Users\User\AppData\Local\Programs\Python\Python310\lib\site-packages\django\core\handlers\exception.py", line 55, in inner
    response = get_response(request)
  File "C:\Users\User\AppData\Local\Programs\Python\Python310\lib\site-packages\django\utils\deprecation.py", line 134, in __call__
    response = response or self.get_response(request)
  File "C:\Users\User\AppData\Local\Programs\Python\Python310\lib\site-packages\django\core\handlers\exception.py", line 57, in inner
    response = response_for_exception(request, exc)
  File "C:\Users\User\AppData\Local\Programs\Python\Python310\lib\site-packages\django\core\handlers\exception.py", line 143, in response_for_exception
    log_response(
  File "C:\Users\User\AppData\Local\Programs\Python\Python310\lib\site-packages\django\utils\log.py", line 241, in log_response
    getattr(logger, level)(
  File "C:\Users\User\AppData\Local\Programs\Python\Python310\lib\logging\__init__.py", line 1497, in error
    self._log(ERROR, msg, args, **kwargs)
  File "C:\Users\User\AppData\Local\Programs\Python\Python310\lib\logging\__init__.py", line 1615, in _log
    self.handle(record)
  File "C:\Users\User\AppData\Local\Programs\Python\Python310\lib\logging\__init__.py", line 1625, in handle
    self.callHandlers(record)
  File "C:\Users\User\AppData\Local\Programs\Python\Python310\lib\logging\__init__.py", line 1687, in callHandlers
    hdlr.handle(record)
  File "C:\Users\User\AppData\Local\Programs\Python\Python310\lib\logging\__init__.py", line 967, in handle
    self.emit(record)
  File "C:\Users\User\PycharmProjects\my_portal\my_portal\settings.py", line 275, in emit
    self.server.send_message(msg, self.fromaddr, self.toaddrs)
  File "C:\Users\User\AppData\Local\Programs\Python\Python310\lib\smtplib.py", line 986, in send_message
    return self.sendmail(from_addr, to_addrs, flatmsg, mail_options,
  File "C:\Users\User\AppData\Local\Programs\Python\Python310\lib\smtplib.py", line 908, in sendmail
    raise SMTPDataError(code, resp)
smtplib.SMTPDataError: (554, b'5.7.1 Message rejected under suspicion of SPAM; https://ya.cc/1IrBc 1724955539-MIbwHU7VvmI0-It3ZvrYU')

During handling of the above exception, another exception occurred:

Traceback (most recent call last):
  File "C:\Users\User\AppData\Local\Programs\Python\Python310\lib\site-packages\django\core\handlers\exception.py", line 55, in inner
    response = get_response(request)
  File "C:\Users\User\AppData\Local\Programs\Python\Python310\lib\site-packages\django\utils\deprecation.py", line 134, in __call__
    response = response or self.get_response(request)
  File "C:\Users\User\AppData\Local\Programs\Python\Python310\lib\site-packages\django\core\handlers\exception.py", line 57, in inner
    response = response_for_exception(request, exc)
  File "C:\Users\User\AppData\Local\Programs\Python\Python310\lib\site-packages\django\core\handlers\exception.py", line 143, in response_for_exception
    log_response(
  File "C:\Users\User\AppData\Local\Programs\Python\Python310\lib\site-packages\django\utils\log.py", line 241, in log_response
    getattr(logger, level)(
  File "C:\Users\User\AppData\Local\Programs\Python\Python310\lib\logging\__init__.py", line 1497, in error
    self._log(ERROR, msg, args, **kwargs)
  File "C:\Users\User\AppData\Local\Programs\Python\Python310\lib\logging\__init__.py", line 1615, in _log
    self.handle(record)
  File "C:\Users\User\AppData\Local\Programs\Python\Python310\lib\logging\__init__.py", line 1625, in handle
    self.callHandlers(record)
  File "C:\Users\User\AppData\Local\Programs\Python\Python310\lib\logging\__init__.py", line 1687, in callHandlers
    hdlr.handle(record)
  File "C:\Users\User\AppData\Local\Programs\Python\Python310\lib\logging\__init__.py", line 967, in handle
    self.emit(record)
  File "C:\Users\User\PycharmProjects\my_portal\my_portal\settings.py", line 275, in emit
    self.server.send_message(msg, self.fromaddr, self.toaddrs)
  File "C:\Users\User\AppData\Local\Programs\Python\Python310\lib\smtplib.py", line 986, in send_message
    return self.sendmail(from_addr, to_addrs, flatmsg, mail_options,
  File "C:\Users\User\AppData\Local\Programs\Python\Python310\lib\smtplib.py", line 908, in sendmail
    raise SMTPDataError(code, resp)
smtplib.SMTPDataError: (554, b'5.7.1 Message rejected under suspicion of SPAM; https://ya.cc/1IrBc 1724955540-MIbwHU7VvmI0-fJp7hE4r')

During handling of the above exception, another exception occurred:

Traceback (most recent call last):
  File "C:\Users\User\AppData\Local\Programs\Python\Python310\lib\site-packages\django\core\handlers\exception.py", line 55, in inner
    response = get_response(request)
  File "C:\Users\User\AppData\Local\Programs\Python\Python310\lib\site-packages\django\utils\deprecation.py", line 134, in __call__
    response = response or self.get_response(request)
  File "C:\Users\User\AppData\Local\Programs\Python\Python310\lib\site-packages\django\core\handlers\exception.py", line 57, in inner
    response = response_for_exception(request, exc)
  File "C:\Users\User\AppData\Local\Programs\Python\Python310\lib\site-packages\django\core\handlers\exception.py", line 143, in response_for_exception
    log_response(
  File "C:\Users\User\AppData\Local\Programs\Python\Python310\lib\site-packages\django\utils\log.py", line 241, in log_response
    getattr(logger, level)(
  File "C:\Users\User\AppData\Local\Programs\Python\Python310\lib\logging\__init__.py", line 1497, in error
    self._log(ERROR, msg, args, **kwargs)
  File "C:\Users\User\AppData\Local\Programs\Python\Python310\lib\logging\__init__.py", line 1615, in _log
    self.handle(record)
  File "C:\Users\User\AppData\Local\Programs\Python\Python310\lib\logging\__init__.py", line 1625, in handle
    self.callHandlers(record)
  File "C:\Users\User\AppData\Local\Programs\Python\Python310\lib\logging\__init__.py", line 1687, in callHandlers
    hdlr.handle(record)
  File "C:\Users\User\AppData\Local\Programs\Python\Python310\lib\logging\__init__.py", line 967, in handle
    self.emit(record)
  File "C:\Users\User\PycharmProjects\my_portal\my_portal\settings.py", line 275, in emit
    self.server.send_message(msg, self.fromaddr, self.toaddrs)
  File "C:\Users\User\AppData\Local\Programs\Python\Python310\lib\smtplib.py", line 986, in send_message
    return self.sendmail(from_addr, to_addrs, flatmsg, mail_options,
  File "C:\Users\User\AppData\Local\Programs\Python\Python310\lib\smtplib.py", line 908, in sendmail
    raise SMTPDataError(code, resp)
smtplib.SMTPDataError: (554, b'5.7.1 Message rejected under suspicion of SPAM; https://ya.cc/1IrBc 1724955540-MIbwHU7VvmI0-xLCQ6IvG')

During handling of the above exception, another exception occurred:

Traceback (most recent call last):
  File "C:\Users\User\AppData\Local\Programs\Python\Python310\lib\site-packages\django\core\handlers\exception.py", line 55, in inner
    response = get_response(request)
  File "C:\Users\User\AppData\Local\Programs\Python\Python310\lib\site-packages\django\utils\deprecation.py", line 134, in __call__
    response = response or self.get_response(request)
  File "C:\Users\User\AppData\Local\Programs\Python\Python310\lib\site-packages\django\core\handlers\exception.py", line 57, in inner
    response = response_for_exception(request, exc)
  File "C:\Users\User\AppData\Local\Programs\Python\Python310\lib\site-packages\django\core\handlers\exception.py", line 143, in response_for_exception
    log_response(
  File "C:\Users\User\AppData\Local\Programs\Python\Python310\lib\site-packages\django\utils\log.py", line 241, in log_response
    getattr(logger, level)(
  File "C:\Users\User\AppData\Local\Programs\Python\Python310\lib\logging\__init__.py", line 1497, in error
    self._log(ERROR, msg, args, **kwargs)
  File "C:\Users\User\AppData\Local\Programs\Python\Python310\lib\logging\__init__.py", line 1615, in _log
    self.handle(record)
  File "C:\Users\User\AppData\Local\Programs\Python\Python310\lib\logging\__init__.py", line 1625, in handle
    self.callHandlers(record)
  File "C:\Users\User\AppData\Local\Programs\Python\Python310\lib\logging\__init__.py", line 1687, in callHandlers
    hdlr.handle(record)
  File "C:\Users\User\AppData\Local\Programs\Python\Python310\lib\logging\__init__.py", line 967, in handle
    self.emit(record)
  File "C:\Users\User\PycharmProjects\my_portal\my_portal\settings.py", line 275, in emit
    self.server.send_message(msg, self.fromaddr, self.toaddrs)
  File "C:\Users\User\AppData\Local\Programs\Python\Python310\lib\smtplib.py", line 986, in send_message
    return self.sendmail(from_addr, to_addrs, flatmsg, mail_options,
  File "C:\Users\User\AppData\Local\Programs\Python\Python310\lib\smtplib.py", line 908, in sendmail
    raise SMTPDataError(code, resp)
smtplib.SMTPDataError: (554, b'5.7.1 Message rejected under suspicion of SPAM; https://ya.cc/1IrBc 1724955541-MIbwHU7VvmI0-2Mm21fZy')

During handling of the above exception, another exception occurred:

Traceback (most recent call last):
  File "C:\Users\User\AppData\Local\Programs\Python\Python310\lib\site-packages\django\core\handlers\exception.py", line 55, in inner
    response = get_response(request)
  File "C:\Users\User\AppData\Local\Programs\Python\Python310\lib\site-packages\django\utils\deprecation.py", line 134, in __call__
    response = response or self.get_response(request)
  File "C:\Users\User\AppData\Local\Programs\Python\Python310\lib\site-packages\django\core\handlers\exception.py", line 57, in inner
    response = response_for_exception(request, exc)
  File "C:\Users\User\AppData\Local\Programs\Python\Python310\lib\site-packages\django\core\handlers\exception.py", line 143, in response_for_exception
    log_response(
  File "C:\Users\User\AppData\Local\Programs\Python\Python310\lib\site-packages\django\utils\log.py", line 241, in log_response
    getattr(logger, level)(
  File "C:\Users\User\AppData\Local\Programs\Python\Python310\lib\logging\__init__.py", line 1497, in error
    self._log(ERROR, msg, args, **kwargs)
  File "C:\Users\User\AppData\Local\Programs\Python\Python310\lib\logging\__init__.py", line 1615, in _log
    self.handle(record)
  File "C:\Users\User\AppData\Local\Programs\Python\Python310\lib\logging\__init__.py", line 1625, in handle
    self.callHandlers(record)
  File "C:\Users\User\AppData\Local\Programs\Python\Python310\lib\logging\__init__.py", line 1687, in callHandlers
    hdlr.handle(record)
  File "C:\Users\User\AppData\Local\Programs\Python\Python310\lib\logging\__init__.py", line 967, in handle
    self.emit(record)
  File "C:\Users\User\PycharmProjects\my_portal\my_portal\settings.py", line 275, in emit
    self.server.send_message(msg, self.fromaddr, self.toaddrs)
  File "C:\Users\User\AppData\Local\Programs\Python\Python310\lib\smtplib.py", line 986, in send_message
    return self.sendmail(from_addr, to_addrs, flatmsg, mail_options,
  File "C:\Users\User\AppData\Local\Programs\Python\Python310\lib\smtplib.py", line 908, in sendmail
    raise SMTPDataError(code, resp)
smtplib.SMTPDataError: (554, b'5.7.1 Message rejected under suspicion of SPAM; https://ya.cc/1IrBc 1724955541-MIbwHU7VvmI0-MMxzvQe8')

During handling of the above exception, another exception occurred:

Traceback (most recent call last):
  File "C:\Users\User\AppData\Local\Programs\Python\Python310\lib\site-packages\django\core\handlers\exception.py", line 55, in inner
    response = get_response(request)
  File "C:\Users\User\AppData\Local\Programs\Python\Python310\lib\site-packages\django\utils\deprecation.py", line 134, in __call__
    response = response or self.get_response(request)
  File "C:\Users\User\AppData\Local\Programs\Python\Python310\lib\site-packages\django\core\handlers\exception.py", line 57, in inner
    response = response_for_exception(request, exc)
  File "C:\Users\User\AppData\Local\Programs\Python\Python310\lib\site-packages\django\core\handlers\exception.py", line 143, in response_for_exception
    log_response(
  File "C:\Users\User\AppData\Local\Programs\Python\Python310\lib\site-packages\django\utils\log.py", line 241, in log_response
    getattr(logger, level)(
  File "C:\Users\User\AppData\Local\Programs\Python\Python310\lib\logging\__init__.py", line 1497, in error
    self._log(ERROR, msg, args, **kwargs)
  File "C:\Users\User\AppData\Local\Programs\Python\Python310\lib\logging\__init__.py", line 1615, in _log
    self.handle(record)
  File "C:\Users\User\AppData\Local\Programs\Python\Python310\lib\logging\__init__.py", line 1625, in handle
    self.callHandlers(record)
  File "C:\Users\User\AppData\Local\Programs\Python\Python310\lib\logging\__init__.py", line 1687, in callHandlers
    hdlr.handle(record)
  File "C:\Users\User\AppData\Local\Programs\Python\Python310\lib\logging\__init__.py", line 967, in handle
    self.emit(record)
  File "C:\Users\User\PycharmProjects\my_portal\my_portal\settings.py", line 275, in emit
    self.server.send_message(msg, self.fromaddr, self.toaddrs)
  File "C:\Users\User\AppData\Local\Programs\Python\Python310\lib\smtplib.py", line 986, in send_message
    return self.sendmail(from_addr, to_addrs, flatmsg, mail_options,
  File "C:\Users\User\AppData\Local\Programs\Python\Python310\lib\smtplib.py", line 908, in sendmail
    raise SMTPDataError(code, resp)
smtplib.SMTPDataError: (554, b'5.7.1 Message rejected under suspicion of SPAM; https://ya.cc/1IrBc 1724955542-MIbwHU7VvmI0-RTiU2hKr')

During handling of the above exception, another exception occurred:

Traceback (most recent call last):
  File "C:\Users\User\AppData\Local\Programs\Python\Python310\lib\site-packages\django\core\handlers\exception.py", line 55, in inner
    response = get_response(request)
  File "C:\Users\User\AppData\Local\Programs\Python\Python310\lib\site-packages\django\utils\deprecation.py", line 134, in __call__
    response = response or self.get_response(request)
  File "C:\Users\User\AppData\Local\Programs\Python\Python310\lib\site-packages\django\core\handlers\exception.py", line 57, in inner
    response = response_for_exception(request, exc)
  File "C:\Users\User\AppData\Local\Programs\Python\Python310\lib\site-packages\django\core\handlers\exception.py", line 143, in response_for_exception
    log_response(
  File "C:\Users\User\AppData\Local\Programs\Python\Python310\lib\site-packages\django\utils\log.py", line 241, in log_response
    getattr(logger, level)(
  File "C:\Users\User\AppData\Local\Programs\Python\Python310\lib\logging\__init__.py", line 1497, in error
    self._log(ERROR, msg, args, **kwargs)
  File "C:\Users\User\AppData\Local\Programs\Python\Python310\lib\logging\__init__.py", line 1615, in _log
    self.handle(record)
  File "C:\Users\User\AppData\Local\Programs\Python\Python310\lib\logging\__init__.py", line 1625, in handle
    self.callHandlers(record)
  File "C:\Users\User\AppData\Local\Programs\Python\Python310\lib\logging\__init__.py", line 1687, in callHandlers
    hdlr.handle(record)
  File "C:\Users\User\AppData\Local\Programs\Python\Python310\lib\logging\__init__.py", line 967, in handle
    self.emit(record)
  File "C:\Users\User\PycharmProjects\my_portal\my_portal\settings.py", line 275, in emit
    self.server.send_message(msg, self.fromaddr, self.toaddrs)
  File "C:\Users\User\AppData\Local\Programs\Python\Python310\lib\smtplib.py", line 986, in send_message
    return self.sendmail(from_addr, to_addrs, flatmsg, mail_options,
  File "C:\Users\User\AppData\Local\Programs\Python\Python310\lib\smtplib.py", line 908, in sendmail
    raise SMTPDataError(code, resp)
smtplib.SMTPDataError: (554, b'5.7.1 Message rejected under suspicion of SPAM; https://ya.cc/1IrBc 1724955543-MIbwHU7VvmI0-dBPahyqC')

During handling of the above exception, another exception occurred:

Traceback (most recent call last):
  File "C:\Users\User\AppData\Local\Programs\Python\Python310\lib\site-packages\django\core\handlers\exception.py", line 55, in inner
    response = get_response(request)
  File "C:\Users\User\AppData\Local\Programs\Python\Python310\lib\site-packages\django\utils\deprecation.py", line 134, in __call__
    response = response or self.get_response(request)
  File "C:\Users\User\AppData\Local\Programs\Python\Python310\lib\site-packages\django\core\handlers\exception.py", line 57, in inner
    response = response_for_exception(request, exc)
  File "C:\Users\User\AppData\Local\Programs\Python\Python310\lib\site-packages\django\core\handlers\exception.py", line 143, in response_for_exception
    log_response(
  File "C:\Users\User\AppData\Local\Programs\Python\Python310\lib\site-packages\django\utils\log.py", line 241, in log_response
    getattr(logger, level)(
  File "C:\Users\User\AppData\Local\Programs\Python\Python310\lib\logging\__init__.py", line 1497, in error
    self._log(ERROR, msg, args, **kwargs)
  File "C:\Users\User\AppData\Local\Programs\Python\Python310\lib\logging\__init__.py", line 1615, in _log
    self.handle(record)
  File "C:\Users\User\AppData\Local\Programs\Python\Python310\lib\logging\__init__.py", line 1625, in handle
    self.callHandlers(record)
  File "C:\Users\User\AppData\Local\Programs\Python\Python310\lib\logging\__init__.py", line 1687, in callHandlers
    hdlr.handle(record)
  File "C:\Users\User\AppData\Local\Programs\Python\Python310\lib\logging\__init__.py", line 967, in handle
    self.emit(record)
  File "C:\Users\User\PycharmProjects\my_portal\my_portal\settings.py", line 275, in emit
    self.server.send_message(msg, self.fromaddr, self.toaddrs)
  File "C:\Users\User\AppData\Local\Programs\Python\Python310\lib\smtplib.py", line 986, in send_message
    return self.sendmail(from_addr, to_addrs, flatmsg, mail_options,
  File "C:\Users\User\AppData\Local\Programs\Python\Python310\lib\smtplib.py", line 908, in sendmail
    raise SMTPDataError(code, resp)
smtplib.SMTPDataError: (554, b'5.7.1 Message rejected under suspicion of SPAM; https://ya.cc/1IrBc 1724955544-MIbwHU7VvmI0-gHbM3DnI')
ERROR 2024-08-30 17:02:01,459 settings Test error message
ERROR 2024-08-30 17:02:10,854 settings Test error message
ERROR 2024-08-30 17:09:38,859 settings Test error message
ERROR 2024-08-30 17:13:39,016 settings Test error message
ERROR 2024-08-30 17:18:29,911 settings Test error message
ERROR 2024-08-30 17:18:52,952 settings Test error message
ERROR 2024-08-30 17:19:05,802 settings Test error message
ERROR 2024-08-30 17:19:18,076 settings Test error message
ERROR 2024-08-30 17:19:42,437 settings Test error message
ERROR 2024-08-30 17:19:59,016 settings Test error message
ERROR 2024-08-30 17:20:22,274 settings Test error message
ERROR 2024-08-30 17:20:48,829 settings Test error message
ERROR 2024-08-30 17:20:51,389 settings Test error message
INFO 2024-08-30 17:20:52,082 autoreload Watching for file changes with StatReloader
WARNING 2024-08-30 17:20:53,449 log Not Found: /favicon.ico
